INFO 2024-04-06 03:53:52,267 autoreload 9300 15376 Watching for file changes with StatReloader
INFO 2024-04-06 03:54:44,515 autoreload 9300 15376 E:\GeekBrains\Учеба GeekBrains\3 quarter. Final\2. Django framework (Seminars)\GB_Django\Seminar2\HomeWork2\shopapp\views.py changed, reloading.
INFO 2024-04-06 03:54:45,255 autoreload 13800 16240 Watching for file changes with StatReloader
INFO 2024-04-06 03:55:14,503 autoreload 13800 16240 E:\GeekBrains\Учеба GeekBrains\3 quarter. Final\2. Django framework (Seminars)\GB_Django\Seminar2\HomeWork2\shopapp\views.py changed, reloading.
INFO 2024-04-06 03:55:15,059 autoreload 15252 17392 Watching for file changes with StatReloader
WARNING 2024-04-06 03:55:19,503 log 15252 15952 Not Found: /
WARNING 2024-04-06 03:55:19,506 basehttp 15252 15952 "GET / HTTP/1.1" 404 2167
WARNING 2024-04-06 03:55:20,064 log 15252 15952 Not Found: /favicon.ico
WARNING 2024-04-06 03:55:20,065 basehttp 15252 15952 "GET /favicon.ico HTTP/1.1" 404 2218
INFO 2024-04-06 03:55:26,691 basehttp 15252 15952 "GET /shop HTTP/1.1" 301 0
INFO 2024-04-06 03:55:26,697 basehttp 15252 16656 "GET /shop/ HTTP/1.1" 200 1980
INFO 2024-04-06 03:56:13,943 autoreload 15252 17392 E:\GeekBrains\Учеба GeekBrains\3 quarter. Final\2. Django framework (Seminars)\GB_Django\Seminar2\HomeWork2\shopapp\views.py changed, reloading.
INFO 2024-04-06 03:56:14,559 autoreload 16492 15500 Watching for file changes with StatReloader
INFO 2024-04-06 03:56:22,216 autoreload 16492 15500 E:\GeekBrains\Учеба GeekBrains\3 quarter. Final\2. Django framework (Seminars)\GB_Django\Seminar2\HomeWork2\shopapp\views.py changed, reloading.
INFO 2024-04-06 03:56:22,838 autoreload 14808 12704 Watching for file changes with StatReloader
INFO 2024-04-06 03:56:26,458 basehttp 14808 8408 "GET /shop/ HTTP/1.1" 200 1637
INFO 2024-04-06 03:56:29,594 basehttp 14808 8408 "GET /shop/ HTTP/1.1" 200 1637
INFO 2024-04-06 03:56:40,797 basehttp 14808 8408 "GET /shop/mysite/ HTTP/1.1" 200 787
ERROR 2024-04-06 03:56:49,925 log 14808 8408 Internal Server Error: /shop/fake_db/
Traceback (most recent call last):
  File "E:\GeekBrains\Учеба GeekBrains\3 quarter. Final\2. Django framework (Seminars)\GB_Django\.venv\Lib\site-packages\django\core\handlers\exception.py", line 55, in inner
    response = get_response(request)
               ^^^^^^^^^^^^^^^^^^^^^
  File "E:\GeekBrains\Учеба GeekBrains\3 quarter. Final\2. Django framework (Seminars)\GB_Django\.venv\Lib\site-packages\django\core\handlers\base.py", line 197, in _get_response
    response = wrapped_callback(request, *callback_args, **callback_kwargs)
               ^^^^^^^^^^^^^^^^^^^^^^^^^^^^^^^^^^^^^^^^^^^^^^^^^^^^^^^^^^^^
  File "E:\GeekBrains\Учеба GeekBrains\3 quarter. Final\2. Django framework (Seminars)\GB_Django\Seminar2\HomeWork2\shopapp\views.py", line 54, in fake_db
    random_date = datetime.datetime.now() - datetime.timedelta(days=random.randint(1, 365))
                  ^^^^^^^^^^^^^^^^^
AttributeError: type object 'datetime.datetime' has no attribute 'datetime'
ERROR 2024-04-06 03:56:49,928 basehttp 14808 8408 "GET /shop/fake_db/ HTTP/1.1" 500 68803
INFO 2024-04-06 03:58:23,341 autoreload 14808 12704 E:\GeekBrains\Учеба GeekBrains\3 quarter. Final\2. Django framework (Seminars)\GB_Django\Seminar2\HomeWork2\shopapp\views.py changed, reloading.
INFO 2024-04-06 03:58:23,976 autoreload 10444 13376 Watching for file changes with StatReloader
ERROR 2024-04-06 03:58:28,915 log 10444 11136 Internal Server Error: /shop/fake_db/
Traceback (most recent call last):
  File "E:\GeekBrains\Учеба GeekBrains\3 quarter. Final\2. Django framework (Seminars)\GB_Django\.venv\Lib\site-packages\django\core\handlers\exception.py", line 55, in inner
    response = get_response(request)
               ^^^^^^^^^^^^^^^^^^^^^
  File "E:\GeekBrains\Учеба GeekBrains\3 quarter. Final\2. Django framework (Seminars)\GB_Django\.venv\Lib\site-packages\django\core\handlers\base.py", line 197, in _get_response
    response = wrapped_callback(request, *callback_args, **callback_kwargs)
               ^^^^^^^^^^^^^^^^^^^^^^^^^^^^^^^^^^^^^^^^^^^^^^^^^^^^^^^^^^^^
  File "E:\GeekBrains\Учеба GeekBrains\3 quarter. Final\2. Django framework (Seminars)\GB_Django\Seminar2\HomeWork2\shopapp\views.py", line 54, in fake_db
    random_date = datetime.now() - datetime.timedelta(days=random.randint(1, 365))
                                   ^^^^^^^^^^^^^^^^^^
AttributeError: type object 'datetime.datetime' has no attribute 'timedelta'
ERROR 2024-04-06 03:58:28,918 basehttp 10444 11136 "GET /shop/fake_db/ HTTP/1.1" 500 68962
INFO 2024-04-06 04:01:03,878 autoreload 10444 13376 E:\GeekBrains\Учеба GeekBrains\3 quarter. Final\2. Django framework (Seminars)\GB_Django\Seminar2\HomeWork2\shopapp\views.py changed, reloading.
INFO 2024-04-06 04:01:04,452 autoreload 16404 15680 Watching for file changes with StatReloader
ERROR 2024-04-06 04:01:07,927 log 16404 15744 Internal Server Error: /shop/fake_db/
Traceback (most recent call last):
  File "E:\GeekBrains\Учеба GeekBrains\3 quarter. Final\2. Django framework (Seminars)\GB_Django\.venv\Lib\site-packages\django\core\handlers\exception.py", line 55, in inner
    response = get_response(request)
               ^^^^^^^^^^^^^^^^^^^^^
  File "E:\GeekBrains\Учеба GeekBrains\3 quarter. Final\2. Django framework (Seminars)\GB_Django\.venv\Lib\site-packages\django\core\handlers\base.py", line 197, in _get_response
    response = wrapped_callback(request, *callback_args, **callback_kwargs)
               ^^^^^^^^^^^^^^^^^^^^^^^^^^^^^^^^^^^^^^^^^^^^^^^^^^^^^^^^^^^^
  File "E:\GeekBrains\Учеба GeekBrains\3 quarter. Final\2. Django framework (Seminars)\GB_Django\Seminar2\HomeWork2\shopapp\views.py", line 60, in fake_db
    customer.save()
  File "E:\GeekBrains\Учеба GeekBrains\3 quarter. Final\2. Django framework (Seminars)\GB_Django\.venv\Lib\site-packages\django\db\models\base.py", line 822, in save
    self.save_base(
  File "E:\GeekBrains\Учеба GeekBrains\3 quarter. Final\2. Django framework (Seminars)\GB_Django\.venv\Lib\site-packages\django\db\models\base.py", line 909, in save_base
    updated = self._save_table(
              ^^^^^^^^^^^^^^^^^
  File "E:\GeekBrains\Учеба GeekBrains\3 quarter. Final\2. Django framework (Seminars)\GB_Django\.venv\Lib\site-packages\django\db\models\base.py", line 1067, in _save_table
    results = self._do_insert(
              ^^^^^^^^^^^^^^^^
  File "E:\GeekBrains\Учеба GeekBrains\3 quarter. Final\2. Django framework (Seminars)\GB_Django\.venv\Lib\site-packages\django\db\models\base.py", line 1108, in _do_insert
    return manager._insert(
           ^^^^^^^^^^^^^^^^
  File "E:\GeekBrains\Учеба GeekBrains\3 quarter. Final\2. Django framework (Seminars)\GB_Django\.venv\Lib\site-packages\django\db\models\manager.py", line 87, in manager_method
    return getattr(self.get_queryset(), name)(*args, **kwargs)
           ^^^^^^^^^^^^^^^^^^^^^^^^^^^^^^^^^^^^^^^^^^^^^^^^^^^
  File "E:\GeekBrains\Учеба GeekBrains\3 quarter. Final\2. Django framework (Seminars)\GB_Django\.venv\Lib\site-packages\django\db\models\query.py", line 1847, in _insert
    return query.get_compiler(using=using).execute_sql(returning_fields)
           ^^^^^^^^^^^^^^^^^^^^^^^^^^^^^^^^^^^^^^^^^^^^^^^^^^^^^^^^^^^^^
  File "E:\GeekBrains\Учеба GeekBrains\3 quarter. Final\2. Django framework (Seminars)\GB_Django\.venv\Lib\site-packages\django\db\models\sql\compiler.py", line 1822, in execute_sql
    for sql, params in self.as_sql():
                       ^^^^^^^^^^^^^
  File "E:\GeekBrains\Учеба GeekBrains\3 quarter. Final\2. Django framework (Seminars)\GB_Django\.venv\Lib\site-packages\django\db\models\sql\compiler.py", line 1747, in as_sql
    self.prepare_value(field, self.pre_save_val(field, obj))
  File "E:\GeekBrains\Учеба GeekBrains\3 quarter. Final\2. Django framework (Seminars)\GB_Django\.venv\Lib\site-packages\django\db\models\sql\compiler.py", line 1686, in prepare_value
    return field.get_db_prep_save(value, connection=self.connection)
           ^^^^^^^^^^^^^^^^^^^^^^^^^^^^^^^^^^^^^^^^^^^^^^^^^^^^^^^^^
  File "E:\GeekBrains\Учеба GeekBrains\3 quarter. Final\2. Django framework (Seminars)\GB_Django\.venv\Lib\site-packages\django\db\models\fields\__init__.py", line 1013, in get_db_prep_save
    return self.get_db_prep_value(value, connection=connection, prepared=False)
           ^^^^^^^^^^^^^^^^^^^^^^^^^^^^^^^^^^^^^^^^^^^^^^^^^^^^^^^^^^^^^^^^^^^^
  File "E:\GeekBrains\Учеба GeekBrains\3 quarter. Final\2. Django framework (Seminars)\GB_Django\.venv\Lib\site-packages\django\db\models\fields\__init__.py", line 1530, in get_db_prep_value
    value = self.get_prep_value(value)
            ^^^^^^^^^^^^^^^^^^^^^^^^^^
  File "E:\GeekBrains\Учеба GeekBrains\3 quarter. Final\2. Django framework (Seminars)\GB_Django\.venv\Lib\site-packages\django\db\models\fields\__init__.py", line 1525, in get_prep_value
    return self.to_python(value)
           ^^^^^^^^^^^^^^^^^^^^^
  File "E:\GeekBrains\Учеба GeekBrains\3 quarter. Final\2. Django framework (Seminars)\GB_Django\.venv\Lib\site-packages\django\db\models\fields\__init__.py", line 1491, in to_python
    raise exceptions.ValidationError(
django.core.exceptions.ValidationError: ['“2023-09-07 04:01:07.859147” value has an invalid date format. It must be in YYYY-MM-DD format.']
ERROR 2024-04-06 04:01:07,933 basehttp 16404 15744 "GET /shop/fake_db/ HTTP/1.1" 500 133731
INFO 2024-04-06 04:03:51,069 autoreload 16404 15680 E:\GeekBrains\Учеба GeekBrains\3 quarter. Final\2. Django framework (Seminars)\GB_Django\Seminar2\HomeWork2\shopapp\views.py changed, reloading.
INFO 2024-04-06 04:03:51,726 autoreload 16776 10404 Watching for file changes with StatReloader
INFO 2024-04-06 04:05:34,923 autoreload 16776 10404 E:\GeekBrains\Учеба GeekBrains\3 quarter. Final\2. Django framework (Seminars)\GB_Django\Seminar2\HomeWork2\shopapp\views.py changed, reloading.
INFO 2024-04-06 04:05:35,522 autoreload 16824 16948 Watching for file changes with StatReloader
ERROR 2024-04-06 04:05:39,216 log 16824 8788 Internal Server Error: /shop/fake_db/
Traceback (most recent call last):
  File "E:\GeekBrains\Учеба GeekBrains\3 quarter. Final\2. Django framework (Seminars)\GB_Django\.venv\Lib\site-packages\django\db\backends\utils.py", line 105, in _execute
    return self.cursor.execute(sql, params)
           ^^^^^^^^^^^^^^^^^^^^^^^^^^^^^^^^
  File "E:\GeekBrains\Учеба GeekBrains\3 quarter. Final\2. Django framework (Seminars)\GB_Django\.venv\Lib\site-packages\django\db\backends\sqlite3\base.py", line 329, in execute
    return super().execute(query, params)
           ^^^^^^^^^^^^^^^^^^^^^^^^^^^^^^
sqlite3.OperationalError: no such table: shopapp_customer

The above exception was the direct cause of the following exception:

Traceback (most recent call last):
  File "E:\GeekBrains\Учеба GeekBrains\3 quarter. Final\2. Django framework (Seminars)\GB_Django\.venv\Lib\site-packages\django\core\handlers\exception.py", line 55, in inner
    response = get_response(request)
               ^^^^^^^^^^^^^^^^^^^^^
  File "E:\GeekBrains\Учеба GeekBrains\3 quarter. Final\2. Django framework (Seminars)\GB_Django\.venv\Lib\site-packages\django\core\handlers\base.py", line 197, in _get_response
    response = wrapped_callback(request, *callback_args, **callback_kwargs)
               ^^^^^^^^^^^^^^^^^^^^^^^^^^^^^^^^^^^^^^^^^^^^^^^^^^^^^^^^^^^^
  File "E:\GeekBrains\Учеба GeekBrains\3 quarter. Final\2. Django framework (Seminars)\GB_Django\Seminar2\HomeWork2\shopapp\views.py", line 61, in fake_db
    customer.save()
  File "E:\GeekBrains\Учеба GeekBrains\3 quarter. Final\2. Django framework (Seminars)\GB_Django\.venv\Lib\site-packages\django\db\models\base.py", line 822, in save
    self.save_base(
  File "E:\GeekBrains\Учеба GeekBrains\3 quarter. Final\2. Django framework (Seminars)\GB_Django\.venv\Lib\site-packages\django\db\models\base.py", line 909, in save_base
    updated = self._save_table(
              ^^^^^^^^^^^^^^^^^
  File "E:\GeekBrains\Учеба GeekBrains\3 quarter. Final\2. Django framework (Seminars)\GB_Django\.venv\Lib\site-packages\django\db\models\base.py", line 1067, in _save_table
    results = self._do_insert(
              ^^^^^^^^^^^^^^^^
  File "E:\GeekBrains\Учеба GeekBrains\3 quarter. Final\2. Django framework (Seminars)\GB_Django\.venv\Lib\site-packages\django\db\models\base.py", line 1108, in _do_insert
    return manager._insert(
           ^^^^^^^^^^^^^^^^
  File "E:\GeekBrains\Учеба GeekBrains\3 quarter. Final\2. Django framework (Seminars)\GB_Django\.venv\Lib\site-packages\django\db\models\manager.py", line 87, in manager_method
    return getattr(self.get_queryset(), name)(*args, **kwargs)
           ^^^^^^^^^^^^^^^^^^^^^^^^^^^^^^^^^^^^^^^^^^^^^^^^^^^
  File "E:\GeekBrains\Учеба GeekBrains\3 quarter. Final\2. Django framework (Seminars)\GB_Django\.venv\Lib\site-packages\django\db\models\query.py", line 1847, in _insert
    return query.get_compiler(using=using).execute_sql(returning_fields)
           ^^^^^^^^^^^^^^^^^^^^^^^^^^^^^^^^^^^^^^^^^^^^^^^^^^^^^^^^^^^^^
  File "E:\GeekBrains\Учеба GeekBrains\3 quarter. Final\2. Django framework (Seminars)\GB_Django\.venv\Lib\site-packages\django\db\models\sql\compiler.py", line 1823, in execute_sql
    cursor.execute(sql, params)
  File "E:\GeekBrains\Учеба GeekBrains\3 quarter. Final\2. Django framework (Seminars)\GB_Django\.venv\Lib\site-packages\django\db\backends\utils.py", line 122, in execute
    return super().execute(sql, params)
           ^^^^^^^^^^^^^^^^^^^^^^^^^^^^
  File "E:\GeekBrains\Учеба GeekBrains\3 quarter. Final\2. Django framework (Seminars)\GB_Django\.venv\Lib\site-packages\django\db\backends\utils.py", line 79, in execute
    return self._execute_with_wrappers(
           ^^^^^^^^^^^^^^^^^^^^^^^^^^^^
  File "E:\GeekBrains\Учеба GeekBrains\3 quarter. Final\2. Django framework (Seminars)\GB_Django\.venv\Lib\site-packages\django\db\backends\utils.py", line 92, in _execute_with_wrappers
    return executor(sql, params, many, context)
           ^^^^^^^^^^^^^^^^^^^^^^^^^^^^^^^^^^^^
  File "E:\GeekBrains\Учеба GeekBrains\3 quarter. Final\2. Django framework (Seminars)\GB_Django\.venv\Lib\site-packages\django\db\backends\utils.py", line 100, in _execute
    with self.db.wrap_database_errors:
  File "E:\GeekBrains\Учеба GeekBrains\3 quarter. Final\2. Django framework (Seminars)\GB_Django\.venv\Lib\site-packages\django\db\utils.py", line 91, in __exit__
    raise dj_exc_value.with_traceback(traceback) from exc_value
  File "E:\GeekBrains\Учеба GeekBrains\3 quarter. Final\2. Django framework (Seminars)\GB_Django\.venv\Lib\site-packages\django\db\backends\utils.py", line 105, in _execute
    return self.cursor.execute(sql, params)
           ^^^^^^^^^^^^^^^^^^^^^^^^^^^^^^^^
  File "E:\GeekBrains\Учеба GeekBrains\3 quarter. Final\2. Django framework (Seminars)\GB_Django\.venv\Lib\site-packages\django\db\backends\sqlite3\base.py", line 329, in execute
    return super().execute(query, params)
           ^^^^^^^^^^^^^^^^^^^^^^^^^^^^^^
django.db.utils.OperationalError: no such table: shopapp_customer
ERROR 2024-04-06 04:05:39,221 basehttp 16824 8788 "GET /shop/fake_db/ HTTP/1.1" 500 153626
INFO 2024-04-06 04:11:45,778 autoreload 17328 16396 Watching for file changes with StatReloader
ERROR 2024-04-06 04:11:48,633 log 17328 3576 Internal Server Error: /shop/fake_db/
Traceback (most recent call last):
  File "E:\GeekBrains\Учеба GeekBrains\3 quarter. Final\2. Django framework (Seminars)\GB_Django\.venv\Lib\site-packages\django\core\handlers\exception.py", line 55, in inner
    response = get_response(request)
               ^^^^^^^^^^^^^^^^^^^^^
  File "E:\GeekBrains\Учеба GeekBrains\3 quarter. Final\2. Django framework (Seminars)\GB_Django\.venv\Lib\site-packages\django\core\handlers\base.py", line 197, in _get_response
    response = wrapped_callback(request, *callback_args, **callback_kwargs)
               ^^^^^^^^^^^^^^^^^^^^^^^^^^^^^^^^^^^^^^^^^^^^^^^^^^^^^^^^^^^^
  File "E:\GeekBrains\Учеба GeekBrains\3 quarter. Final\2. Django framework (Seminars)\GB_Django\Seminar2\HomeWork2\shopapp\views.py", line 65, in fake_db
    total_price=f'{round(random.uniform(0, 100), 2)}')
                         ^^^^^^^^^^^^^^
AttributeError: 'builtin_function_or_method' object has no attribute 'uniform'
ERROR 2024-04-06 04:11:48,635 basehttp 17328 3576 "GET /shop/fake_db/ HTTP/1.1" 500 69462
INFO 2024-04-06 04:12:48,745 autoreload 17328 16396 E:\GeekBrains\Учеба GeekBrains\3 quarter. Final\2. Django framework (Seminars)\GB_Django\Seminar2\HomeWork2\shopapp\views.py changed, reloading.
INFO 2024-04-06 04:12:49,298 autoreload 6364 13464 Watching for file changes with StatReloader
ERROR 2024-04-06 04:12:52,386 log 6364 15248 Internal Server Error: /shop/fake_db/
Traceback (most recent call last):
  File "E:\GeekBrains\Учеба GeekBrains\3 quarter. Final\2. Django framework (Seminars)\GB_Django\.venv\Lib\site-packages\django\core\handlers\exception.py", line 55, in inner
    response = get_response(request)
               ^^^^^^^^^^^^^^^^^^^^^
  File "E:\GeekBrains\Учеба GeekBrains\3 quarter. Final\2. Django framework (Seminars)\GB_Django\.venv\Lib\site-packages\django\core\handlers\base.py", line 197, in _get_response
    response = wrapped_callback(request, *callback_args, **callback_kwargs)
               ^^^^^^^^^^^^^^^^^^^^^^^^^^^^^^^^^^^^^^^^^^^^^^^^^^^^^^^^^^^^
  File "E:\GeekBrains\Учеба GeekBrains\3 quarter. Final\2. Django framework (Seminars)\GB_Django\Seminar2\HomeWork2\shopapp\views.py", line 63, in fake_db
    order = Order(customer=customer,
            ^^^^^^^^^^^^^^^^^^^^^^^^
  File "E:\GeekBrains\Учеба GeekBrains\3 quarter. Final\2. Django framework (Seminars)\GB_Django\.venv\Lib\site-packages\django\db\models\base.py", line 567, in __init__
    raise TypeError(
TypeError: Order() got unexpected keyword arguments: 'total_price'
ERROR 2024-04-06 04:12:52,389 basehttp 6364 15248 "GET /shop/fake_db/ HTTP/1.1" 500 76436
INFO 2024-04-06 04:16:30,075 autoreload 6364 13464 E:\GeekBrains\Учеба GeekBrains\3 quarter. Final\2. Django framework (Seminars)\GB_Django\Seminar2\HomeWork2\shopapp\views.py changed, reloading.
INFO 2024-04-06 04:16:30,651 autoreload 15976 10388 Watching for file changes with StatReloader
ERROR 2024-04-06 04:16:33,978 log 15976 16780 Internal Server Error: /shop/fake_db/
Traceback (most recent call last):
  File "E:\GeekBrains\Учеба GeekBrains\3 quarter. Final\2. Django framework (Seminars)\GB_Django\.venv\Lib\site-packages\django\core\handlers\exception.py", line 55, in inner
    response = get_response(request)
               ^^^^^^^^^^^^^^^^^^^^^
  File "E:\GeekBrains\Учеба GeekBrains\3 quarter. Final\2. Django framework (Seminars)\GB_Django\.venv\Lib\site-packages\django\core\handlers\base.py", line 197, in _get_response
    response = wrapped_callback(request, *callback_args, **callback_kwargs)
               ^^^^^^^^^^^^^^^^^^^^^^^^^^^^^^^^^^^^^^^^^^^^^^^^^^^^^^^^^^^^
  File "E:\GeekBrains\Учеба GeekBrains\3 quarter. Final\2. Django framework (Seminars)\GB_Django\Seminar2\HomeWork2\shopapp\views.py", line 63, in fake_db
    order = Order(customer=customer,
            ^^^^^^^^^^^^^^^^^^^^^^^^
  File "E:\GeekBrains\Учеба GeekBrains\3 quarter. Final\2. Django framework (Seminars)\GB_Django\.venv\Lib\site-packages\django\db\models\base.py", line 567, in __init__
    raise TypeError(
TypeError: Order() got unexpected keyword arguments: 'total_price'
ERROR 2024-04-06 04:16:33,980 basehttp 15976 16780 "GET /shop/fake_db/ HTTP/1.1" 500 76437
INFO 2024-04-06 04:17:33,766 autoreload 15976 10388 E:\GeekBrains\Учеба GeekBrains\3 quarter. Final\2. Django framework (Seminars)\GB_Django\Seminar2\HomeWork2\shopapp\views.py changed, reloading.
INFO 2024-04-06 04:17:34,387 autoreload 888 15884 Watching for file changes with StatReloader
ERROR 2024-04-06 04:17:37,350 log 888 6884 Internal Server Error: /shop/fake_db/
Traceback (most recent call last):
  File "E:\GeekBrains\Учеба GeekBrains\3 quarter. Final\2. Django framework (Seminars)\GB_Django\.venv\Lib\site-packages\django\db\backends\utils.py", line 105, in _execute
    return self.cursor.execute(sql, params)
           ^^^^^^^^^^^^^^^^^^^^^^^^^^^^^^^^
  File "E:\GeekBrains\Учеба GeekBrains\3 quarter. Final\2. Django framework (Seminars)\GB_Django\.venv\Lib\site-packages\django\db\backends\sqlite3\base.py", line 329, in execute
    return super().execute(query, params)
           ^^^^^^^^^^^^^^^^^^^^^^^^^^^^^^
sqlite3.IntegrityError: NOT NULL constraint failed: shopapp_product.quantity

The above exception was the direct cause of the following exception:

Traceback (most recent call last):
  File "E:\GeekBrains\Учеба GeekBrains\3 quarter. Final\2. Django framework (Seminars)\GB_Django\.venv\Lib\site-packages\django\core\handlers\exception.py", line 55, in inner
    response = get_response(request)
               ^^^^^^^^^^^^^^^^^^^^^
  File "E:\GeekBrains\Учеба GeekBrains\3 quarter. Final\2. Django framework (Seminars)\GB_Django\.venv\Lib\site-packages\django\core\handlers\base.py", line 197, in _get_response
    response = wrapped_callback(request, *callback_args, **callback_kwargs)
               ^^^^^^^^^^^^^^^^^^^^^^^^^^^^^^^^^^^^^^^^^^^^^^^^^^^^^^^^^^^^
  File "E:\GeekBrains\Учеба GeekBrains\3 quarter. Final\2. Django framework (Seminars)\GB_Django\Seminar2\HomeWork2\shopapp\views.py", line 71, in fake_db
    product.save()
  File "E:\GeekBrains\Учеба GeekBrains\3 quarter. Final\2. Django framework (Seminars)\GB_Django\.venv\Lib\site-packages\django\db\models\base.py", line 822, in save
    self.save_base(
  File "E:\GeekBrains\Учеба GeekBrains\3 quarter. Final\2. Django framework (Seminars)\GB_Django\.venv\Lib\site-packages\django\db\models\base.py", line 909, in save_base
    updated = self._save_table(
              ^^^^^^^^^^^^^^^^^
  File "E:\GeekBrains\Учеба GeekBrains\3 quarter. Final\2. Django framework (Seminars)\GB_Django\.venv\Lib\site-packages\django\db\models\base.py", line 1067, in _save_table
    results = self._do_insert(
              ^^^^^^^^^^^^^^^^
  File "E:\GeekBrains\Учеба GeekBrains\3 quarter. Final\2. Django framework (Seminars)\GB_Django\.venv\Lib\site-packages\django\db\models\base.py", line 1108, in _do_insert
    return manager._insert(
           ^^^^^^^^^^^^^^^^
  File "E:\GeekBrains\Учеба GeekBrains\3 quarter. Final\2. Django framework (Seminars)\GB_Django\.venv\Lib\site-packages\django\db\models\manager.py", line 87, in manager_method
    return getattr(self.get_queryset(), name)(*args, **kwargs)
           ^^^^^^^^^^^^^^^^^^^^^^^^^^^^^^^^^^^^^^^^^^^^^^^^^^^
  File "E:\GeekBrains\Учеба GeekBrains\3 quarter. Final\2. Django framework (Seminars)\GB_Django\.venv\Lib\site-packages\django\db\models\query.py", line 1847, in _insert
    return query.get_compiler(using=using).execute_sql(returning_fields)
           ^^^^^^^^^^^^^^^^^^^^^^^^^^^^^^^^^^^^^^^^^^^^^^^^^^^^^^^^^^^^^
  File "E:\GeekBrains\Учеба GeekBrains\3 quarter. Final\2. Django framework (Seminars)\GB_Django\.venv\Lib\site-packages\django\db\models\sql\compiler.py", line 1823, in execute_sql
    cursor.execute(sql, params)
  File "E:\GeekBrains\Учеба GeekBrains\3 quarter. Final\2. Django framework (Seminars)\GB_Django\.venv\Lib\site-packages\django\db\backends\utils.py", line 122, in execute
    return super().execute(sql, params)
           ^^^^^^^^^^^^^^^^^^^^^^^^^^^^
  File "E:\GeekBrains\Учеба GeekBrains\3 quarter. Final\2. Django framework (Seminars)\GB_Django\.venv\Lib\site-packages\django\db\backends\utils.py", line 79, in execute
    return self._execute_with_wrappers(
           ^^^^^^^^^^^^^^^^^^^^^^^^^^^^
  File "E:\GeekBrains\Учеба GeekBrains\3 quarter. Final\2. Django framework (Seminars)\GB_Django\.venv\Lib\site-packages\django\db\backends\utils.py", line 92, in _execute_with_wrappers
    return executor(sql, params, many, context)
           ^^^^^^^^^^^^^^^^^^^^^^^^^^^^^^^^^^^^
  File "E:\GeekBrains\Учеба GeekBrains\3 quarter. Final\2. Django framework (Seminars)\GB_Django\.venv\Lib\site-packages\django\db\backends\utils.py", line 100, in _execute
    with self.db.wrap_database_errors:
  File "E:\GeekBrains\Учеба GeekBrains\3 quarter. Final\2. Django framework (Seminars)\GB_Django\.venv\Lib\site-packages\django\db\utils.py", line 91, in __exit__
    raise dj_exc_value.with_traceback(traceback) from exc_value
  File "E:\GeekBrains\Учеба GeekBrains\3 quarter. Final\2. Django framework (Seminars)\GB_Django\.venv\Lib\site-packages\django\db\backends\utils.py", line 105, in _execute
    return self.cursor.execute(sql, params)
           ^^^^^^^^^^^^^^^^^^^^^^^^^^^^^^^^
  File "E:\GeekBrains\Учеба GeekBrains\3 quarter. Final\2. Django framework (Seminars)\GB_Django\.venv\Lib\site-packages\django\db\backends\sqlite3\base.py", line 329, in execute
    return super().execute(query, params)
           ^^^^^^^^^^^^^^^^^^^^^^^^^^^^^^
django.db.utils.IntegrityError: NOT NULL constraint failed: shopapp_product.quantity
ERROR 2024-04-06 04:17:37,357 basehttp 888 6884 "GET /shop/fake_db/ HTTP/1.1" 500 152637
INFO 2024-04-06 04:20:22,775 autoreload 16560 972 Watching for file changes with StatReloader
ERROR 2024-04-06 04:20:26,270 log 16560 15296 Internal Server Error: /shop/fake_db/
Traceback (most recent call last):
  File "E:\GeekBrains\Учеба GeekBrains\3 quarter. Final\2. Django framework (Seminars)\GB_Django\.venv\Lib\site-packages\django\db\backends\utils.py", line 105, in _execute
    return self.cursor.execute(sql, params)
           ^^^^^^^^^^^^^^^^^^^^^^^^^^^^^^^^
  File "E:\GeekBrains\Учеба GeekBrains\3 quarter. Final\2. Django framework (Seminars)\GB_Django\.venv\Lib\site-packages\django\db\backends\sqlite3\base.py", line 329, in execute
    return super().execute(query, params)
           ^^^^^^^^^^^^^^^^^^^^^^^^^^^^^^
sqlite3.IntegrityError: NOT NULL constraint failed: shopapp_product.quantity

The above exception was the direct cause of the following exception:

Traceback (most recent call last):
  File "E:\GeekBrains\Учеба GeekBrains\3 quarter. Final\2. Django framework (Seminars)\GB_Django\.venv\Lib\site-packages\django\core\handlers\exception.py", line 55, in inner
    response = get_response(request)
               ^^^^^^^^^^^^^^^^^^^^^
  File "E:\GeekBrains\Учеба GeekBrains\3 quarter. Final\2. Django framework (Seminars)\GB_Django\.venv\Lib\site-packages\django\core\handlers\base.py", line 197, in _get_response
    response = wrapped_callback(request, *callback_args, **callback_kwargs)
               ^^^^^^^^^^^^^^^^^^^^^^^^^^^^^^^^^^^^^^^^^^^^^^^^^^^^^^^^^^^^
  File "E:\GeekBrains\Учеба GeekBrains\3 quarter. Final\2. Django framework (Seminars)\GB_Django\Seminar2\HomeWork2\shopapp\views.py", line 71, in fake_db
    product.save()
  File "E:\GeekBrains\Учеба GeekBrains\3 quarter. Final\2. Django framework (Seminars)\GB_Django\.venv\Lib\site-packages\django\db\models\base.py", line 822, in save
    self.save_base(
  File "E:\GeekBrains\Учеба GeekBrains\3 quarter. Final\2. Django framework (Seminars)\GB_Django\.venv\Lib\site-packages\django\db\models\base.py", line 909, in save_base
    updated = self._save_table(
              ^^^^^^^^^^^^^^^^^
  File "E:\GeekBrains\Учеба GeekBrains\3 quarter. Final\2. Django framework (Seminars)\GB_Django\.venv\Lib\site-packages\django\db\models\base.py", line 1067, in _save_table
    results = self._do_insert(
              ^^^^^^^^^^^^^^^^
  File "E:\GeekBrains\Учеба GeekBrains\3 quarter. Final\2. Django framework (Seminars)\GB_Django\.venv\Lib\site-packages\django\db\models\base.py", line 1108, in _do_insert
    return manager._insert(
           ^^^^^^^^^^^^^^^^
  File "E:\GeekBrains\Учеба GeekBrains\3 quarter. Final\2. Django framework (Seminars)\GB_Django\.venv\Lib\site-packages\django\db\models\manager.py", line 87, in manager_method
    return getattr(self.get_queryset(), name)(*args, **kwargs)
           ^^^^^^^^^^^^^^^^^^^^^^^^^^^^^^^^^^^^^^^^^^^^^^^^^^^
  File "E:\GeekBrains\Учеба GeekBrains\3 quarter. Final\2. Django framework (Seminars)\GB_Django\.venv\Lib\site-packages\django\db\models\query.py", line 1847, in _insert
    return query.get_compiler(using=using).execute_sql(returning_fields)
           ^^^^^^^^^^^^^^^^^^^^^^^^^^^^^^^^^^^^^^^^^^^^^^^^^^^^^^^^^^^^^
  File "E:\GeekBrains\Учеба GeekBrains\3 quarter. Final\2. Django framework (Seminars)\GB_Django\.venv\Lib\site-packages\django\db\models\sql\compiler.py", line 1823, in execute_sql
    cursor.execute(sql, params)
  File "E:\GeekBrains\Учеба GeekBrains\3 quarter. Final\2. Django framework (Seminars)\GB_Django\.venv\Lib\site-packages\django\db\backends\utils.py", line 122, in execute
    return super().execute(sql, params)
           ^^^^^^^^^^^^^^^^^^^^^^^^^^^^
  File "E:\GeekBrains\Учеба GeekBrains\3 quarter. Final\2. Django framework (Seminars)\GB_Django\.venv\Lib\site-packages\django\db\backends\utils.py", line 79, in execute
    return self._execute_with_wrappers(
           ^^^^^^^^^^^^^^^^^^^^^^^^^^^^
  File "E:\GeekBrains\Учеба GeekBrains\3 quarter. Final\2. Django framework (Seminars)\GB_Django\.venv\Lib\site-packages\django\db\backends\utils.py", line 92, in _execute_with_wrappers
    return executor(sql, params, many, context)
           ^^^^^^^^^^^^^^^^^^^^^^^^^^^^^^^^^^^^
  File "E:\GeekBrains\Учеба GeekBrains\3 quarter. Final\2. Django framework (Seminars)\GB_Django\.venv\Lib\site-packages\django\db\backends\utils.py", line 100, in _execute
    with self.db.wrap_database_errors:
  File "E:\GeekBrains\Учеба GeekBrains\3 quarter. Final\2. Django framework (Seminars)\GB_Django\.venv\Lib\site-packages\django\db\utils.py", line 91, in __exit__
    raise dj_exc_value.with_traceback(traceback) from exc_value
  File "E:\GeekBrains\Учеба GeekBrains\3 quarter. Final\2. Django framework (Seminars)\GB_Django\.venv\Lib\site-packages\django\db\backends\utils.py", line 105, in _execute
    return self.cursor.execute(sql, params)
           ^^^^^^^^^^^^^^^^^^^^^^^^^^^^^^^^
  File "E:\GeekBrains\Учеба GeekBrains\3 quarter. Final\2. Django framework (Seminars)\GB_Django\.venv\Lib\site-packages\django\db\backends\sqlite3\base.py", line 329, in execute
    return super().execute(query, params)
           ^^^^^^^^^^^^^^^^^^^^^^^^^^^^^^
django.db.utils.IntegrityError: NOT NULL constraint failed: shopapp_product.quantity
ERROR 2024-04-06 04:20:26,276 basehttp 16560 15296 "GET /shop/fake_db/ HTTP/1.1" 500 152635
INFO 2024-04-06 04:26:58,526 autoreload 16560 972 E:\GeekBrains\Учеба GeekBrains\3 quarter. Final\2. Django framework (Seminars)\GB_Django\Seminar2\HomeWork2\shopapp\views.py changed, reloading.
INFO 2024-04-06 04:26:59,232 autoreload 15180 16388 Watching for file changes with StatReloader
ERROR 2024-04-06 04:27:06,217 log 15180 8152 Internal Server Error: /shop/fake_db/
Traceback (most recent call last):
  File "E:\GeekBrains\Учеба GeekBrains\3 quarter. Final\2. Django framework (Seminars)\GB_Django\.venv\Lib\site-packages\django\db\backends\utils.py", line 105, in _execute
    return self.cursor.execute(sql, params)
           ^^^^^^^^^^^^^^^^^^^^^^^^^^^^^^^^
  File "E:\GeekBrains\Учеба GeekBrains\3 quarter. Final\2. Django framework (Seminars)\GB_Django\.venv\Lib\site-packages\django\db\backends\sqlite3\base.py", line 329, in execute
    return super().execute(query, params)
           ^^^^^^^^^^^^^^^^^^^^^^^^^^^^^^
sqlite3.IntegrityError: NOT NULL constraint failed: shopapp_product.quantity

The above exception was the direct cause of the following exception:

Traceback (most recent call last):
  File "E:\GeekBrains\Учеба GeekBrains\3 quarter. Final\2. Django framework (Seminars)\GB_Django\.venv\Lib\site-packages\django\core\handlers\exception.py", line 55, in inner
    response = get_response(request)
               ^^^^^^^^^^^^^^^^^^^^^
  File "E:\GeekBrains\Учеба GeekBrains\3 quarter. Final\2. Django framework (Seminars)\GB_Django\.venv\Lib\site-packages\django\core\handlers\base.py", line 197, in _get_response
    response = wrapped_callback(request, *callback_args, **callback_kwargs)
               ^^^^^^^^^^^^^^^^^^^^^^^^^^^^^^^^^^^^^^^^^^^^^^^^^^^^^^^^^^^^
  File "E:\GeekBrains\Учеба GeekBrains\3 quarter. Final\2. Django framework (Seminars)\GB_Django\Seminar2\HomeWork2\shopapp\views.py", line 67, in fake_db
    product.save()
  File "E:\GeekBrains\Учеба GeekBrains\3 quarter. Final\2. Django framework (Seminars)\GB_Django\.venv\Lib\site-packages\django\db\models\base.py", line 822, in save
    self.save_base(
  File "E:\GeekBrains\Учеба GeekBrains\3 quarter. Final\2. Django framework (Seminars)\GB_Django\.venv\Lib\site-packages\django\db\models\base.py", line 909, in save_base
    updated = self._save_table(
              ^^^^^^^^^^^^^^^^^
  File "E:\GeekBrains\Учеба GeekBrains\3 quarter. Final\2. Django framework (Seminars)\GB_Django\.venv\Lib\site-packages\django\db\models\base.py", line 1067, in _save_table
    results = self._do_insert(
              ^^^^^^^^^^^^^^^^
  File "E:\GeekBrains\Учеба GeekBrains\3 quarter. Final\2. Django framework (Seminars)\GB_Django\.venv\Lib\site-packages\django\db\models\base.py", line 1108, in _do_insert
    return manager._insert(
           ^^^^^^^^^^^^^^^^
  File "E:\GeekBrains\Учеба GeekBrains\3 quarter. Final\2. Django framework (Seminars)\GB_Django\.venv\Lib\site-packages\django\db\models\manager.py", line 87, in manager_method
    return getattr(self.get_queryset(), name)(*args, **kwargs)
           ^^^^^^^^^^^^^^^^^^^^^^^^^^^^^^^^^^^^^^^^^^^^^^^^^^^
  File "E:\GeekBrains\Учеба GeekBrains\3 quarter. Final\2. Django framework (Seminars)\GB_Django\.venv\Lib\site-packages\django\db\models\query.py", line 1847, in _insert
    return query.get_compiler(using=using).execute_sql(returning_fields)
           ^^^^^^^^^^^^^^^^^^^^^^^^^^^^^^^^^^^^^^^^^^^^^^^^^^^^^^^^^^^^^
  File "E:\GeekBrains\Учеба GeekBrains\3 quarter. Final\2. Django framework (Seminars)\GB_Django\.venv\Lib\site-packages\django\db\models\sql\compiler.py", line 1823, in execute_sql
    cursor.execute(sql, params)
  File "E:\GeekBrains\Учеба GeekBrains\3 quarter. Final\2. Django framework (Seminars)\GB_Django\.venv\Lib\site-packages\django\db\backends\utils.py", line 122, in execute
    return super().execute(sql, params)
           ^^^^^^^^^^^^^^^^^^^^^^^^^^^^
  File "E:\GeekBrains\Учеба GeekBrains\3 quarter. Final\2. Django framework (Seminars)\GB_Django\.venv\Lib\site-packages\django\db\backends\utils.py", line 79, in execute
    return self._execute_with_wrappers(
           ^^^^^^^^^^^^^^^^^^^^^^^^^^^^
  File "E:\GeekBrains\Учеба GeekBrains\3 quarter. Final\2. Django framework (Seminars)\GB_Django\.venv\Lib\site-packages\django\db\backends\utils.py", line 92, in _execute_with_wrappers
    return executor(sql, params, many, context)
           ^^^^^^^^^^^^^^^^^^^^^^^^^^^^^^^^^^^^
  File "E:\GeekBrains\Учеба GeekBrains\3 quarter. Final\2. Django framework (Seminars)\GB_Django\.venv\Lib\site-packages\django\db\backends\utils.py", line 100, in _execute
    with self.db.wrap_database_errors:
  File "E:\GeekBrains\Учеба GeekBrains\3 quarter. Final\2. Django framework (Seminars)\GB_Django\.venv\Lib\site-packages\django\db\utils.py", line 91, in __exit__
    raise dj_exc_value.with_traceback(traceback) from exc_value
  File "E:\GeekBrains\Учеба GeekBrains\3 quarter. Final\2. Django framework (Seminars)\GB_Django\.venv\Lib\site-packages\django\db\backends\utils.py", line 105, in _execute
    return self.cursor.execute(sql, params)
           ^^^^^^^^^^^^^^^^^^^^^^^^^^^^^^^^
  File "E:\GeekBrains\Учеба GeekBrains\3 quarter. Final\2. Django framework (Seminars)\GB_Django\.venv\Lib\site-packages\django\db\backends\sqlite3\base.py", line 329, in execute
    return super().execute(query, params)
           ^^^^^^^^^^^^^^^^^^^^^^^^^^^^^^
django.db.utils.IntegrityError: NOT NULL constraint failed: shopapp_product.quantity
ERROR 2024-04-06 04:27:06,223 basehttp 15180 8152 "GET /shop/fake_db/ HTTP/1.1" 500 153136
INFO 2024-04-06 04:29:18,582 autoreload 15180 16388 E:\GeekBrains\Учеба GeekBrains\3 quarter. Final\2. Django framework (Seminars)\GB_Django\Seminar2\HomeWork2\shopapp\models.py changed, reloading.
INFO 2024-04-06 04:29:19,183 autoreload 8580 8932 Watching for file changes with StatReloader
ERROR 2024-04-06 04:29:35,534 log 8580 10564 Internal Server Error: /shop/fake_db/
Traceback (most recent call last):
  File "E:\GeekBrains\Учеба GeekBrains\3 quarter. Final\2. Django framework (Seminars)\GB_Django\.venv\Lib\site-packages\django\db\backends\utils.py", line 105, in _execute
    return self.cursor.execute(sql, params)
           ^^^^^^^^^^^^^^^^^^^^^^^^^^^^^^^^
  File "E:\GeekBrains\Учеба GeekBrains\3 quarter. Final\2. Django framework (Seminars)\GB_Django\.venv\Lib\site-packages\django\db\backends\sqlite3\base.py", line 329, in execute
    return super().execute(query, params)
           ^^^^^^^^^^^^^^^^^^^^^^^^^^^^^^
sqlite3.IntegrityError: NOT NULL constraint failed: shopapp_product.quantity

The above exception was the direct cause of the following exception:

Traceback (most recent call last):
  File "E:\GeekBrains\Учеба GeekBrains\3 quarter. Final\2. Django framework (Seminars)\GB_Django\.venv\Lib\site-packages\django\core\handlers\exception.py", line 55, in inner
    response = get_response(request)
               ^^^^^^^^^^^^^^^^^^^^^
  File "E:\GeekBrains\Учеба GeekBrains\3 quarter. Final\2. Django framework (Seminars)\GB_Django\.venv\Lib\site-packages\django\core\handlers\base.py", line 197, in _get_response
    response = wrapped_callback(request, *callback_args, **callback_kwargs)
               ^^^^^^^^^^^^^^^^^^^^^^^^^^^^^^^^^^^^^^^^^^^^^^^^^^^^^^^^^^^^
  File "E:\GeekBrains\Учеба GeekBrains\3 quarter. Final\2. Django framework (Seminars)\GB_Django\Seminar2\HomeWork2\shopapp\views.py", line 67, in fake_db
    product.save()
  File "E:\GeekBrains\Учеба GeekBrains\3 quarter. Final\2. Django framework (Seminars)\GB_Django\.venv\Lib\site-packages\django\db\models\base.py", line 822, in save
    self.save_base(
  File "E:\GeekBrains\Учеба GeekBrains\3 quarter. Final\2. Django framework (Seminars)\GB_Django\.venv\Lib\site-packages\django\db\models\base.py", line 909, in save_base
    updated = self._save_table(
              ^^^^^^^^^^^^^^^^^
  File "E:\GeekBrains\Учеба GeekBrains\3 quarter. Final\2. Django framework (Seminars)\GB_Django\.venv\Lib\site-packages\django\db\models\base.py", line 1067, in _save_table
    results = self._do_insert(
              ^^^^^^^^^^^^^^^^
  File "E:\GeekBrains\Учеба GeekBrains\3 quarter. Final\2. Django framework (Seminars)\GB_Django\.venv\Lib\site-packages\django\db\models\base.py", line 1108, in _do_insert
    return manager._insert(
           ^^^^^^^^^^^^^^^^
  File "E:\GeekBrains\Учеба GeekBrains\3 quarter. Final\2. Django framework (Seminars)\GB_Django\.venv\Lib\site-packages\django\db\models\manager.py", line 87, in manager_method
    return getattr(self.get_queryset(), name)(*args, **kwargs)
           ^^^^^^^^^^^^^^^^^^^^^^^^^^^^^^^^^^^^^^^^^^^^^^^^^^^
  File "E:\GeekBrains\Учеба GeekBrains\3 quarter. Final\2. Django framework (Seminars)\GB_Django\.venv\Lib\site-packages\django\db\models\query.py", line 1847, in _insert
    return query.get_compiler(using=using).execute_sql(returning_fields)
           ^^^^^^^^^^^^^^^^^^^^^^^^^^^^^^^^^^^^^^^^^^^^^^^^^^^^^^^^^^^^^
  File "E:\GeekBrains\Учеба GeekBrains\3 quarter. Final\2. Django framework (Seminars)\GB_Django\.venv\Lib\site-packages\django\db\models\sql\compiler.py", line 1823, in execute_sql
    cursor.execute(sql, params)
  File "E:\GeekBrains\Учеба GeekBrains\3 quarter. Final\2. Django framework (Seminars)\GB_Django\.venv\Lib\site-packages\django\db\backends\utils.py", line 122, in execute
    return super().execute(sql, params)
           ^^^^^^^^^^^^^^^^^^^^^^^^^^^^
  File "E:\GeekBrains\Учеба GeekBrains\3 quarter. Final\2. Django framework (Seminars)\GB_Django\.venv\Lib\site-packages\django\db\backends\utils.py", line 79, in execute
    return self._execute_with_wrappers(
           ^^^^^^^^^^^^^^^^^^^^^^^^^^^^
  File "E:\GeekBrains\Учеба GeekBrains\3 quarter. Final\2. Django framework (Seminars)\GB_Django\.venv\Lib\site-packages\django\db\backends\utils.py", line 92, in _execute_with_wrappers
    return executor(sql, params, many, context)
           ^^^^^^^^^^^^^^^^^^^^^^^^^^^^^^^^^^^^
  File "E:\GeekBrains\Учеба GeekBrains\3 quarter. Final\2. Django framework (Seminars)\GB_Django\.venv\Lib\site-packages\django\db\backends\utils.py", line 100, in _execute
    with self.db.wrap_database_errors:
  File "E:\GeekBrains\Учеба GeekBrains\3 quarter. Final\2. Django framework (Seminars)\GB_Django\.venv\Lib\site-packages\django\db\utils.py", line 91, in __exit__
    raise dj_exc_value.with_traceback(traceback) from exc_value
  File "E:\GeekBrains\Учеба GeekBrains\3 quarter. Final\2. Django framework (Seminars)\GB_Django\.venv\Lib\site-packages\django\db\backends\utils.py", line 105, in _execute
    return self.cursor.execute(sql, params)
           ^^^^^^^^^^^^^^^^^^^^^^^^^^^^^^^^
  File "E:\GeekBrains\Учеба GeekBrains\3 quarter. Final\2. Django framework (Seminars)\GB_Django\.venv\Lib\site-packages\django\db\backends\sqlite3\base.py", line 329, in execute
    return super().execute(query, params)
           ^^^^^^^^^^^^^^^^^^^^^^^^^^^^^^
django.db.utils.IntegrityError: NOT NULL constraint failed: shopapp_product.quantity
ERROR 2024-04-06 04:29:35,541 basehttp 8580 10564 "GET /shop/fake_db/ HTTP/1.1" 500 153143
INFO 2024-04-06 04:30:01,454 autoreload 8580 8932 E:\GeekBrains\Учеба GeekBrains\3 quarter. Final\2. Django framework (Seminars)\GB_Django\Seminar2\HomeWork2\shopapp\models.py changed, reloading.
INFO 2024-04-06 04:30:02,026 autoreload 12048 2628 Watching for file changes with StatReloader
INFO 2024-04-06 04:31:43,813 autoreload 12048 2628 E:\GeekBrains\Учеба GeekBrains\3 quarter. Final\2. Django framework (Seminars)\GB_Django\Seminar2\HomeWork2\shopapp\models.py changed, reloading.
INFO 2024-04-06 04:31:44,387 autoreload 16408 15672 Watching for file changes with StatReloader
ERROR 2024-04-06 04:31:47,669 log 16408 15500 Internal Server Error: /shop/fake_db/
Traceback (most recent call last):
  File "E:\GeekBrains\Учеба GeekBrains\3 quarter. Final\2. Django framework (Seminars)\GB_Django\.venv\Lib\site-packages\django\db\backends\utils.py", line 105, in _execute
    return self.cursor.execute(sql, params)
           ^^^^^^^^^^^^^^^^^^^^^^^^^^^^^^^^
  File "E:\GeekBrains\Учеба GeekBrains\3 quarter. Final\2. Django framework (Seminars)\GB_Django\.venv\Lib\site-packages\django\db\backends\sqlite3\base.py", line 329, in execute
    return super().execute(query, params)
           ^^^^^^^^^^^^^^^^^^^^^^^^^^^^^^
sqlite3.IntegrityError: NOT NULL constraint failed: shopapp_product.quantity

The above exception was the direct cause of the following exception:

Traceback (most recent call last):
  File "E:\GeekBrains\Учеба GeekBrains\3 quarter. Final\2. Django framework (Seminars)\GB_Django\.venv\Lib\site-packages\django\core\handlers\exception.py", line 55, in inner
    response = get_response(request)
               ^^^^^^^^^^^^^^^^^^^^^
  File "E:\GeekBrains\Учеба GeekBrains\3 quarter. Final\2. Django framework (Seminars)\GB_Django\.venv\Lib\site-packages\django\core\handlers\base.py", line 197, in _get_response
    response = wrapped_callback(request, *callback_args, **callback_kwargs)
               ^^^^^^^^^^^^^^^^^^^^^^^^^^^^^^^^^^^^^^^^^^^^^^^^^^^^^^^^^^^^
  File "E:\GeekBrains\Учеба GeekBrains\3 quarter. Final\2. Django framework (Seminars)\GB_Django\Seminar2\HomeWork2\shopapp\views.py", line 67, in fake_db
    product.save()
  File "E:\GeekBrains\Учеба GeekBrains\3 quarter. Final\2. Django framework (Seminars)\GB_Django\.venv\Lib\site-packages\django\db\models\base.py", line 822, in save
    self.save_base(
  File "E:\GeekBrains\Учеба GeekBrains\3 quarter. Final\2. Django framework (Seminars)\GB_Django\.venv\Lib\site-packages\django\db\models\base.py", line 909, in save_base
    updated = self._save_table(
              ^^^^^^^^^^^^^^^^^
  File "E:\GeekBrains\Учеба GeekBrains\3 quarter. Final\2. Django framework (Seminars)\GB_Django\.venv\Lib\site-packages\django\db\models\base.py", line 1067, in _save_table
    results = self._do_insert(
              ^^^^^^^^^^^^^^^^
  File "E:\GeekBrains\Учеба GeekBrains\3 quarter. Final\2. Django framework (Seminars)\GB_Django\.venv\Lib\site-packages\django\db\models\base.py", line 1108, in _do_insert
    return manager._insert(
           ^^^^^^^^^^^^^^^^
  File "E:\GeekBrains\Учеба GeekBrains\3 quarter. Final\2. Django framework (Seminars)\GB_Django\.venv\Lib\site-packages\django\db\models\manager.py", line 87, in manager_method
    return getattr(self.get_queryset(), name)(*args, **kwargs)
           ^^^^^^^^^^^^^^^^^^^^^^^^^^^^^^^^^^^^^^^^^^^^^^^^^^^
  File "E:\GeekBrains\Учеба GeekBrains\3 quarter. Final\2. Django framework (Seminars)\GB_Django\.venv\Lib\site-packages\django\db\models\query.py", line 1847, in _insert
    return query.get_compiler(using=using).execute_sql(returning_fields)
           ^^^^^^^^^^^^^^^^^^^^^^^^^^^^^^^^^^^^^^^^^^^^^^^^^^^^^^^^^^^^^
  File "E:\GeekBrains\Учеба GeekBrains\3 quarter. Final\2. Django framework (Seminars)\GB_Django\.venv\Lib\site-packages\django\db\models\sql\compiler.py", line 1823, in execute_sql
    cursor.execute(sql, params)
  File "E:\GeekBrains\Учеба GeekBrains\3 quarter. Final\2. Django framework (Seminars)\GB_Django\.venv\Lib\site-packages\django\db\backends\utils.py", line 122, in execute
    return super().execute(sql, params)
           ^^^^^^^^^^^^^^^^^^^^^^^^^^^^
  File "E:\GeekBrains\Учеба GeekBrains\3 quarter. Final\2. Django framework (Seminars)\GB_Django\.venv\Lib\site-packages\django\db\backends\utils.py", line 79, in execute
    return self._execute_with_wrappers(
           ^^^^^^^^^^^^^^^^^^^^^^^^^^^^
  File "E:\GeekBrains\Учеба GeekBrains\3 quarter. Final\2. Django framework (Seminars)\GB_Django\.venv\Lib\site-packages\django\db\backends\utils.py", line 92, in _execute_with_wrappers
    return executor(sql, params, many, context)
           ^^^^^^^^^^^^^^^^^^^^^^^^^^^^^^^^^^^^
  File "E:\GeekBrains\Учеба GeekBrains\3 quarter. Final\2. Django framework (Seminars)\GB_Django\.venv\Lib\site-packages\django\db\backends\utils.py", line 100, in _execute
    with self.db.wrap_database_errors:
  File "E:\GeekBrains\Учеба GeekBrains\3 quarter. Final\2. Django framework (Seminars)\GB_Django\.venv\Lib\site-packages\django\db\utils.py", line 91, in __exit__
    raise dj_exc_value.with_traceback(traceback) from exc_value
  File "E:\GeekBrains\Учеба GeekBrains\3 quarter. Final\2. Django framework (Seminars)\GB_Django\.venv\Lib\site-packages\django\db\backends\utils.py", line 105, in _execute
    return self.cursor.execute(sql, params)
           ^^^^^^^^^^^^^^^^^^^^^^^^^^^^^^^^
  File "E:\GeekBrains\Учеба GeekBrains\3 quarter. Final\2. Django framework (Seminars)\GB_Django\.venv\Lib\site-packages\django\db\backends\sqlite3\base.py", line 329, in execute
    return super().execute(query, params)
           ^^^^^^^^^^^^^^^^^^^^^^^^^^^^^^
django.db.utils.IntegrityError: NOT NULL constraint failed: shopapp_product.quantity
ERROR 2024-04-06 04:31:47,675 basehttp 16408 15500 "GET /shop/fake_db/ HTTP/1.1" 500 153160
INFO 2024-04-06 04:37:36,854 autoreload 16408 15672 E:\GeekBrains\Учеба GeekBrains\3 quarter. Final\2. Django framework (Seminars)\GB_Django\Seminar2\HomeWork2\shopapp\views.py changed, reloading.
INFO 2024-04-06 04:37:37,526 autoreload 16556 14756 Watching for file changes with StatReloader
WARNING 2024-04-06 04:39:06,719 log 16556 14980 Not Found: /
WARNING 2024-04-06 04:39:06,719 basehttp 16556 14980 "GET / HTTP/1.1" 404 2167
INFO 2024-04-06 04:39:23,659 basehttp 16556 14980 "GET /shop/ HTTP/1.1" 200 1637
ERROR 2024-04-06 04:39:36,464 log 16556 14980 Internal Server Error: /shop/fake_db/
Traceback (most recent call last):
  File "E:\GeekBrains\Учеба GeekBrains\3 quarter. Final\2. Django framework (Seminars)\GB_Django\.venv\Lib\site-packages\django\db\backends\utils.py", line 105, in _execute
    return self.cursor.execute(sql, params)
           ^^^^^^^^^^^^^^^^^^^^^^^^^^^^^^^^
  File "E:\GeekBrains\Учеба GeekBrains\3 quarter. Final\2. Django framework (Seminars)\GB_Django\.venv\Lib\site-packages\django\db\backends\sqlite3\base.py", line 329, in execute
    return super().execute(query, params)
           ^^^^^^^^^^^^^^^^^^^^^^^^^^^^^^
sqlite3.IntegrityError: NOT NULL constraint failed: shopapp_product.quantity

The above exception was the direct cause of the following exception:

Traceback (most recent call last):
  File "E:\GeekBrains\Учеба GeekBrains\3 quarter. Final\2. Django framework (Seminars)\GB_Django\.venv\Lib\site-packages\django\core\handlers\exception.py", line 55, in inner
    response = get_response(request)
               ^^^^^^^^^^^^^^^^^^^^^
  File "E:\GeekBrains\Учеба GeekBrains\3 quarter. Final\2. Django framework (Seminars)\GB_Django\.venv\Lib\site-packages\django\core\handlers\base.py", line 197, in _get_response
    response = wrapped_callback(request, *callback_args, **callback_kwargs)
               ^^^^^^^^^^^^^^^^^^^^^^^^^^^^^^^^^^^^^^^^^^^^^^^^^^^^^^^^^^^^
  File "E:\GeekBrains\Учеба GeekBrains\3 quarter. Final\2. Django framework (Seminars)\GB_Django\Seminar2\HomeWork2\shopapp\views.py", line 67, in fake_db
    product.save()
  File "E:\GeekBrains\Учеба GeekBrains\3 quarter. Final\2. Django framework (Seminars)\GB_Django\.venv\Lib\site-packages\django\db\models\base.py", line 822, in save
    self.save_base(
  File "E:\GeekBrains\Учеба GeekBrains\3 quarter. Final\2. Django framework (Seminars)\GB_Django\.venv\Lib\site-packages\django\db\models\base.py", line 909, in save_base
    updated = self._save_table(
              ^^^^^^^^^^^^^^^^^
  File "E:\GeekBrains\Учеба GeekBrains\3 quarter. Final\2. Django framework (Seminars)\GB_Django\.venv\Lib\site-packages\django\db\models\base.py", line 1067, in _save_table
    results = self._do_insert(
              ^^^^^^^^^^^^^^^^
  File "E:\GeekBrains\Учеба GeekBrains\3 quarter. Final\2. Django framework (Seminars)\GB_Django\.venv\Lib\site-packages\django\db\models\base.py", line 1108, in _do_insert
    return manager._insert(
           ^^^^^^^^^^^^^^^^
  File "E:\GeekBrains\Учеба GeekBrains\3 quarter. Final\2. Django framework (Seminars)\GB_Django\.venv\Lib\site-packages\django\db\models\manager.py", line 87, in manager_method
    return getattr(self.get_queryset(), name)(*args, **kwargs)
           ^^^^^^^^^^^^^^^^^^^^^^^^^^^^^^^^^^^^^^^^^^^^^^^^^^^
  File "E:\GeekBrains\Учеба GeekBrains\3 quarter. Final\2. Django framework (Seminars)\GB_Django\.venv\Lib\site-packages\django\db\models\query.py", line 1847, in _insert
    return query.get_compiler(using=using).execute_sql(returning_fields)
           ^^^^^^^^^^^^^^^^^^^^^^^^^^^^^^^^^^^^^^^^^^^^^^^^^^^^^^^^^^^^^
  File "E:\GeekBrains\Учеба GeekBrains\3 quarter. Final\2. Django framework (Seminars)\GB_Django\.venv\Lib\site-packages\django\db\models\sql\compiler.py", line 1823, in execute_sql
    cursor.execute(sql, params)
  File "E:\GeekBrains\Учеба GeekBrains\3 quarter. Final\2. Django framework (Seminars)\GB_Django\.venv\Lib\site-packages\django\db\backends\utils.py", line 122, in execute
    return super().execute(sql, params)
           ^^^^^^^^^^^^^^^^^^^^^^^^^^^^
  File "E:\GeekBrains\Учеба GeekBrains\3 quarter. Final\2. Django framework (Seminars)\GB_Django\.venv\Lib\site-packages\django\db\backends\utils.py", line 79, in execute
    return self._execute_with_wrappers(
           ^^^^^^^^^^^^^^^^^^^^^^^^^^^^
  File "E:\GeekBrains\Учеба GeekBrains\3 quarter. Final\2. Django framework (Seminars)\GB_Django\.venv\Lib\site-packages\django\db\backends\utils.py", line 92, in _execute_with_wrappers
    return executor(sql, params, many, context)
           ^^^^^^^^^^^^^^^^^^^^^^^^^^^^^^^^^^^^
  File "E:\GeekBrains\Учеба GeekBrains\3 quarter. Final\2. Django framework (Seminars)\GB_Django\.venv\Lib\site-packages\django\db\backends\utils.py", line 100, in _execute
    with self.db.wrap_database_errors:
  File "E:\GeekBrains\Учеба GeekBrains\3 quarter. Final\2. Django framework (Seminars)\GB_Django\.venv\Lib\site-packages\django\db\utils.py", line 91, in __exit__
    raise dj_exc_value.with_traceback(traceback) from exc_value
  File "E:\GeekBrains\Учеба GeekBrains\3 quarter. Final\2. Django framework (Seminars)\GB_Django\.venv\Lib\site-packages\django\db\backends\utils.py", line 105, in _execute
    return self.cursor.execute(sql, params)
           ^^^^^^^^^^^^^^^^^^^^^^^^^^^^^^^^
  File "E:\GeekBrains\Учеба GeekBrains\3 quarter. Final\2. Django framework (Seminars)\GB_Django\.venv\Lib\site-packages\django\db\backends\sqlite3\base.py", line 329, in execute
    return super().execute(query, params)
           ^^^^^^^^^^^^^^^^^^^^^^^^^^^^^^
django.db.utils.IntegrityError: NOT NULL constraint failed: shopapp_product.quantity
ERROR 2024-04-06 04:39:36,469 basehttp 16556 14980 "GET /shop/fake_db/ HTTP/1.1" 500 153016
INFO 2024-04-06 04:44:34,973 autoreload 16556 14756 E:\GeekBrains\Учеба GeekBrains\3 quarter. Final\2. Django framework (Seminars)\GB_Django\Seminar2\HomeWork2\shopapp\models.py changed, reloading.
INFO 2024-04-06 04:44:35,619 autoreload 14740 2464 Watching for file changes with StatReloader
ERROR 2024-04-06 04:44:38,512 log 14740 12704 Internal Server Error: /shop/fake_db/
Traceback (most recent call last):
  File "E:\GeekBrains\Учеба GeekBrains\3 quarter. Final\2. Django framework (Seminars)\GB_Django\.venv\Lib\site-packages\django\db\backends\utils.py", line 105, in _execute
    return self.cursor.execute(sql, params)
           ^^^^^^^^^^^^^^^^^^^^^^^^^^^^^^^^
  File "E:\GeekBrains\Учеба GeekBrains\3 quarter. Final\2. Django framework (Seminars)\GB_Django\.venv\Lib\site-packages\django\db\backends\sqlite3\base.py", line 329, in execute
    return super().execute(query, params)
           ^^^^^^^^^^^^^^^^^^^^^^^^^^^^^^
sqlite3.IntegrityError: NOT NULL constraint failed: shopapp_product.quantity

The above exception was the direct cause of the following exception:

Traceback (most recent call last):
  File "E:\GeekBrains\Учеба GeekBrains\3 quarter. Final\2. Django framework (Seminars)\GB_Django\.venv\Lib\site-packages\django\core\handlers\exception.py", line 55, in inner
    response = get_response(request)
               ^^^^^^^^^^^^^^^^^^^^^
  File "E:\GeekBrains\Учеба GeekBrains\3 quarter. Final\2. Django framework (Seminars)\GB_Django\.venv\Lib\site-packages\django\core\handlers\base.py", line 197, in _get_response
    response = wrapped_callback(request, *callback_args, **callback_kwargs)
               ^^^^^^^^^^^^^^^^^^^^^^^^^^^^^^^^^^^^^^^^^^^^^^^^^^^^^^^^^^^^
  File "E:\GeekBrains\Учеба GeekBrains\3 quarter. Final\2. Django framework (Seminars)\GB_Django\Seminar2\HomeWork2\shopapp\views.py", line 67, in fake_db
    product.save()
  File "E:\GeekBrains\Учеба GeekBrains\3 quarter. Final\2. Django framework (Seminars)\GB_Django\.venv\Lib\site-packages\django\db\models\base.py", line 822, in save
    self.save_base(
  File "E:\GeekBrains\Учеба GeekBrains\3 quarter. Final\2. Django framework (Seminars)\GB_Django\.venv\Lib\site-packages\django\db\models\base.py", line 909, in save_base
    updated = self._save_table(
              ^^^^^^^^^^^^^^^^^
  File "E:\GeekBrains\Учеба GeekBrains\3 quarter. Final\2. Django framework (Seminars)\GB_Django\.venv\Lib\site-packages\django\db\models\base.py", line 1067, in _save_table
    results = self._do_insert(
              ^^^^^^^^^^^^^^^^
  File "E:\GeekBrains\Учеба GeekBrains\3 quarter. Final\2. Django framework (Seminars)\GB_Django\.venv\Lib\site-packages\django\db\models\base.py", line 1108, in _do_insert
    return manager._insert(
           ^^^^^^^^^^^^^^^^
  File "E:\GeekBrains\Учеба GeekBrains\3 quarter. Final\2. Django framework (Seminars)\GB_Django\.venv\Lib\site-packages\django\db\models\manager.py", line 87, in manager_method
    return getattr(self.get_queryset(), name)(*args, **kwargs)
           ^^^^^^^^^^^^^^^^^^^^^^^^^^^^^^^^^^^^^^^^^^^^^^^^^^^
  File "E:\GeekBrains\Учеба GeekBrains\3 quarter. Final\2. Django framework (Seminars)\GB_Django\.venv\Lib\site-packages\django\db\models\query.py", line 1847, in _insert
    return query.get_compiler(using=using).execute_sql(returning_fields)
           ^^^^^^^^^^^^^^^^^^^^^^^^^^^^^^^^^^^^^^^^^^^^^^^^^^^^^^^^^^^^^
  File "E:\GeekBrains\Учеба GeekBrains\3 quarter. Final\2. Django framework (Seminars)\GB_Django\.venv\Lib\site-packages\django\db\models\sql\compiler.py", line 1823, in execute_sql
    cursor.execute(sql, params)
  File "E:\GeekBrains\Учеба GeekBrains\3 quarter. Final\2. Django framework (Seminars)\GB_Django\.venv\Lib\site-packages\django\db\backends\utils.py", line 122, in execute
    return super().execute(sql, params)
           ^^^^^^^^^^^^^^^^^^^^^^^^^^^^
  File "E:\GeekBrains\Учеба GeekBrains\3 quarter. Final\2. Django framework (Seminars)\GB_Django\.venv\Lib\site-packages\django\db\backends\utils.py", line 79, in execute
    return self._execute_with_wrappers(
           ^^^^^^^^^^^^^^^^^^^^^^^^^^^^
  File "E:\GeekBrains\Учеба GeekBrains\3 quarter. Final\2. Django framework (Seminars)\GB_Django\.venv\Lib\site-packages\django\db\backends\utils.py", line 92, in _execute_with_wrappers
    return executor(sql, params, many, context)
           ^^^^^^^^^^^^^^^^^^^^^^^^^^^^^^^^^^^^
  File "E:\GeekBrains\Учеба GeekBrains\3 quarter. Final\2. Django framework (Seminars)\GB_Django\.venv\Lib\site-packages\django\db\backends\utils.py", line 100, in _execute
    with self.db.wrap_database_errors:
  File "E:\GeekBrains\Учеба GeekBrains\3 quarter. Final\2. Django framework (Seminars)\GB_Django\.venv\Lib\site-packages\django\db\utils.py", line 91, in __exit__
    raise dj_exc_value.with_traceback(traceback) from exc_value
  File "E:\GeekBrains\Учеба GeekBrains\3 quarter. Final\2. Django framework (Seminars)\GB_Django\.venv\Lib\site-packages\django\db\backends\utils.py", line 105, in _execute
    return self.cursor.execute(sql, params)
           ^^^^^^^^^^^^^^^^^^^^^^^^^^^^^^^^
  File "E:\GeekBrains\Учеба GeekBrains\3 quarter. Final\2. Django framework (Seminars)\GB_Django\.venv\Lib\site-packages\django\db\backends\sqlite3\base.py", line 329, in execute
    return super().execute(query, params)
           ^^^^^^^^^^^^^^^^^^^^^^^^^^^^^^
django.db.utils.IntegrityError: NOT NULL constraint failed: shopapp_product.quantity
ERROR 2024-04-06 04:44:38,518 basehttp 14740 12704 "GET /shop/fake_db/ HTTP/1.1" 500 153159
INFO 2024-04-06 04:48:53,262 autoreload 14740 2464 E:\GeekBrains\Учеба GeekBrains\3 quarter. Final\2. Django framework (Seminars)\GB_Django\Seminar2\HomeWork2\shopapp\views.py changed, reloading.
INFO 2024-04-06 04:48:53,831 autoreload 15672 17224 Watching for file changes with StatReloader
INFO 2024-04-06 04:49:28,498 autoreload 15672 17224 E:\GeekBrains\Учеба GeekBrains\3 quarter. Final\2. Django framework (Seminars)\GB_Django\Seminar2\HomeWork2\shopapp\urls.py changed, reloading.
INFO 2024-04-06 04:49:29,183 autoreload 10976 15184 Watching for file changes with StatReloader
INFO 2024-04-06 04:49:38,035 basehttp 10976 6944 "GET /shop/fake_db/ HTTP/1.1" 200 63
ERROR 2024-04-06 04:49:48,171 log 10976 6944 Internal Server Error: /shop/fake_product/
Traceback (most recent call last):
  File "E:\GeekBrains\Учеба GeekBrains\3 quarter. Final\2. Django framework (Seminars)\GB_Django\.venv\Lib\site-packages\django\db\backends\utils.py", line 105, in _execute
    return self.cursor.execute(sql, params)
           ^^^^^^^^^^^^^^^^^^^^^^^^^^^^^^^^
  File "E:\GeekBrains\Учеба GeekBrains\3 quarter. Final\2. Django framework (Seminars)\GB_Django\.venv\Lib\site-packages\django\db\backends\sqlite3\base.py", line 329, in execute
    return super().execute(query, params)
           ^^^^^^^^^^^^^^^^^^^^^^^^^^^^^^
sqlite3.IntegrityError: NOT NULL constraint failed: shopapp_product.quantity

The above exception was the direct cause of the following exception:

Traceback (most recent call last):
  File "E:\GeekBrains\Учеба GeekBrains\3 quarter. Final\2. Django framework (Seminars)\GB_Django\.venv\Lib\site-packages\django\core\handlers\exception.py", line 55, in inner
    response = get_response(request)
               ^^^^^^^^^^^^^^^^^^^^^
  File "E:\GeekBrains\Учеба GeekBrains\3 quarter. Final\2. Django framework (Seminars)\GB_Django\.venv\Lib\site-packages\django\core\handlers\base.py", line 197, in _get_response
    response = wrapped_callback(request, *callback_args, **callback_kwargs)
               ^^^^^^^^^^^^^^^^^^^^^^^^^^^^^^^^^^^^^^^^^^^^^^^^^^^^^^^^^^^^
  File "E:\GeekBrains\Учеба GeekBrains\3 quarter. Final\2. Django framework (Seminars)\GB_Django\Seminar2\HomeWork2\shopapp\views.py", line 72, in fake_product
    product.save()
  File "E:\GeekBrains\Учеба GeekBrains\3 quarter. Final\2. Django framework (Seminars)\GB_Django\.venv\Lib\site-packages\django\db\models\base.py", line 822, in save
    self.save_base(
  File "E:\GeekBrains\Учеба GeekBrains\3 quarter. Final\2. Django framework (Seminars)\GB_Django\.venv\Lib\site-packages\django\db\models\base.py", line 909, in save_base
    updated = self._save_table(
              ^^^^^^^^^^^^^^^^^
  File "E:\GeekBrains\Учеба GeekBrains\3 quarter. Final\2. Django framework (Seminars)\GB_Django\.venv\Lib\site-packages\django\db\models\base.py", line 1067, in _save_table
    results = self._do_insert(
              ^^^^^^^^^^^^^^^^
  File "E:\GeekBrains\Учеба GeekBrains\3 quarter. Final\2. Django framework (Seminars)\GB_Django\.venv\Lib\site-packages\django\db\models\base.py", line 1108, in _do_insert
    return manager._insert(
           ^^^^^^^^^^^^^^^^
  File "E:\GeekBrains\Учеба GeekBrains\3 quarter. Final\2. Django framework (Seminars)\GB_Django\.venv\Lib\site-packages\django\db\models\manager.py", line 87, in manager_method
    return getattr(self.get_queryset(), name)(*args, **kwargs)
           ^^^^^^^^^^^^^^^^^^^^^^^^^^^^^^^^^^^^^^^^^^^^^^^^^^^
  File "E:\GeekBrains\Учеба GeekBrains\3 quarter. Final\2. Django framework (Seminars)\GB_Django\.venv\Lib\site-packages\django\db\models\query.py", line 1847, in _insert
    return query.get_compiler(using=using).execute_sql(returning_fields)
           ^^^^^^^^^^^^^^^^^^^^^^^^^^^^^^^^^^^^^^^^^^^^^^^^^^^^^^^^^^^^^
  File "E:\GeekBrains\Учеба GeekBrains\3 quarter. Final\2. Django framework (Seminars)\GB_Django\.venv\Lib\site-packages\django\db\models\sql\compiler.py", line 1823, in execute_sql
    cursor.execute(sql, params)
  File "E:\GeekBrains\Учеба GeekBrains\3 quarter. Final\2. Django framework (Seminars)\GB_Django\.venv\Lib\site-packages\django\db\backends\utils.py", line 122, in execute
    return super().execute(sql, params)
           ^^^^^^^^^^^^^^^^^^^^^^^^^^^^
  File "E:\GeekBrains\Учеба GeekBrains\3 quarter. Final\2. Django framework (Seminars)\GB_Django\.venv\Lib\site-packages\django\db\backends\utils.py", line 79, in execute
    return self._execute_with_wrappers(
           ^^^^^^^^^^^^^^^^^^^^^^^^^^^^
  File "E:\GeekBrains\Учеба GeekBrains\3 quarter. Final\2. Django framework (Seminars)\GB_Django\.venv\Lib\site-packages\django\db\backends\utils.py", line 92, in _execute_with_wrappers
    return executor(sql, params, many, context)
           ^^^^^^^^^^^^^^^^^^^^^^^^^^^^^^^^^^^^
  File "E:\GeekBrains\Учеба GeekBrains\3 quarter. Final\2. Django framework (Seminars)\GB_Django\.venv\Lib\site-packages\django\db\backends\utils.py", line 100, in _execute
    with self.db.wrap_database_errors:
  File "E:\GeekBrains\Учеба GeekBrains\3 quarter. Final\2. Django framework (Seminars)\GB_Django\.venv\Lib\site-packages\django\db\utils.py", line 91, in __exit__
    raise dj_exc_value.with_traceback(traceback) from exc_value
  File "E:\GeekBrains\Учеба GeekBrains\3 quarter. Final\2. Django framework (Seminars)\GB_Django\.venv\Lib\site-packages\django\db\backends\utils.py", line 105, in _execute
    return self.cursor.execute(sql, params)
           ^^^^^^^^^^^^^^^^^^^^^^^^^^^^^^^^
  File "E:\GeekBrains\Учеба GeekBrains\3 quarter. Final\2. Django framework (Seminars)\GB_Django\.venv\Lib\site-packages\django\db\backends\sqlite3\base.py", line 329, in execute
    return super().execute(query, params)
           ^^^^^^^^^^^^^^^^^^^^^^^^^^^^^^
django.db.utils.IntegrityError: NOT NULL constraint failed: shopapp_product.quantity
ERROR 2024-04-06 04:49:48,178 basehttp 10976 6944 "GET /shop/fake_product/ HTTP/1.1" 500 152277
INFO 2024-04-06 04:54:15,748 autoreload 10976 15184 E:\GeekBrains\Учеба GeekBrains\3 quarter. Final\2. Django framework (Seminars)\GB_Django\Seminar2\HomeWork2\shopapp\urls.py changed, reloading.
INFO 2024-04-06 04:54:16,365 autoreload 5164 1724 Watching for file changes with StatReloader
ERROR 2024-04-06 04:54:25,427 log 5164 15780 Internal Server Error: /shop/fake_order/
Traceback (most recent call last):
  File "E:\GeekBrains\Учеба GeekBrains\3 quarter. Final\2. Django framework (Seminars)\GB_Django\.venv\Lib\site-packages\django\core\handlers\exception.py", line 55, in inner
    response = get_response(request)
               ^^^^^^^^^^^^^^^^^^^^^
  File "E:\GeekBrains\Учеба GeekBrains\3 quarter. Final\2. Django framework (Seminars)\GB_Django\.venv\Lib\site-packages\django\core\handlers\base.py", line 197, in _get_response
    response = wrapped_callback(request, *callback_args, **callback_kwargs)
               ^^^^^^^^^^^^^^^^^^^^^^^^^^^^^^^^^^^^^^^^^^^^^^^^^^^^^^^^^^^^
  File "E:\GeekBrains\Учеба GeekBrains\3 quarter. Final\2. Django framework (Seminars)\GB_Django\Seminar2\HomeWork2\shopapp\views.py", line 78, in fake_order
    order = Order(customer=Customer,
            ^^^^^^^^^^^^^^^^^^^^^^^^
  File "E:\GeekBrains\Учеба GeekBrains\3 quarter. Final\2. Django framework (Seminars)\GB_Django\.venv\Lib\site-packages\django\db\models\base.py", line 543, in __init__
    _setattr(self, field.name, rel_obj)
  File "E:\GeekBrains\Учеба GeekBrains\3 quarter. Final\2. Django framework (Seminars)\GB_Django\.venv\Lib\site-packages\django\db\models\fields\related_descriptors.py", line 284, in __set__
    raise ValueError(
ValueError: Cannot assign "<class 'shopapp.models.Customer'>": "Order.customer" must be a "Customer" instance.
ERROR 2024-04-06 04:54:25,431 basehttp 5164 15780 "GET /shop/fake_order/ HTTP/1.1" 500 79241
INFO 2024-04-06 04:55:38,245 autoreload 5164 1724 E:\GeekBrains\Учеба GeekBrains\3 quarter. Final\2. Django framework (Seminars)\GB_Django\Seminar2\HomeWork2\shopapp\views.py changed, reloading.
INFO 2024-04-06 04:55:38,941 autoreload 9168 17164 Watching for file changes with StatReloader
INFO 2024-04-06 05:05:45,101 autoreload 9168 17164 E:\GeekBrains\Учеба GeekBrains\3 quarter. Final\2. Django framework (Seminars)\GB_Django\Seminar2\HomeWork2\shopapp\views.py changed, reloading.
INFO 2024-04-06 05:05:45,734 autoreload 9600 9836 Watching for file changes with StatReloader
ERROR 2024-04-06 05:05:50,810 log 9600 3972 Internal Server Error: /shop/fake_order/
Traceback (most recent call last):
  File "E:\GeekBrains\Учеба GeekBrains\3 quarter. Final\2. Django framework (Seminars)\GB_Django\.venv\Lib\site-packages\django\db\models\fields\__init__.py", line 1805, in to_python
    decimal_value = decimal.Decimal(value)
                    ^^^^^^^^^^^^^^^^^^^^^^
decimal.InvalidOperation: [<class 'decimal.ConversionSyntax'>]

During handling of the above exception, another exception occurred:

Traceback (most recent call last):
  File "E:\GeekBrains\Учеба GeekBrains\3 quarter. Final\2. Django framework (Seminars)\GB_Django\.venv\Lib\site-packages\django\core\handlers\exception.py", line 55, in inner
    response = get_response(request)
               ^^^^^^^^^^^^^^^^^^^^^
  File "E:\GeekBrains\Учеба GeekBrains\3 quarter. Final\2. Django framework (Seminars)\GB_Django\.venv\Lib\site-packages\django\core\handlers\base.py", line 197, in _get_response
    response = wrapped_callback(request, *callback_args, **callback_kwargs)
               ^^^^^^^^^^^^^^^^^^^^^^^^^^^^^^^^^^^^^^^^^^^^^^^^^^^^^^^^^^^^
  File "E:\GeekBrains\Учеба GeekBrains\3 quarter. Final\2. Django framework (Seminars)\GB_Django\Seminar2\HomeWork2\shopapp\views.py", line 81, in fake_order
    order.save()
  File "E:\GeekBrains\Учеба GeekBrains\3 quarter. Final\2. Django framework (Seminars)\GB_Django\.venv\Lib\site-packages\django\db\models\base.py", line 822, in save
    self.save_base(
  File "E:\GeekBrains\Учеба GeekBrains\3 quarter. Final\2. Django framework (Seminars)\GB_Django\.venv\Lib\site-packages\django\db\models\base.py", line 909, in save_base
    updated = self._save_table(
              ^^^^^^^^^^^^^^^^^
  File "E:\GeekBrains\Учеба GeekBrains\3 quarter. Final\2. Django framework (Seminars)\GB_Django\.venv\Lib\site-packages\django\db\models\base.py", line 1067, in _save_table
    results = self._do_insert(
              ^^^^^^^^^^^^^^^^
  File "E:\GeekBrains\Учеба GeekBrains\3 quarter. Final\2. Django framework (Seminars)\GB_Django\.venv\Lib\site-packages\django\db\models\base.py", line 1108, in _do_insert
    return manager._insert(
           ^^^^^^^^^^^^^^^^
  File "E:\GeekBrains\Учеба GeekBrains\3 quarter. Final\2. Django framework (Seminars)\GB_Django\.venv\Lib\site-packages\django\db\models\manager.py", line 87, in manager_method
    return getattr(self.get_queryset(), name)(*args, **kwargs)
           ^^^^^^^^^^^^^^^^^^^^^^^^^^^^^^^^^^^^^^^^^^^^^^^^^^^
  File "E:\GeekBrains\Учеба GeekBrains\3 quarter. Final\2. Django framework (Seminars)\GB_Django\.venv\Lib\site-packages\django\db\models\query.py", line 1847, in _insert
    return query.get_compiler(using=using).execute_sql(returning_fields)
           ^^^^^^^^^^^^^^^^^^^^^^^^^^^^^^^^^^^^^^^^^^^^^^^^^^^^^^^^^^^^^
  File "E:\GeekBrains\Учеба GeekBrains\3 quarter. Final\2. Django framework (Seminars)\GB_Django\.venv\Lib\site-packages\django\db\models\sql\compiler.py", line 1822, in execute_sql
    for sql, params in self.as_sql():
                       ^^^^^^^^^^^^^
  File "E:\GeekBrains\Учеба GeekBrains\3 quarter. Final\2. Django framework (Seminars)\GB_Django\.venv\Lib\site-packages\django\db\models\sql\compiler.py", line 1747, in as_sql
    self.prepare_value(field, self.pre_save_val(field, obj))
  File "E:\GeekBrains\Учеба GeekBrains\3 quarter. Final\2. Django framework (Seminars)\GB_Django\.venv\Lib\site-packages\django\db\models\sql\compiler.py", line 1686, in prepare_value
    return field.get_db_prep_save(value, connection=self.connection)
           ^^^^^^^^^^^^^^^^^^^^^^^^^^^^^^^^^^^^^^^^^^^^^^^^^^^^^^^^^
  File "E:\GeekBrains\Учеба GeekBrains\3 quarter. Final\2. Django framework (Seminars)\GB_Django\.venv\Lib\site-packages\django\db\models\fields\__init__.py", line 1824, in get_db_prep_save
    self.to_python(value), self.max_digits, self.decimal_places
    ^^^^^^^^^^^^^^^^^^^^^
  File "E:\GeekBrains\Учеба GeekBrains\3 quarter. Final\2. Django framework (Seminars)\GB_Django\.venv\Lib\site-packages\django\db\models\fields\__init__.py", line 1807, in to_python
    raise exceptions.ValidationError(
django.core.exceptions.ValidationError: ['“<django.db.models.query_utils.DeferredAttribute object at 0x000002530D53CBF0>” value must be a decimal number.']
ERROR 2024-04-06 05:05:50,815 basehttp 9600 3972 "GET /shop/fake_order/ HTTP/1.1" 500 127867
ERROR 2024-04-06 05:06:01,987 log 9600 3972 Internal Server Error: /shop/fake_product/
Traceback (most recent call last):
  File "E:\GeekBrains\Учеба GeekBrains\3 quarter. Final\2. Django framework (Seminars)\GB_Django\.venv\Lib\site-packages\django\db\backends\utils.py", line 105, in _execute
    return self.cursor.execute(sql, params)
           ^^^^^^^^^^^^^^^^^^^^^^^^^^^^^^^^
  File "E:\GeekBrains\Учеба GeekBrains\3 quarter. Final\2. Django framework (Seminars)\GB_Django\.venv\Lib\site-packages\django\db\backends\sqlite3\base.py", line 329, in execute
    return super().execute(query, params)
           ^^^^^^^^^^^^^^^^^^^^^^^^^^^^^^
sqlite3.IntegrityError: NOT NULL constraint failed: shopapp_product.quantity

The above exception was the direct cause of the following exception:

Traceback (most recent call last):
  File "E:\GeekBrains\Учеба GeekBrains\3 quarter. Final\2. Django framework (Seminars)\GB_Django\.venv\Lib\site-packages\django\core\handlers\exception.py", line 55, in inner
    response = get_response(request)
               ^^^^^^^^^^^^^^^^^^^^^
  File "E:\GeekBrains\Учеба GeekBrains\3 quarter. Final\2. Django framework (Seminars)\GB_Django\.venv\Lib\site-packages\django\core\handlers\base.py", line 197, in _get_response
    response = wrapped_callback(request, *callback_args, **callback_kwargs)
               ^^^^^^^^^^^^^^^^^^^^^^^^^^^^^^^^^^^^^^^^^^^^^^^^^^^^^^^^^^^^
  File "E:\GeekBrains\Учеба GeekBrains\3 quarter. Final\2. Django framework (Seminars)\GB_Django\Seminar2\HomeWork2\shopapp\views.py", line 72, in fake_product
    product.save()
  File "E:\GeekBrains\Учеба GeekBrains\3 quarter. Final\2. Django framework (Seminars)\GB_Django\.venv\Lib\site-packages\django\db\models\base.py", line 822, in save
    self.save_base(
  File "E:\GeekBrains\Учеба GeekBrains\3 quarter. Final\2. Django framework (Seminars)\GB_Django\.venv\Lib\site-packages\django\db\models\base.py", line 909, in save_base
    updated = self._save_table(
              ^^^^^^^^^^^^^^^^^
  File "E:\GeekBrains\Учеба GeekBrains\3 quarter. Final\2. Django framework (Seminars)\GB_Django\.venv\Lib\site-packages\django\db\models\base.py", line 1067, in _save_table
    results = self._do_insert(
              ^^^^^^^^^^^^^^^^
  File "E:\GeekBrains\Учеба GeekBrains\3 quarter. Final\2. Django framework (Seminars)\GB_Django\.venv\Lib\site-packages\django\db\models\base.py", line 1108, in _do_insert
    return manager._insert(
           ^^^^^^^^^^^^^^^^
  File "E:\GeekBrains\Учеба GeekBrains\3 quarter. Final\2. Django framework (Seminars)\GB_Django\.venv\Lib\site-packages\django\db\models\manager.py", line 87, in manager_method
    return getattr(self.get_queryset(), name)(*args, **kwargs)
           ^^^^^^^^^^^^^^^^^^^^^^^^^^^^^^^^^^^^^^^^^^^^^^^^^^^
  File "E:\GeekBrains\Учеба GeekBrains\3 quarter. Final\2. Django framework (Seminars)\GB_Django\.venv\Lib\site-packages\django\db\models\query.py", line 1847, in _insert
    return query.get_compiler(using=using).execute_sql(returning_fields)
           ^^^^^^^^^^^^^^^^^^^^^^^^^^^^^^^^^^^^^^^^^^^^^^^^^^^^^^^^^^^^^
  File "E:\GeekBrains\Учеба GeekBrains\3 quarter. Final\2. Django framework (Seminars)\GB_Django\.venv\Lib\site-packages\django\db\models\sql\compiler.py", line 1823, in execute_sql
    cursor.execute(sql, params)
  File "E:\GeekBrains\Учеба GeekBrains\3 quarter. Final\2. Django framework (Seminars)\GB_Django\.venv\Lib\site-packages\django\db\backends\utils.py", line 122, in execute
    return super().execute(sql, params)
           ^^^^^^^^^^^^^^^^^^^^^^^^^^^^
  File "E:\GeekBrains\Учеба GeekBrains\3 quarter. Final\2. Django framework (Seminars)\GB_Django\.venv\Lib\site-packages\django\db\backends\utils.py", line 79, in execute
    return self._execute_with_wrappers(
           ^^^^^^^^^^^^^^^^^^^^^^^^^^^^
  File "E:\GeekBrains\Учеба GeekBrains\3 quarter. Final\2. Django framework (Seminars)\GB_Django\.venv\Lib\site-packages\django\db\backends\utils.py", line 92, in _execute_with_wrappers
    return executor(sql, params, many, context)
           ^^^^^^^^^^^^^^^^^^^^^^^^^^^^^^^^^^^^
  File "E:\GeekBrains\Учеба GeekBrains\3 quarter. Final\2. Django framework (Seminars)\GB_Django\.venv\Lib\site-packages\django\db\backends\utils.py", line 100, in _execute
    with self.db.wrap_database_errors:
  File "E:\GeekBrains\Учеба GeekBrains\3 quarter. Final\2. Django framework (Seminars)\GB_Django\.venv\Lib\site-packages\django\db\utils.py", line 91, in __exit__
    raise dj_exc_value.with_traceback(traceback) from exc_value
  File "E:\GeekBrains\Учеба GeekBrains\3 quarter. Final\2. Django framework (Seminars)\GB_Django\.venv\Lib\site-packages\django\db\backends\utils.py", line 105, in _execute
    return self.cursor.execute(sql, params)
           ^^^^^^^^^^^^^^^^^^^^^^^^^^^^^^^^
  File "E:\GeekBrains\Учеба GeekBrains\3 quarter. Final\2. Django framework (Seminars)\GB_Django\.venv\Lib\site-packages\django\db\backends\sqlite3\base.py", line 329, in execute
    return super().execute(query, params)
           ^^^^^^^^^^^^^^^^^^^^^^^^^^^^^^
django.db.utils.IntegrityError: NOT NULL constraint failed: shopapp_product.quantity
ERROR 2024-04-06 05:06:01,990 basehttp 9600 3972 "GET /shop/fake_product/ HTTP/1.1" 500 152080
INFO 2024-04-06 05:07:58,406 autoreload 9600 9836 E:\GeekBrains\Учеба GeekBrains\3 quarter. Final\2. Django framework (Seminars)\GB_Django\Seminar2\HomeWork2\shopapp\views.py changed, reloading.
INFO 2024-04-06 05:07:59,061 autoreload 9040 16144 Watching for file changes with StatReloader
INFO 2024-04-06 05:13:00,781 autoreload 9644 15064 Watching for file changes with StatReloader
WARNING 2024-04-06 05:13:08,504 log 9644 17280 Not Found: /
WARNING 2024-04-06 05:13:08,505 basehttp 9644 17280 "GET / HTTP/1.1" 404 2167
ERROR 2024-04-06 05:13:28,765 log 9644 17280 Internal Server Error: /shop/fake_product/
Traceback (most recent call last):
  File "C:\Users\mva-1\AppData\Local\Packages\PythonSoftwareFoundation.Python.3.12_qbz5n2kfra8p0\LocalCache\local-packages\Python312\site-packages\django\db\backends\utils.py", line 105, in _execute
    return self.cursor.execute(sql, params)
           ^^^^^^^^^^^^^^^^^^^^^^^^^^^^^^^^
  File "C:\Users\mva-1\AppData\Local\Packages\PythonSoftwareFoundation.Python.3.12_qbz5n2kfra8p0\LocalCache\local-packages\Python312\site-packages\django\db\backends\sqlite3\base.py", line 329, in execute
    return super().execute(query, params)
           ^^^^^^^^^^^^^^^^^^^^^^^^^^^^^^
sqlite3.IntegrityError: NOT NULL constraint failed: shopapp_product.quantity

The above exception was the direct cause of the following exception:

Traceback (most recent call last):
  File "C:\Users\mva-1\AppData\Local\Packages\PythonSoftwareFoundation.Python.3.12_qbz5n2kfra8p0\LocalCache\local-packages\Python312\site-packages\django\core\handlers\exception.py", line 55, in inner
    response = get_response(request)
               ^^^^^^^^^^^^^^^^^^^^^
  File "C:\Users\mva-1\AppData\Local\Packages\PythonSoftwareFoundation.Python.3.12_qbz5n2kfra8p0\LocalCache\local-packages\Python312\site-packages\django\core\handlers\base.py", line 197, in _get_response
    response = wrapped_callback(request, *callback_args, **callback_kwargs)
               ^^^^^^^^^^^^^^^^^^^^^^^^^^^^^^^^^^^^^^^^^^^^^^^^^^^^^^^^^^^^
  File "E:\GeekBrains\Учеба GeekBrains\3 quarter. Final\2. Django framework (Seminars)\GB_Django\Seminar2\HomeWork2\shopapp\views.py", line 72, in fake_product
    product.save()
  File "C:\Users\mva-1\AppData\Local\Packages\PythonSoftwareFoundation.Python.3.12_qbz5n2kfra8p0\LocalCache\local-packages\Python312\site-packages\django\db\models\base.py", line 822, in save
    self.save_base(
  File "C:\Users\mva-1\AppData\Local\Packages\PythonSoftwareFoundation.Python.3.12_qbz5n2kfra8p0\LocalCache\local-packages\Python312\site-packages\django\db\models\base.py", line 909, in save_base
    updated = self._save_table(
              ^^^^^^^^^^^^^^^^^
  File "C:\Users\mva-1\AppData\Local\Packages\PythonSoftwareFoundation.Python.3.12_qbz5n2kfra8p0\LocalCache\local-packages\Python312\site-packages\django\db\models\base.py", line 1067, in _save_table
    results = self._do_insert(
              ^^^^^^^^^^^^^^^^
  File "C:\Users\mva-1\AppData\Local\Packages\PythonSoftwareFoundation.Python.3.12_qbz5n2kfra8p0\LocalCache\local-packages\Python312\site-packages\django\db\models\base.py", line 1108, in _do_insert
    return manager._insert(
           ^^^^^^^^^^^^^^^^
  File "C:\Users\mva-1\AppData\Local\Packages\PythonSoftwareFoundation.Python.3.12_qbz5n2kfra8p0\LocalCache\local-packages\Python312\site-packages\django\db\models\manager.py", line 87, in manager_method
    return getattr(self.get_queryset(), name)(*args, **kwargs)
           ^^^^^^^^^^^^^^^^^^^^^^^^^^^^^^^^^^^^^^^^^^^^^^^^^^^
  File "C:\Users\mva-1\AppData\Local\Packages\PythonSoftwareFoundation.Python.3.12_qbz5n2kfra8p0\LocalCache\local-packages\Python312\site-packages\django\db\models\query.py", line 1847, in _insert
    return query.get_compiler(using=using).execute_sql(returning_fields)
           ^^^^^^^^^^^^^^^^^^^^^^^^^^^^^^^^^^^^^^^^^^^^^^^^^^^^^^^^^^^^^
  File "C:\Users\mva-1\AppData\Local\Packages\PythonSoftwareFoundation.Python.3.12_qbz5n2kfra8p0\LocalCache\local-packages\Python312\site-packages\django\db\models\sql\compiler.py", line 1823, in execute_sql
    cursor.execute(sql, params)
  File "C:\Users\mva-1\AppData\Local\Packages\PythonSoftwareFoundation.Python.3.12_qbz5n2kfra8p0\LocalCache\local-packages\Python312\site-packages\django\db\backends\utils.py", line 122, in execute
    return super().execute(sql, params)
           ^^^^^^^^^^^^^^^^^^^^^^^^^^^^
  File "C:\Users\mva-1\AppData\Local\Packages\PythonSoftwareFoundation.Python.3.12_qbz5n2kfra8p0\LocalCache\local-packages\Python312\site-packages\django\db\backends\utils.py", line 79, in execute
    return self._execute_with_wrappers(
           ^^^^^^^^^^^^^^^^^^^^^^^^^^^^
  File "C:\Users\mva-1\AppData\Local\Packages\PythonSoftwareFoundation.Python.3.12_qbz5n2kfra8p0\LocalCache\local-packages\Python312\site-packages\django\db\backends\utils.py", line 92, in _execute_with_wrappers
    return executor(sql, params, many, context)
           ^^^^^^^^^^^^^^^^^^^^^^^^^^^^^^^^^^^^
  File "C:\Users\mva-1\AppData\Local\Packages\PythonSoftwareFoundation.Python.3.12_qbz5n2kfra8p0\LocalCache\local-packages\Python312\site-packages\django\db\backends\utils.py", line 100, in _execute
    with self.db.wrap_database_errors:
  File "C:\Users\mva-1\AppData\Local\Packages\PythonSoftwareFoundation.Python.3.12_qbz5n2kfra8p0\LocalCache\local-packages\Python312\site-packages\django\db\utils.py", line 91, in __exit__
    raise dj_exc_value.with_traceback(traceback) from exc_value
  File "C:\Users\mva-1\AppData\Local\Packages\PythonSoftwareFoundation.Python.3.12_qbz5n2kfra8p0\LocalCache\local-packages\Python312\site-packages\django\db\backends\utils.py", line 105, in _execute
    return self.cursor.execute(sql, params)
           ^^^^^^^^^^^^^^^^^^^^^^^^^^^^^^^^
  File "C:\Users\mva-1\AppData\Local\Packages\PythonSoftwareFoundation.Python.3.12_qbz5n2kfra8p0\LocalCache\local-packages\Python312\site-packages\django\db\backends\sqlite3\base.py", line 329, in execute
    return super().execute(query, params)
           ^^^^^^^^^^^^^^^^^^^^^^^^^^^^^^
django.db.utils.IntegrityError: NOT NULL constraint failed: shopapp_product.quantity
ERROR 2024-04-06 05:13:28,771 basehttp 9644 17280 "GET /shop/fake_product/ HTTP/1.1" 500 151281
INFO 2024-04-06 05:14:58,677 autoreload 9644 15064 E:\GeekBrains\Учеба GeekBrains\3 quarter. Final\2. Django framework (Seminars)\GB_Django\Seminar2\HomeWork2\shopapp\migrations\0001_initial.py changed, reloading.
INFO 2024-04-06 05:14:59,264 autoreload 16616 10616 Watching for file changes with StatReloader
ERROR 2024-04-06 05:15:01,947 log 16616 17292 Internal Server Error: /shop/fake_product/
Traceback (most recent call last):
  File "C:\Users\mva-1\AppData\Local\Packages\PythonSoftwareFoundation.Python.3.12_qbz5n2kfra8p0\LocalCache\local-packages\Python312\site-packages\django\db\backends\utils.py", line 105, in _execute
    return self.cursor.execute(sql, params)
           ^^^^^^^^^^^^^^^^^^^^^^^^^^^^^^^^
  File "C:\Users\mva-1\AppData\Local\Packages\PythonSoftwareFoundation.Python.3.12_qbz5n2kfra8p0\LocalCache\local-packages\Python312\site-packages\django\db\backends\sqlite3\base.py", line 329, in execute
    return super().execute(query, params)
           ^^^^^^^^^^^^^^^^^^^^^^^^^^^^^^
sqlite3.IntegrityError: NOT NULL constraint failed: shopapp_product.quantity

The above exception was the direct cause of the following exception:

Traceback (most recent call last):
  File "C:\Users\mva-1\AppData\Local\Packages\PythonSoftwareFoundation.Python.3.12_qbz5n2kfra8p0\LocalCache\local-packages\Python312\site-packages\django\core\handlers\exception.py", line 55, in inner
    response = get_response(request)
               ^^^^^^^^^^^^^^^^^^^^^
  File "C:\Users\mva-1\AppData\Local\Packages\PythonSoftwareFoundation.Python.3.12_qbz5n2kfra8p0\LocalCache\local-packages\Python312\site-packages\django\core\handlers\base.py", line 197, in _get_response
    response = wrapped_callback(request, *callback_args, **callback_kwargs)
               ^^^^^^^^^^^^^^^^^^^^^^^^^^^^^^^^^^^^^^^^^^^^^^^^^^^^^^^^^^^^
  File "E:\GeekBrains\Учеба GeekBrains\3 quarter. Final\2. Django framework (Seminars)\GB_Django\Seminar2\HomeWork2\shopapp\views.py", line 72, in fake_product
    product.save()
  File "C:\Users\mva-1\AppData\Local\Packages\PythonSoftwareFoundation.Python.3.12_qbz5n2kfra8p0\LocalCache\local-packages\Python312\site-packages\django\db\models\base.py", line 822, in save
    self.save_base(
  File "C:\Users\mva-1\AppData\Local\Packages\PythonSoftwareFoundation.Python.3.12_qbz5n2kfra8p0\LocalCache\local-packages\Python312\site-packages\django\db\models\base.py", line 909, in save_base
    updated = self._save_table(
              ^^^^^^^^^^^^^^^^^
  File "C:\Users\mva-1\AppData\Local\Packages\PythonSoftwareFoundation.Python.3.12_qbz5n2kfra8p0\LocalCache\local-packages\Python312\site-packages\django\db\models\base.py", line 1067, in _save_table
    results = self._do_insert(
              ^^^^^^^^^^^^^^^^
  File "C:\Users\mva-1\AppData\Local\Packages\PythonSoftwareFoundation.Python.3.12_qbz5n2kfra8p0\LocalCache\local-packages\Python312\site-packages\django\db\models\base.py", line 1108, in _do_insert
    return manager._insert(
           ^^^^^^^^^^^^^^^^
  File "C:\Users\mva-1\AppData\Local\Packages\PythonSoftwareFoundation.Python.3.12_qbz5n2kfra8p0\LocalCache\local-packages\Python312\site-packages\django\db\models\manager.py", line 87, in manager_method
    return getattr(self.get_queryset(), name)(*args, **kwargs)
           ^^^^^^^^^^^^^^^^^^^^^^^^^^^^^^^^^^^^^^^^^^^^^^^^^^^
  File "C:\Users\mva-1\AppData\Local\Packages\PythonSoftwareFoundation.Python.3.12_qbz5n2kfra8p0\LocalCache\local-packages\Python312\site-packages\django\db\models\query.py", line 1847, in _insert
    return query.get_compiler(using=using).execute_sql(returning_fields)
           ^^^^^^^^^^^^^^^^^^^^^^^^^^^^^^^^^^^^^^^^^^^^^^^^^^^^^^^^^^^^^
  File "C:\Users\mva-1\AppData\Local\Packages\PythonSoftwareFoundation.Python.3.12_qbz5n2kfra8p0\LocalCache\local-packages\Python312\site-packages\django\db\models\sql\compiler.py", line 1823, in execute_sql
    cursor.execute(sql, params)
  File "C:\Users\mva-1\AppData\Local\Packages\PythonSoftwareFoundation.Python.3.12_qbz5n2kfra8p0\LocalCache\local-packages\Python312\site-packages\django\db\backends\utils.py", line 122, in execute
    return super().execute(sql, params)
           ^^^^^^^^^^^^^^^^^^^^^^^^^^^^
  File "C:\Users\mva-1\AppData\Local\Packages\PythonSoftwareFoundation.Python.3.12_qbz5n2kfra8p0\LocalCache\local-packages\Python312\site-packages\django\db\backends\utils.py", line 79, in execute
    return self._execute_with_wrappers(
           ^^^^^^^^^^^^^^^^^^^^^^^^^^^^
  File "C:\Users\mva-1\AppData\Local\Packages\PythonSoftwareFoundation.Python.3.12_qbz5n2kfra8p0\LocalCache\local-packages\Python312\site-packages\django\db\backends\utils.py", line 92, in _execute_with_wrappers
    return executor(sql, params, many, context)
           ^^^^^^^^^^^^^^^^^^^^^^^^^^^^^^^^^^^^
  File "C:\Users\mva-1\AppData\Local\Packages\PythonSoftwareFoundation.Python.3.12_qbz5n2kfra8p0\LocalCache\local-packages\Python312\site-packages\django\db\backends\utils.py", line 100, in _execute
    with self.db.wrap_database_errors:
  File "C:\Users\mva-1\AppData\Local\Packages\PythonSoftwareFoundation.Python.3.12_qbz5n2kfra8p0\LocalCache\local-packages\Python312\site-packages\django\db\utils.py", line 91, in __exit__
    raise dj_exc_value.with_traceback(traceback) from exc_value
  File "C:\Users\mva-1\AppData\Local\Packages\PythonSoftwareFoundation.Python.3.12_qbz5n2kfra8p0\LocalCache\local-packages\Python312\site-packages\django\db\backends\utils.py", line 105, in _execute
    return self.cursor.execute(sql, params)
           ^^^^^^^^^^^^^^^^^^^^^^^^^^^^^^^^
  File "C:\Users\mva-1\AppData\Local\Packages\PythonSoftwareFoundation.Python.3.12_qbz5n2kfra8p0\LocalCache\local-packages\Python312\site-packages\django\db\backends\sqlite3\base.py", line 329, in execute
    return super().execute(query, params)
           ^^^^^^^^^^^^^^^^^^^^^^^^^^^^^^
django.db.utils.IntegrityError: NOT NULL constraint failed: shopapp_product.quantity
ERROR 2024-04-06 05:15:01,953 basehttp 16616 17292 "GET /shop/fake_product/ HTTP/1.1" 500 151417
INFO 2024-04-06 05:17:09,135 autoreload 14748 6660 Watching for file changes with StatReloader
ERROR 2024-04-06 05:17:11,149 log 14748 16152 Internal Server Error: /shop/fake_product/
Traceback (most recent call last):
  File "C:\Users\mva-1\AppData\Local\Packages\PythonSoftwareFoundation.Python.3.12_qbz5n2kfra8p0\LocalCache\local-packages\Python312\site-packages\django\db\backends\utils.py", line 105, in _execute
    return self.cursor.execute(sql, params)
           ^^^^^^^^^^^^^^^^^^^^^^^^^^^^^^^^
  File "C:\Users\mva-1\AppData\Local\Packages\PythonSoftwareFoundation.Python.3.12_qbz5n2kfra8p0\LocalCache\local-packages\Python312\site-packages\django\db\backends\sqlite3\base.py", line 329, in execute
    return super().execute(query, params)
           ^^^^^^^^^^^^^^^^^^^^^^^^^^^^^^
sqlite3.IntegrityError: NOT NULL constraint failed: shopapp_product.date_added

The above exception was the direct cause of the following exception:

Traceback (most recent call last):
  File "C:\Users\mva-1\AppData\Local\Packages\PythonSoftwareFoundation.Python.3.12_qbz5n2kfra8p0\LocalCache\local-packages\Python312\site-packages\django\core\handlers\exception.py", line 55, in inner
    response = get_response(request)
               ^^^^^^^^^^^^^^^^^^^^^
  File "C:\Users\mva-1\AppData\Local\Packages\PythonSoftwareFoundation.Python.3.12_qbz5n2kfra8p0\LocalCache\local-packages\Python312\site-packages\django\core\handlers\base.py", line 197, in _get_response
    response = wrapped_callback(request, *callback_args, **callback_kwargs)
               ^^^^^^^^^^^^^^^^^^^^^^^^^^^^^^^^^^^^^^^^^^^^^^^^^^^^^^^^^^^^
  File "E:\GeekBrains\Учеба GeekBrains\3 quarter. Final\2. Django framework (Seminars)\GB_Django\Seminar2\HomeWork2\shopapp\views.py", line 72, in fake_product
    product.save()
  File "C:\Users\mva-1\AppData\Local\Packages\PythonSoftwareFoundation.Python.3.12_qbz5n2kfra8p0\LocalCache\local-packages\Python312\site-packages\django\db\models\base.py", line 822, in save
    self.save_base(
  File "C:\Users\mva-1\AppData\Local\Packages\PythonSoftwareFoundation.Python.3.12_qbz5n2kfra8p0\LocalCache\local-packages\Python312\site-packages\django\db\models\base.py", line 909, in save_base
    updated = self._save_table(
              ^^^^^^^^^^^^^^^^^
  File "C:\Users\mva-1\AppData\Local\Packages\PythonSoftwareFoundation.Python.3.12_qbz5n2kfra8p0\LocalCache\local-packages\Python312\site-packages\django\db\models\base.py", line 1067, in _save_table
    results = self._do_insert(
              ^^^^^^^^^^^^^^^^
  File "C:\Users\mva-1\AppData\Local\Packages\PythonSoftwareFoundation.Python.3.12_qbz5n2kfra8p0\LocalCache\local-packages\Python312\site-packages\django\db\models\base.py", line 1108, in _do_insert
    return manager._insert(
           ^^^^^^^^^^^^^^^^
  File "C:\Users\mva-1\AppData\Local\Packages\PythonSoftwareFoundation.Python.3.12_qbz5n2kfra8p0\LocalCache\local-packages\Python312\site-packages\django\db\models\manager.py", line 87, in manager_method
    return getattr(self.get_queryset(), name)(*args, **kwargs)
           ^^^^^^^^^^^^^^^^^^^^^^^^^^^^^^^^^^^^^^^^^^^^^^^^^^^
  File "C:\Users\mva-1\AppData\Local\Packages\PythonSoftwareFoundation.Python.3.12_qbz5n2kfra8p0\LocalCache\local-packages\Python312\site-packages\django\db\models\query.py", line 1847, in _insert
    return query.get_compiler(using=using).execute_sql(returning_fields)
           ^^^^^^^^^^^^^^^^^^^^^^^^^^^^^^^^^^^^^^^^^^^^^^^^^^^^^^^^^^^^^
  File "C:\Users\mva-1\AppData\Local\Packages\PythonSoftwareFoundation.Python.3.12_qbz5n2kfra8p0\LocalCache\local-packages\Python312\site-packages\django\db\models\sql\compiler.py", line 1823, in execute_sql
    cursor.execute(sql, params)
  File "C:\Users\mva-1\AppData\Local\Packages\PythonSoftwareFoundation.Python.3.12_qbz5n2kfra8p0\LocalCache\local-packages\Python312\site-packages\django\db\backends\utils.py", line 122, in execute
    return super().execute(sql, params)
           ^^^^^^^^^^^^^^^^^^^^^^^^^^^^
  File "C:\Users\mva-1\AppData\Local\Packages\PythonSoftwareFoundation.Python.3.12_qbz5n2kfra8p0\LocalCache\local-packages\Python312\site-packages\django\db\backends\utils.py", line 79, in execute
    return self._execute_with_wrappers(
           ^^^^^^^^^^^^^^^^^^^^^^^^^^^^
  File "C:\Users\mva-1\AppData\Local\Packages\PythonSoftwareFoundation.Python.3.12_qbz5n2kfra8p0\LocalCache\local-packages\Python312\site-packages\django\db\backends\utils.py", line 92, in _execute_with_wrappers
    return executor(sql, params, many, context)
           ^^^^^^^^^^^^^^^^^^^^^^^^^^^^^^^^^^^^
  File "C:\Users\mva-1\AppData\Local\Packages\PythonSoftwareFoundation.Python.3.12_qbz5n2kfra8p0\LocalCache\local-packages\Python312\site-packages\django\db\backends\utils.py", line 100, in _execute
    with self.db.wrap_database_errors:
  File "C:\Users\mva-1\AppData\Local\Packages\PythonSoftwareFoundation.Python.3.12_qbz5n2kfra8p0\LocalCache\local-packages\Python312\site-packages\django\db\utils.py", line 91, in __exit__
    raise dj_exc_value.with_traceback(traceback) from exc_value
  File "C:\Users\mva-1\AppData\Local\Packages\PythonSoftwareFoundation.Python.3.12_qbz5n2kfra8p0\LocalCache\local-packages\Python312\site-packages\django\db\backends\utils.py", line 105, in _execute
    return self.cursor.execute(sql, params)
           ^^^^^^^^^^^^^^^^^^^^^^^^^^^^^^^^
  File "C:\Users\mva-1\AppData\Local\Packages\PythonSoftwareFoundation.Python.3.12_qbz5n2kfra8p0\LocalCache\local-packages\Python312\site-packages\django\db\backends\sqlite3\base.py", line 329, in execute
    return super().execute(query, params)
           ^^^^^^^^^^^^^^^^^^^^^^^^^^^^^^
django.db.utils.IntegrityError: NOT NULL constraint failed: shopapp_product.date_added
ERROR 2024-04-06 05:17:11,155 basehttp 14748 16152 "GET /shop/fake_product/ HTTP/1.1" 500 151434
INFO 2024-04-06 05:19:07,983 autoreload 14748 6660 E:\GeekBrains\Учеба GeekBrains\3 quarter. Final\2. Django framework (Seminars)\GB_Django\Seminar2\HomeWork2\shopapp\models.py changed, reloading.
INFO 2024-04-06 05:19:08,705 autoreload 15904 15212 Watching for file changes with StatReloader
INFO 2024-04-06 05:22:52,730 autoreload 15904 15212 E:\GeekBrains\Учеба GeekBrains\3 quarter. Final\2. Django framework (Seminars)\GB_Django\Seminar2\HomeWork2\shopapp\views.py changed, reloading.
INFO 2024-04-06 05:22:53,385 autoreload 8788 16536 Watching for file changes with StatReloader
WARNING 2024-04-06 05:22:54,575 log 8788 16396 Not Found: /shop/fake_product/
WARNING 2024-04-06 05:22:54,575 basehttp 8788 16396 "GET /shop/fake_product/ HTTP/1.1" 404 2649
ERROR 2024-04-06 05:23:17,913 log 8788 16396 Internal Server Error: /shop/fake_db/
Traceback (most recent call last):
  File "C:\Users\mva-1\AppData\Local\Packages\PythonSoftwareFoundation.Python.3.12_qbz5n2kfra8p0\LocalCache\local-packages\Python312\site-packages\django\db\backends\utils.py", line 105, in _execute
    return self.cursor.execute(sql, params)
           ^^^^^^^^^^^^^^^^^^^^^^^^^^^^^^^^
  File "C:\Users\mva-1\AppData\Local\Packages\PythonSoftwareFoundation.Python.3.12_qbz5n2kfra8p0\LocalCache\local-packages\Python312\site-packages\django\db\backends\sqlite3\base.py", line 329, in execute
    return super().execute(query, params)
           ^^^^^^^^^^^^^^^^^^^^^^^^^^^^^^
sqlite3.OperationalError: table shopapp_product has no column named quantity

The above exception was the direct cause of the following exception:

Traceback (most recent call last):
  File "C:\Users\mva-1\AppData\Local\Packages\PythonSoftwareFoundation.Python.3.12_qbz5n2kfra8p0\LocalCache\local-packages\Python312\site-packages\django\core\handlers\exception.py", line 55, in inner
    response = get_response(request)
               ^^^^^^^^^^^^^^^^^^^^^
  File "C:\Users\mva-1\AppData\Local\Packages\PythonSoftwareFoundation.Python.3.12_qbz5n2kfra8p0\LocalCache\local-packages\Python312\site-packages\django\core\handlers\base.py", line 197, in _get_response
    response = wrapped_callback(request, *callback_args, **callback_kwargs)
               ^^^^^^^^^^^^^^^^^^^^^^^^^^^^^^^^^^^^^^^^^^^^^^^^^^^^^^^^^^^^
  File "E:\GeekBrains\Учеба GeekBrains\3 quarter. Final\2. Django framework (Seminars)\GB_Django\Seminar2\HomeWork2\shopapp\views.py", line 67, in fake_db
    product.save()
  File "C:\Users\mva-1\AppData\Local\Packages\PythonSoftwareFoundation.Python.3.12_qbz5n2kfra8p0\LocalCache\local-packages\Python312\site-packages\django\db\models\base.py", line 822, in save
    self.save_base(
  File "C:\Users\mva-1\AppData\Local\Packages\PythonSoftwareFoundation.Python.3.12_qbz5n2kfra8p0\LocalCache\local-packages\Python312\site-packages\django\db\models\base.py", line 909, in save_base
    updated = self._save_table(
              ^^^^^^^^^^^^^^^^^
  File "C:\Users\mva-1\AppData\Local\Packages\PythonSoftwareFoundation.Python.3.12_qbz5n2kfra8p0\LocalCache\local-packages\Python312\site-packages\django\db\models\base.py", line 1067, in _save_table
    results = self._do_insert(
              ^^^^^^^^^^^^^^^^
  File "C:\Users\mva-1\AppData\Local\Packages\PythonSoftwareFoundation.Python.3.12_qbz5n2kfra8p0\LocalCache\local-packages\Python312\site-packages\django\db\models\base.py", line 1108, in _do_insert
    return manager._insert(
           ^^^^^^^^^^^^^^^^
  File "C:\Users\mva-1\AppData\Local\Packages\PythonSoftwareFoundation.Python.3.12_qbz5n2kfra8p0\LocalCache\local-packages\Python312\site-packages\django\db\models\manager.py", line 87, in manager_method
    return getattr(self.get_queryset(), name)(*args, **kwargs)
           ^^^^^^^^^^^^^^^^^^^^^^^^^^^^^^^^^^^^^^^^^^^^^^^^^^^
  File "C:\Users\mva-1\AppData\Local\Packages\PythonSoftwareFoundation.Python.3.12_qbz5n2kfra8p0\LocalCache\local-packages\Python312\site-packages\django\db\models\query.py", line 1847, in _insert
    return query.get_compiler(using=using).execute_sql(returning_fields)
           ^^^^^^^^^^^^^^^^^^^^^^^^^^^^^^^^^^^^^^^^^^^^^^^^^^^^^^^^^^^^^
  File "C:\Users\mva-1\AppData\Local\Packages\PythonSoftwareFoundation.Python.3.12_qbz5n2kfra8p0\LocalCache\local-packages\Python312\site-packages\django\db\models\sql\compiler.py", line 1823, in execute_sql
    cursor.execute(sql, params)
  File "C:\Users\mva-1\AppData\Local\Packages\PythonSoftwareFoundation.Python.3.12_qbz5n2kfra8p0\LocalCache\local-packages\Python312\site-packages\django\db\backends\utils.py", line 122, in execute
    return super().execute(sql, params)
           ^^^^^^^^^^^^^^^^^^^^^^^^^^^^
  File "C:\Users\mva-1\AppData\Local\Packages\PythonSoftwareFoundation.Python.3.12_qbz5n2kfra8p0\LocalCache\local-packages\Python312\site-packages\django\db\backends\utils.py", line 79, in execute
    return self._execute_with_wrappers(
           ^^^^^^^^^^^^^^^^^^^^^^^^^^^^
  File "C:\Users\mva-1\AppData\Local\Packages\PythonSoftwareFoundation.Python.3.12_qbz5n2kfra8p0\LocalCache\local-packages\Python312\site-packages\django\db\backends\utils.py", line 92, in _execute_with_wrappers
    return executor(sql, params, many, context)
           ^^^^^^^^^^^^^^^^^^^^^^^^^^^^^^^^^^^^
  File "C:\Users\mva-1\AppData\Local\Packages\PythonSoftwareFoundation.Python.3.12_qbz5n2kfra8p0\LocalCache\local-packages\Python312\site-packages\django\db\backends\utils.py", line 100, in _execute
    with self.db.wrap_database_errors:
  File "C:\Users\mva-1\AppData\Local\Packages\PythonSoftwareFoundation.Python.3.12_qbz5n2kfra8p0\LocalCache\local-packages\Python312\site-packages\django\db\utils.py", line 91, in __exit__
    raise dj_exc_value.with_traceback(traceback) from exc_value
  File "C:\Users\mva-1\AppData\Local\Packages\PythonSoftwareFoundation.Python.3.12_qbz5n2kfra8p0\LocalCache\local-packages\Python312\site-packages\django\db\backends\utils.py", line 105, in _execute
    return self.cursor.execute(sql, params)
           ^^^^^^^^^^^^^^^^^^^^^^^^^^^^^^^^
  File "C:\Users\mva-1\AppData\Local\Packages\PythonSoftwareFoundation.Python.3.12_qbz5n2kfra8p0\LocalCache\local-packages\Python312\site-packages\django\db\backends\sqlite3\base.py", line 329, in execute
    return super().execute(query, params)
           ^^^^^^^^^^^^^^^^^^^^^^^^^^^^^^
django.db.utils.OperationalError: table shopapp_product has no column named quantity
ERROR 2024-04-06 05:23:17,921 basehttp 8788 16396 "GET /shop/fake_db/ HTTP/1.1" 500 152514
INFO 2024-04-06 05:24:37,262 autoreload 8256 6252 Watching for file changes with StatReloader
ERROR 2024-04-06 05:24:40,447 log 8256 14756 Internal Server Error: /shop/fake_db/
Traceback (most recent call last):
  File "C:\Users\mva-1\AppData\Local\Packages\PythonSoftwareFoundation.Python.3.12_qbz5n2kfra8p0\LocalCache\local-packages\Python312\site-packages\django\db\backends\utils.py", line 105, in _execute
    return self.cursor.execute(sql, params)
           ^^^^^^^^^^^^^^^^^^^^^^^^^^^^^^^^
  File "C:\Users\mva-1\AppData\Local\Packages\PythonSoftwareFoundation.Python.3.12_qbz5n2kfra8p0\LocalCache\local-packages\Python312\site-packages\django\db\backends\sqlite3\base.py", line 329, in execute
    return super().execute(query, params)
           ^^^^^^^^^^^^^^^^^^^^^^^^^^^^^^
sqlite3.IntegrityError: NOT NULL constraint failed: shopapp_product.quantity

The above exception was the direct cause of the following exception:

Traceback (most recent call last):
  File "C:\Users\mva-1\AppData\Local\Packages\PythonSoftwareFoundation.Python.3.12_qbz5n2kfra8p0\LocalCache\local-packages\Python312\site-packages\django\core\handlers\exception.py", line 55, in inner
    response = get_response(request)
               ^^^^^^^^^^^^^^^^^^^^^
  File "C:\Users\mva-1\AppData\Local\Packages\PythonSoftwareFoundation.Python.3.12_qbz5n2kfra8p0\LocalCache\local-packages\Python312\site-packages\django\core\handlers\base.py", line 197, in _get_response
    response = wrapped_callback(request, *callback_args, **callback_kwargs)
               ^^^^^^^^^^^^^^^^^^^^^^^^^^^^^^^^^^^^^^^^^^^^^^^^^^^^^^^^^^^^
  File "E:\GeekBrains\Учеба GeekBrains\3 quarter. Final\2. Django framework (Seminars)\GB_Django\Seminar2\HomeWork2\shopapp\views.py", line 67, in fake_db
    product.save()
  File "C:\Users\mva-1\AppData\Local\Packages\PythonSoftwareFoundation.Python.3.12_qbz5n2kfra8p0\LocalCache\local-packages\Python312\site-packages\django\db\models\base.py", line 822, in save
    self.save_base(
  File "C:\Users\mva-1\AppData\Local\Packages\PythonSoftwareFoundation.Python.3.12_qbz5n2kfra8p0\LocalCache\local-packages\Python312\site-packages\django\db\models\base.py", line 909, in save_base
    updated = self._save_table(
              ^^^^^^^^^^^^^^^^^
  File "C:\Users\mva-1\AppData\Local\Packages\PythonSoftwareFoundation.Python.3.12_qbz5n2kfra8p0\LocalCache\local-packages\Python312\site-packages\django\db\models\base.py", line 1067, in _save_table
    results = self._do_insert(
              ^^^^^^^^^^^^^^^^
  File "C:\Users\mva-1\AppData\Local\Packages\PythonSoftwareFoundation.Python.3.12_qbz5n2kfra8p0\LocalCache\local-packages\Python312\site-packages\django\db\models\base.py", line 1108, in _do_insert
    return manager._insert(
           ^^^^^^^^^^^^^^^^
  File "C:\Users\mva-1\AppData\Local\Packages\PythonSoftwareFoundation.Python.3.12_qbz5n2kfra8p0\LocalCache\local-packages\Python312\site-packages\django\db\models\manager.py", line 87, in manager_method
    return getattr(self.get_queryset(), name)(*args, **kwargs)
           ^^^^^^^^^^^^^^^^^^^^^^^^^^^^^^^^^^^^^^^^^^^^^^^^^^^
  File "C:\Users\mva-1\AppData\Local\Packages\PythonSoftwareFoundation.Python.3.12_qbz5n2kfra8p0\LocalCache\local-packages\Python312\site-packages\django\db\models\query.py", line 1847, in _insert
    return query.get_compiler(using=using).execute_sql(returning_fields)
           ^^^^^^^^^^^^^^^^^^^^^^^^^^^^^^^^^^^^^^^^^^^^^^^^^^^^^^^^^^^^^
  File "C:\Users\mva-1\AppData\Local\Packages\PythonSoftwareFoundation.Python.3.12_qbz5n2kfra8p0\LocalCache\local-packages\Python312\site-packages\django\db\models\sql\compiler.py", line 1823, in execute_sql
    cursor.execute(sql, params)
  File "C:\Users\mva-1\AppData\Local\Packages\PythonSoftwareFoundation.Python.3.12_qbz5n2kfra8p0\LocalCache\local-packages\Python312\site-packages\django\db\backends\utils.py", line 122, in execute
    return super().execute(sql, params)
           ^^^^^^^^^^^^^^^^^^^^^^^^^^^^
  File "C:\Users\mva-1\AppData\Local\Packages\PythonSoftwareFoundation.Python.3.12_qbz5n2kfra8p0\LocalCache\local-packages\Python312\site-packages\django\db\backends\utils.py", line 79, in execute
    return self._execute_with_wrappers(
           ^^^^^^^^^^^^^^^^^^^^^^^^^^^^
  File "C:\Users\mva-1\AppData\Local\Packages\PythonSoftwareFoundation.Python.3.12_qbz5n2kfra8p0\LocalCache\local-packages\Python312\site-packages\django\db\backends\utils.py", line 92, in _execute_with_wrappers
    return executor(sql, params, many, context)
           ^^^^^^^^^^^^^^^^^^^^^^^^^^^^^^^^^^^^
  File "C:\Users\mva-1\AppData\Local\Packages\PythonSoftwareFoundation.Python.3.12_qbz5n2kfra8p0\LocalCache\local-packages\Python312\site-packages\django\db\backends\utils.py", line 100, in _execute
    with self.db.wrap_database_errors:
  File "C:\Users\mva-1\AppData\Local\Packages\PythonSoftwareFoundation.Python.3.12_qbz5n2kfra8p0\LocalCache\local-packages\Python312\site-packages\django\db\utils.py", line 91, in __exit__
    raise dj_exc_value.with_traceback(traceback) from exc_value
  File "C:\Users\mva-1\AppData\Local\Packages\PythonSoftwareFoundation.Python.3.12_qbz5n2kfra8p0\LocalCache\local-packages\Python312\site-packages\django\db\backends\utils.py", line 105, in _execute
    return self.cursor.execute(sql, params)
           ^^^^^^^^^^^^^^^^^^^^^^^^^^^^^^^^
  File "C:\Users\mva-1\AppData\Local\Packages\PythonSoftwareFoundation.Python.3.12_qbz5n2kfra8p0\LocalCache\local-packages\Python312\site-packages\django\db\backends\sqlite3\base.py", line 329, in execute
    return super().execute(query, params)
           ^^^^^^^^^^^^^^^^^^^^^^^^^^^^^^
django.db.utils.IntegrityError: NOT NULL constraint failed: shopapp_product.quantity
ERROR 2024-04-06 05:24:40,453 basehttp 8256 14756 "GET /shop/fake_db/ HTTP/1.1" 500 152587
INFO 2024-04-06 05:26:59,200 autoreload 8256 6252 E:\GeekBrains\Учеба GeekBrains\3 quarter. Final\2. Django framework (Seminars)\GB_Django\Seminar2\HomeWork2\shopapp\views.py changed, reloading.
INFO 2024-04-06 05:26:59,882 autoreload 14992 1984 Watching for file changes with StatReloader
ERROR 2024-04-06 05:27:06,398 log 14992 8220 Internal Server Error: /shop/fake_db/
Traceback (most recent call last):
  File "C:\Users\mva-1\AppData\Local\Packages\PythonSoftwareFoundation.Python.3.12_qbz5n2kfra8p0\LocalCache\local-packages\Python312\site-packages\django\db\backends\utils.py", line 105, in _execute
    return self.cursor.execute(sql, params)
           ^^^^^^^^^^^^^^^^^^^^^^^^^^^^^^^^
  File "C:\Users\mva-1\AppData\Local\Packages\PythonSoftwareFoundation.Python.3.12_qbz5n2kfra8p0\LocalCache\local-packages\Python312\site-packages\django\db\backends\sqlite3\base.py", line 329, in execute
    return super().execute(query, params)
           ^^^^^^^^^^^^^^^^^^^^^^^^^^^^^^
sqlite3.IntegrityError: NOT NULL constraint failed: shopapp_product.quantity

The above exception was the direct cause of the following exception:

Traceback (most recent call last):
  File "C:\Users\mva-1\AppData\Local\Packages\PythonSoftwareFoundation.Python.3.12_qbz5n2kfra8p0\LocalCache\local-packages\Python312\site-packages\django\core\handlers\exception.py", line 55, in inner
    response = get_response(request)
               ^^^^^^^^^^^^^^^^^^^^^
  File "C:\Users\mva-1\AppData\Local\Packages\PythonSoftwareFoundation.Python.3.12_qbz5n2kfra8p0\LocalCache\local-packages\Python312\site-packages\django\core\handlers\base.py", line 197, in _get_response
    response = wrapped_callback(request, *callback_args, **callback_kwargs)
               ^^^^^^^^^^^^^^^^^^^^^^^^^^^^^^^^^^^^^^^^^^^^^^^^^^^^^^^^^^^^
  File "E:\GeekBrains\Учеба GeekBrains\3 quarter. Final\2. Django framework (Seminars)\GB_Django\Seminar2\HomeWork2\shopapp\views.py", line 71, in fake_db
    product.save()
  File "C:\Users\mva-1\AppData\Local\Packages\PythonSoftwareFoundation.Python.3.12_qbz5n2kfra8p0\LocalCache\local-packages\Python312\site-packages\django\db\models\base.py", line 822, in save
    self.save_base(
  File "C:\Users\mva-1\AppData\Local\Packages\PythonSoftwareFoundation.Python.3.12_qbz5n2kfra8p0\LocalCache\local-packages\Python312\site-packages\django\db\models\base.py", line 909, in save_base
    updated = self._save_table(
              ^^^^^^^^^^^^^^^^^
  File "C:\Users\mva-1\AppData\Local\Packages\PythonSoftwareFoundation.Python.3.12_qbz5n2kfra8p0\LocalCache\local-packages\Python312\site-packages\django\db\models\base.py", line 1067, in _save_table
    results = self._do_insert(
              ^^^^^^^^^^^^^^^^
  File "C:\Users\mva-1\AppData\Local\Packages\PythonSoftwareFoundation.Python.3.12_qbz5n2kfra8p0\LocalCache\local-packages\Python312\site-packages\django\db\models\base.py", line 1108, in _do_insert
    return manager._insert(
           ^^^^^^^^^^^^^^^^
  File "C:\Users\mva-1\AppData\Local\Packages\PythonSoftwareFoundation.Python.3.12_qbz5n2kfra8p0\LocalCache\local-packages\Python312\site-packages\django\db\models\manager.py", line 87, in manager_method
    return getattr(self.get_queryset(), name)(*args, **kwargs)
           ^^^^^^^^^^^^^^^^^^^^^^^^^^^^^^^^^^^^^^^^^^^^^^^^^^^
  File "C:\Users\mva-1\AppData\Local\Packages\PythonSoftwareFoundation.Python.3.12_qbz5n2kfra8p0\LocalCache\local-packages\Python312\site-packages\django\db\models\query.py", line 1847, in _insert
    return query.get_compiler(using=using).execute_sql(returning_fields)
           ^^^^^^^^^^^^^^^^^^^^^^^^^^^^^^^^^^^^^^^^^^^^^^^^^^^^^^^^^^^^^
  File "C:\Users\mva-1\AppData\Local\Packages\PythonSoftwareFoundation.Python.3.12_qbz5n2kfra8p0\LocalCache\local-packages\Python312\site-packages\django\db\models\sql\compiler.py", line 1823, in execute_sql
    cursor.execute(sql, params)
  File "C:\Users\mva-1\AppData\Local\Packages\PythonSoftwareFoundation.Python.3.12_qbz5n2kfra8p0\LocalCache\local-packages\Python312\site-packages\django\db\backends\utils.py", line 122, in execute
    return super().execute(sql, params)
           ^^^^^^^^^^^^^^^^^^^^^^^^^^^^
  File "C:\Users\mva-1\AppData\Local\Packages\PythonSoftwareFoundation.Python.3.12_qbz5n2kfra8p0\LocalCache\local-packages\Python312\site-packages\django\db\backends\utils.py", line 79, in execute
    return self._execute_with_wrappers(
           ^^^^^^^^^^^^^^^^^^^^^^^^^^^^
  File "C:\Users\mva-1\AppData\Local\Packages\PythonSoftwareFoundation.Python.3.12_qbz5n2kfra8p0\LocalCache\local-packages\Python312\site-packages\django\db\backends\utils.py", line 92, in _execute_with_wrappers
    return executor(sql, params, many, context)
           ^^^^^^^^^^^^^^^^^^^^^^^^^^^^^^^^^^^^
  File "C:\Users\mva-1\AppData\Local\Packages\PythonSoftwareFoundation.Python.3.12_qbz5n2kfra8p0\LocalCache\local-packages\Python312\site-packages\django\db\backends\utils.py", line 100, in _execute
    with self.db.wrap_database_errors:
  File "C:\Users\mva-1\AppData\Local\Packages\PythonSoftwareFoundation.Python.3.12_qbz5n2kfra8p0\LocalCache\local-packages\Python312\site-packages\django\db\utils.py", line 91, in __exit__
    raise dj_exc_value.with_traceback(traceback) from exc_value
  File "C:\Users\mva-1\AppData\Local\Packages\PythonSoftwareFoundation.Python.3.12_qbz5n2kfra8p0\LocalCache\local-packages\Python312\site-packages\django\db\backends\utils.py", line 105, in _execute
    return self.cursor.execute(sql, params)
           ^^^^^^^^^^^^^^^^^^^^^^^^^^^^^^^^
  File "C:\Users\mva-1\AppData\Local\Packages\PythonSoftwareFoundation.Python.3.12_qbz5n2kfra8p0\LocalCache\local-packages\Python312\site-packages\django\db\backends\sqlite3\base.py", line 329, in execute
    return super().execute(query, params)
           ^^^^^^^^^^^^^^^^^^^^^^^^^^^^^^
django.db.utils.IntegrityError: NOT NULL constraint failed: shopapp_product.quantity
ERROR 2024-04-06 05:27:06,405 basehttp 14992 8220 "GET /shop/fake_db/ HTTP/1.1" 500 152559
INFO 2024-04-06 05:27:46,606 autoreload 14992 1984 E:\GeekBrains\Учеба GeekBrains\3 quarter. Final\2. Django framework (Seminars)\GB_Django\Seminar2\HomeWork2\shopapp\views.py changed, reloading.
INFO 2024-04-06 05:27:47,313 autoreload 13228 14776 Watching for file changes with StatReloader
ERROR 2024-04-06 05:28:12,229 log 13228 16892 Internal Server Error: /shop/fake_db/
Traceback (most recent call last):
  File "C:\Users\mva-1\AppData\Local\Packages\PythonSoftwareFoundation.Python.3.12_qbz5n2kfra8p0\LocalCache\local-packages\Python312\site-packages\django\db\backends\utils.py", line 105, in _execute
    return self.cursor.execute(sql, params)
           ^^^^^^^^^^^^^^^^^^^^^^^^^^^^^^^^
  File "C:\Users\mva-1\AppData\Local\Packages\PythonSoftwareFoundation.Python.3.12_qbz5n2kfra8p0\LocalCache\local-packages\Python312\site-packages\django\db\backends\sqlite3\base.py", line 329, in execute
    return super().execute(query, params)
           ^^^^^^^^^^^^^^^^^^^^^^^^^^^^^^
sqlite3.IntegrityError: NOT NULL constraint failed: shopapp_product.quantity

The above exception was the direct cause of the following exception:

Traceback (most recent call last):
  File "C:\Users\mva-1\AppData\Local\Packages\PythonSoftwareFoundation.Python.3.12_qbz5n2kfra8p0\LocalCache\local-packages\Python312\site-packages\django\core\handlers\exception.py", line 55, in inner
    response = get_response(request)
               ^^^^^^^^^^^^^^^^^^^^^
  File "C:\Users\mva-1\AppData\Local\Packages\PythonSoftwareFoundation.Python.3.12_qbz5n2kfra8p0\LocalCache\local-packages\Python312\site-packages\django\core\handlers\base.py", line 197, in _get_response
    response = wrapped_callback(request, *callback_args, **callback_kwargs)
               ^^^^^^^^^^^^^^^^^^^^^^^^^^^^^^^^^^^^^^^^^^^^^^^^^^^^^^^^^^^^
  File "E:\GeekBrains\Учеба GeekBrains\3 quarter. Final\2. Django framework (Seminars)\GB_Django\Seminar2\HomeWork2\shopapp\views.py", line 67, in fake_db
    product.save()
  File "C:\Users\mva-1\AppData\Local\Packages\PythonSoftwareFoundation.Python.3.12_qbz5n2kfra8p0\LocalCache\local-packages\Python312\site-packages\django\db\models\base.py", line 822, in save
    self.save_base(
  File "C:\Users\mva-1\AppData\Local\Packages\PythonSoftwareFoundation.Python.3.12_qbz5n2kfra8p0\LocalCache\local-packages\Python312\site-packages\django\db\models\base.py", line 909, in save_base
    updated = self._save_table(
              ^^^^^^^^^^^^^^^^^
  File "C:\Users\mva-1\AppData\Local\Packages\PythonSoftwareFoundation.Python.3.12_qbz5n2kfra8p0\LocalCache\local-packages\Python312\site-packages\django\db\models\base.py", line 1067, in _save_table
    results = self._do_insert(
              ^^^^^^^^^^^^^^^^
  File "C:\Users\mva-1\AppData\Local\Packages\PythonSoftwareFoundation.Python.3.12_qbz5n2kfra8p0\LocalCache\local-packages\Python312\site-packages\django\db\models\base.py", line 1108, in _do_insert
    return manager._insert(
           ^^^^^^^^^^^^^^^^
  File "C:\Users\mva-1\AppData\Local\Packages\PythonSoftwareFoundation.Python.3.12_qbz5n2kfra8p0\LocalCache\local-packages\Python312\site-packages\django\db\models\manager.py", line 87, in manager_method
    return getattr(self.get_queryset(), name)(*args, **kwargs)
           ^^^^^^^^^^^^^^^^^^^^^^^^^^^^^^^^^^^^^^^^^^^^^^^^^^^
  File "C:\Users\mva-1\AppData\Local\Packages\PythonSoftwareFoundation.Python.3.12_qbz5n2kfra8p0\LocalCache\local-packages\Python312\site-packages\django\db\models\query.py", line 1847, in _insert
    return query.get_compiler(using=using).execute_sql(returning_fields)
           ^^^^^^^^^^^^^^^^^^^^^^^^^^^^^^^^^^^^^^^^^^^^^^^^^^^^^^^^^^^^^
  File "C:\Users\mva-1\AppData\Local\Packages\PythonSoftwareFoundation.Python.3.12_qbz5n2kfra8p0\LocalCache\local-packages\Python312\site-packages\django\db\models\sql\compiler.py", line 1823, in execute_sql
    cursor.execute(sql, params)
  File "C:\Users\mva-1\AppData\Local\Packages\PythonSoftwareFoundation.Python.3.12_qbz5n2kfra8p0\LocalCache\local-packages\Python312\site-packages\django\db\backends\utils.py", line 122, in execute
    return super().execute(sql, params)
           ^^^^^^^^^^^^^^^^^^^^^^^^^^^^
  File "C:\Users\mva-1\AppData\Local\Packages\PythonSoftwareFoundation.Python.3.12_qbz5n2kfra8p0\LocalCache\local-packages\Python312\site-packages\django\db\backends\utils.py", line 79, in execute
    return self._execute_with_wrappers(
           ^^^^^^^^^^^^^^^^^^^^^^^^^^^^
  File "C:\Users\mva-1\AppData\Local\Packages\PythonSoftwareFoundation.Python.3.12_qbz5n2kfra8p0\LocalCache\local-packages\Python312\site-packages\django\db\backends\utils.py", line 92, in _execute_with_wrappers
    return executor(sql, params, many, context)
           ^^^^^^^^^^^^^^^^^^^^^^^^^^^^^^^^^^^^
  File "C:\Users\mva-1\AppData\Local\Packages\PythonSoftwareFoundation.Python.3.12_qbz5n2kfra8p0\LocalCache\local-packages\Python312\site-packages\django\db\backends\utils.py", line 100, in _execute
    with self.db.wrap_database_errors:
  File "C:\Users\mva-1\AppData\Local\Packages\PythonSoftwareFoundation.Python.3.12_qbz5n2kfra8p0\LocalCache\local-packages\Python312\site-packages\django\db\utils.py", line 91, in __exit__
    raise dj_exc_value.with_traceback(traceback) from exc_value
  File "C:\Users\mva-1\AppData\Local\Packages\PythonSoftwareFoundation.Python.3.12_qbz5n2kfra8p0\LocalCache\local-packages\Python312\site-packages\django\db\backends\utils.py", line 105, in _execute
    return self.cursor.execute(sql, params)
           ^^^^^^^^^^^^^^^^^^^^^^^^^^^^^^^^
  File "C:\Users\mva-1\AppData\Local\Packages\PythonSoftwareFoundation.Python.3.12_qbz5n2kfra8p0\LocalCache\local-packages\Python312\site-packages\django\db\backends\sqlite3\base.py", line 329, in execute
    return super().execute(query, params)
           ^^^^^^^^^^^^^^^^^^^^^^^^^^^^^^
django.db.utils.IntegrityError: NOT NULL constraint failed: shopapp_product.quantity
ERROR 2024-04-06 05:28:12,235 basehttp 13228 16892 "GET /shop/fake_db/ HTTP/1.1" 500 152591
INFO 2024-04-06 05:32:40,905 autoreload 13228 14776 E:\GeekBrains\Учеба GeekBrains\3 quarter. Final\2. Django framework (Seminars)\GB_Django\Seminar2\HomeWork2\shopapp\views.py changed, reloading.
INFO 2024-04-06 05:32:41,514 autoreload 8320 6676 Watching for file changes with StatReloader
ERROR 2024-04-06 05:32:44,671 log 8320 17164 Internal Server Error: /shop/fake_db/
Traceback (most recent call last):
  File "C:\Users\mva-1\AppData\Local\Packages\PythonSoftwareFoundation.Python.3.12_qbz5n2kfra8p0\LocalCache\local-packages\Python312\site-packages\django\db\models\fields\__init__.py", line 1805, in to_python
    decimal_value = decimal.Decimal(value)
                    ^^^^^^^^^^^^^^^^^^^^^^
decimal.InvalidOperation: [<class 'decimal.ConversionSyntax'>]

During handling of the above exception, another exception occurred:

Traceback (most recent call last):
  File "C:\Users\mva-1\AppData\Local\Packages\PythonSoftwareFoundation.Python.3.12_qbz5n2kfra8p0\LocalCache\local-packages\Python312\site-packages\django\core\handlers\exception.py", line 55, in inner
    response = get_response(request)
               ^^^^^^^^^^^^^^^^^^^^^
  File "C:\Users\mva-1\AppData\Local\Packages\PythonSoftwareFoundation.Python.3.12_qbz5n2kfra8p0\LocalCache\local-packages\Python312\site-packages\django\core\handlers\base.py", line 197, in _get_response
    response = wrapped_callback(request, *callback_args, **callback_kwargs)
               ^^^^^^^^^^^^^^^^^^^^^^^^^^^^^^^^^^^^^^^^^^^^^^^^^^^^^^^^^^^^
  File "E:\GeekBrains\Учеба GeekBrains\3 quarter. Final\2. Django framework (Seminars)\GB_Django\Seminar2\HomeWork2\shopapp\views.py", line 69, in fake_db
    product.save()
  File "C:\Users\mva-1\AppData\Local\Packages\PythonSoftwareFoundation.Python.3.12_qbz5n2kfra8p0\LocalCache\local-packages\Python312\site-packages\django\db\models\base.py", line 822, in save
    self.save_base(
  File "C:\Users\mva-1\AppData\Local\Packages\PythonSoftwareFoundation.Python.3.12_qbz5n2kfra8p0\LocalCache\local-packages\Python312\site-packages\django\db\models\base.py", line 909, in save_base
    updated = self._save_table(
              ^^^^^^^^^^^^^^^^^
  File "C:\Users\mva-1\AppData\Local\Packages\PythonSoftwareFoundation.Python.3.12_qbz5n2kfra8p0\LocalCache\local-packages\Python312\site-packages\django\db\models\base.py", line 1067, in _save_table
    results = self._do_insert(
              ^^^^^^^^^^^^^^^^
  File "C:\Users\mva-1\AppData\Local\Packages\PythonSoftwareFoundation.Python.3.12_qbz5n2kfra8p0\LocalCache\local-packages\Python312\site-packages\django\db\models\base.py", line 1108, in _do_insert
    return manager._insert(
           ^^^^^^^^^^^^^^^^
  File "C:\Users\mva-1\AppData\Local\Packages\PythonSoftwareFoundation.Python.3.12_qbz5n2kfra8p0\LocalCache\local-packages\Python312\site-packages\django\db\models\manager.py", line 87, in manager_method
    return getattr(self.get_queryset(), name)(*args, **kwargs)
           ^^^^^^^^^^^^^^^^^^^^^^^^^^^^^^^^^^^^^^^^^^^^^^^^^^^
  File "C:\Users\mva-1\AppData\Local\Packages\PythonSoftwareFoundation.Python.3.12_qbz5n2kfra8p0\LocalCache\local-packages\Python312\site-packages\django\db\models\query.py", line 1847, in _insert
    return query.get_compiler(using=using).execute_sql(returning_fields)
           ^^^^^^^^^^^^^^^^^^^^^^^^^^^^^^^^^^^^^^^^^^^^^^^^^^^^^^^^^^^^^
  File "C:\Users\mva-1\AppData\Local\Packages\PythonSoftwareFoundation.Python.3.12_qbz5n2kfra8p0\LocalCache\local-packages\Python312\site-packages\django\db\models\sql\compiler.py", line 1822, in execute_sql
    for sql, params in self.as_sql():
                       ^^^^^^^^^^^^^
  File "C:\Users\mva-1\AppData\Local\Packages\PythonSoftwareFoundation.Python.3.12_qbz5n2kfra8p0\LocalCache\local-packages\Python312\site-packages\django\db\models\sql\compiler.py", line 1747, in as_sql
    self.prepare_value(field, self.pre_save_val(field, obj))
  File "C:\Users\mva-1\AppData\Local\Packages\PythonSoftwareFoundation.Python.3.12_qbz5n2kfra8p0\LocalCache\local-packages\Python312\site-packages\django\db\models\sql\compiler.py", line 1686, in prepare_value
    return field.get_db_prep_save(value, connection=self.connection)
           ^^^^^^^^^^^^^^^^^^^^^^^^^^^^^^^^^^^^^^^^^^^^^^^^^^^^^^^^^
  File "C:\Users\mva-1\AppData\Local\Packages\PythonSoftwareFoundation.Python.3.12_qbz5n2kfra8p0\LocalCache\local-packages\Python312\site-packages\django\db\models\fields\__init__.py", line 1824, in get_db_prep_save
    self.to_python(value), self.max_digits, self.decimal_places
    ^^^^^^^^^^^^^^^^^^^^^
  File "C:\Users\mva-1\AppData\Local\Packages\PythonSoftwareFoundation.Python.3.12_qbz5n2kfra8p0\LocalCache\local-packages\Python312\site-packages\django\db\models\fields\__init__.py", line 1807, in to_python
    raise exceptions.ValidationError(
django.core.exceptions.ValidationError: ['“Цена_0.0” value must be a decimal number.']
ERROR 2024-04-06 05:32:44,677 basehttp 8320 17164 "GET /shop/fake_db/ HTTP/1.1" 500 128538
INFO 2024-04-06 05:34:13,176 autoreload 8320 6676 E:\GeekBrains\Учеба GeekBrains\3 quarter. Final\2. Django framework (Seminars)\GB_Django\Seminar2\HomeWork2\shopapp\views.py changed, reloading.
INFO 2024-04-06 05:34:13,802 autoreload 2820 17072 Watching for file changes with StatReloader
ERROR 2024-04-06 05:34:17,014 log 2820 13796 Internal Server Error: /shop/fake_db/
Traceback (most recent call last):
  File "C:\Users\mva-1\AppData\Local\Packages\PythonSoftwareFoundation.Python.3.12_qbz5n2kfra8p0\LocalCache\local-packages\Python312\site-packages\django\db\models\fields\__init__.py", line 1805, in to_python
    decimal_value = decimal.Decimal(value)
                    ^^^^^^^^^^^^^^^^^^^^^^
decimal.InvalidOperation: [<class 'decimal.ConversionSyntax'>]

During handling of the above exception, another exception occurred:

Traceback (most recent call last):
  File "C:\Users\mva-1\AppData\Local\Packages\PythonSoftwareFoundation.Python.3.12_qbz5n2kfra8p0\LocalCache\local-packages\Python312\site-packages\django\core\handlers\exception.py", line 55, in inner
    response = get_response(request)
               ^^^^^^^^^^^^^^^^^^^^^
  File "C:\Users\mva-1\AppData\Local\Packages\PythonSoftwareFoundation.Python.3.12_qbz5n2kfra8p0\LocalCache\local-packages\Python312\site-packages\django\core\handlers\base.py", line 197, in _get_response
    response = wrapped_callback(request, *callback_args, **callback_kwargs)
               ^^^^^^^^^^^^^^^^^^^^^^^^^^^^^^^^^^^^^^^^^^^^^^^^^^^^^^^^^^^^
  File "E:\GeekBrains\Учеба GeekBrains\3 quarter. Final\2. Django framework (Seminars)\GB_Django\Seminar2\HomeWork2\shopapp\views.py", line 69, in fake_db
    product.save()
  File "C:\Users\mva-1\AppData\Local\Packages\PythonSoftwareFoundation.Python.3.12_qbz5n2kfra8p0\LocalCache\local-packages\Python312\site-packages\django\db\models\base.py", line 822, in save
    self.save_base(
  File "C:\Users\mva-1\AppData\Local\Packages\PythonSoftwareFoundation.Python.3.12_qbz5n2kfra8p0\LocalCache\local-packages\Python312\site-packages\django\db\models\base.py", line 909, in save_base
    updated = self._save_table(
              ^^^^^^^^^^^^^^^^^
  File "C:\Users\mva-1\AppData\Local\Packages\PythonSoftwareFoundation.Python.3.12_qbz5n2kfra8p0\LocalCache\local-packages\Python312\site-packages\django\db\models\base.py", line 1067, in _save_table
    results = self._do_insert(
              ^^^^^^^^^^^^^^^^
  File "C:\Users\mva-1\AppData\Local\Packages\PythonSoftwareFoundation.Python.3.12_qbz5n2kfra8p0\LocalCache\local-packages\Python312\site-packages\django\db\models\base.py", line 1108, in _do_insert
    return manager._insert(
           ^^^^^^^^^^^^^^^^
  File "C:\Users\mva-1\AppData\Local\Packages\PythonSoftwareFoundation.Python.3.12_qbz5n2kfra8p0\LocalCache\local-packages\Python312\site-packages\django\db\models\manager.py", line 87, in manager_method
    return getattr(self.get_queryset(), name)(*args, **kwargs)
           ^^^^^^^^^^^^^^^^^^^^^^^^^^^^^^^^^^^^^^^^^^^^^^^^^^^
  File "C:\Users\mva-1\AppData\Local\Packages\PythonSoftwareFoundation.Python.3.12_qbz5n2kfra8p0\LocalCache\local-packages\Python312\site-packages\django\db\models\query.py", line 1847, in _insert
    return query.get_compiler(using=using).execute_sql(returning_fields)
           ^^^^^^^^^^^^^^^^^^^^^^^^^^^^^^^^^^^^^^^^^^^^^^^^^^^^^^^^^^^^^
  File "C:\Users\mva-1\AppData\Local\Packages\PythonSoftwareFoundation.Python.3.12_qbz5n2kfra8p0\LocalCache\local-packages\Python312\site-packages\django\db\models\sql\compiler.py", line 1822, in execute_sql
    for sql, params in self.as_sql():
                       ^^^^^^^^^^^^^
  File "C:\Users\mva-1\AppData\Local\Packages\PythonSoftwareFoundation.Python.3.12_qbz5n2kfra8p0\LocalCache\local-packages\Python312\site-packages\django\db\models\sql\compiler.py", line 1747, in as_sql
    self.prepare_value(field, self.pre_save_val(field, obj))
  File "C:\Users\mva-1\AppData\Local\Packages\PythonSoftwareFoundation.Python.3.12_qbz5n2kfra8p0\LocalCache\local-packages\Python312\site-packages\django\db\models\sql\compiler.py", line 1686, in prepare_value
    return field.get_db_prep_save(value, connection=self.connection)
           ^^^^^^^^^^^^^^^^^^^^^^^^^^^^^^^^^^^^^^^^^^^^^^^^^^^^^^^^^
  File "C:\Users\mva-1\AppData\Local\Packages\PythonSoftwareFoundation.Python.3.12_qbz5n2kfra8p0\LocalCache\local-packages\Python312\site-packages\django\db\models\fields\__init__.py", line 1824, in get_db_prep_save
    self.to_python(value), self.max_digits, self.decimal_places
    ^^^^^^^^^^^^^^^^^^^^^
  File "C:\Users\mva-1\AppData\Local\Packages\PythonSoftwareFoundation.Python.3.12_qbz5n2kfra8p0\LocalCache\local-packages\Python312\site-packages\django\db\models\fields\__init__.py", line 1807, in to_python
    raise exceptions.ValidationError(
django.core.exceptions.ValidationError: ['“Цена_0” value must be a decimal number.']
ERROR 2024-04-06 05:34:17,022 basehttp 2820 13796 "GET /shop/fake_db/ HTTP/1.1" 500 128495
INFO 2024-04-06 05:34:46,937 autoreload 2820 17072 E:\GeekBrains\Учеба GeekBrains\3 quarter. Final\2. Django framework (Seminars)\GB_Django\Seminar2\HomeWork2\shopapp\views.py changed, reloading.
INFO 2024-04-06 05:34:47,541 autoreload 16852 15012 Watching for file changes with StatReloader
ERROR 2024-04-06 05:34:50,355 log 16852 13824 Internal Server Error: /shop/fake_db/
Traceback (most recent call last):
  File "C:\Users\mva-1\AppData\Local\Packages\PythonSoftwareFoundation.Python.3.12_qbz5n2kfra8p0\LocalCache\local-packages\Python312\site-packages\django\db\models\fields\__init__.py", line 1805, in to_python
    decimal_value = decimal.Decimal(value)
                    ^^^^^^^^^^^^^^^^^^^^^^
decimal.InvalidOperation: [<class 'decimal.ConversionSyntax'>]

During handling of the above exception, another exception occurred:

Traceback (most recent call last):
  File "C:\Users\mva-1\AppData\Local\Packages\PythonSoftwareFoundation.Python.3.12_qbz5n2kfra8p0\LocalCache\local-packages\Python312\site-packages\django\core\handlers\exception.py", line 55, in inner
    response = get_response(request)
               ^^^^^^^^^^^^^^^^^^^^^
  File "C:\Users\mva-1\AppData\Local\Packages\PythonSoftwareFoundation.Python.3.12_qbz5n2kfra8p0\LocalCache\local-packages\Python312\site-packages\django\core\handlers\base.py", line 197, in _get_response
    response = wrapped_callback(request, *callback_args, **callback_kwargs)
               ^^^^^^^^^^^^^^^^^^^^^^^^^^^^^^^^^^^^^^^^^^^^^^^^^^^^^^^^^^^^
  File "E:\GeekBrains\Учеба GeekBrains\3 quarter. Final\2. Django framework (Seminars)\GB_Django\Seminar2\HomeWork2\shopapp\views.py", line 68, in fake_db
    product.save()
  File "C:\Users\mva-1\AppData\Local\Packages\PythonSoftwareFoundation.Python.3.12_qbz5n2kfra8p0\LocalCache\local-packages\Python312\site-packages\django\db\models\base.py", line 822, in save
    self.save_base(
  File "C:\Users\mva-1\AppData\Local\Packages\PythonSoftwareFoundation.Python.3.12_qbz5n2kfra8p0\LocalCache\local-packages\Python312\site-packages\django\db\models\base.py", line 909, in save_base
    updated = self._save_table(
              ^^^^^^^^^^^^^^^^^
  File "C:\Users\mva-1\AppData\Local\Packages\PythonSoftwareFoundation.Python.3.12_qbz5n2kfra8p0\LocalCache\local-packages\Python312\site-packages\django\db\models\base.py", line 1067, in _save_table
    results = self._do_insert(
              ^^^^^^^^^^^^^^^^
  File "C:\Users\mva-1\AppData\Local\Packages\PythonSoftwareFoundation.Python.3.12_qbz5n2kfra8p0\LocalCache\local-packages\Python312\site-packages\django\db\models\base.py", line 1108, in _do_insert
    return manager._insert(
           ^^^^^^^^^^^^^^^^
  File "C:\Users\mva-1\AppData\Local\Packages\PythonSoftwareFoundation.Python.3.12_qbz5n2kfra8p0\LocalCache\local-packages\Python312\site-packages\django\db\models\manager.py", line 87, in manager_method
    return getattr(self.get_queryset(), name)(*args, **kwargs)
           ^^^^^^^^^^^^^^^^^^^^^^^^^^^^^^^^^^^^^^^^^^^^^^^^^^^
  File "C:\Users\mva-1\AppData\Local\Packages\PythonSoftwareFoundation.Python.3.12_qbz5n2kfra8p0\LocalCache\local-packages\Python312\site-packages\django\db\models\query.py", line 1847, in _insert
    return query.get_compiler(using=using).execute_sql(returning_fields)
           ^^^^^^^^^^^^^^^^^^^^^^^^^^^^^^^^^^^^^^^^^^^^^^^^^^^^^^^^^^^^^
  File "C:\Users\mva-1\AppData\Local\Packages\PythonSoftwareFoundation.Python.3.12_qbz5n2kfra8p0\LocalCache\local-packages\Python312\site-packages\django\db\models\sql\compiler.py", line 1822, in execute_sql
    for sql, params in self.as_sql():
                       ^^^^^^^^^^^^^
  File "C:\Users\mva-1\AppData\Local\Packages\PythonSoftwareFoundation.Python.3.12_qbz5n2kfra8p0\LocalCache\local-packages\Python312\site-packages\django\db\models\sql\compiler.py", line 1747, in as_sql
    self.prepare_value(field, self.pre_save_val(field, obj))
  File "C:\Users\mva-1\AppData\Local\Packages\PythonSoftwareFoundation.Python.3.12_qbz5n2kfra8p0\LocalCache\local-packages\Python312\site-packages\django\db\models\sql\compiler.py", line 1686, in prepare_value
    return field.get_db_prep_save(value, connection=self.connection)
           ^^^^^^^^^^^^^^^^^^^^^^^^^^^^^^^^^^^^^^^^^^^^^^^^^^^^^^^^^
  File "C:\Users\mva-1\AppData\Local\Packages\PythonSoftwareFoundation.Python.3.12_qbz5n2kfra8p0\LocalCache\local-packages\Python312\site-packages\django\db\models\fields\__init__.py", line 1824, in get_db_prep_save
    self.to_python(value), self.max_digits, self.decimal_places
    ^^^^^^^^^^^^^^^^^^^^^
  File "C:\Users\mva-1\AppData\Local\Packages\PythonSoftwareFoundation.Python.3.12_qbz5n2kfra8p0\LocalCache\local-packages\Python312\site-packages\django\db\models\fields\__init__.py", line 1807, in to_python
    raise exceptions.ValidationError(
django.core.exceptions.ValidationError: ['“Цена_0” value must be a decimal number.']
ERROR 2024-04-06 05:34:50,361 basehttp 16852 13824 "GET /shop/fake_db/ HTTP/1.1" 500 128321
INFO 2024-04-06 05:35:21,640 autoreload 16852 15012 E:\GeekBrains\Учеба GeekBrains\3 quarter. Final\2. Django framework (Seminars)\GB_Django\Seminar2\HomeWork2\shopapp\views.py changed, reloading.
INFO 2024-04-06 05:35:22,318 autoreload 16124 14836 Watching for file changes with StatReloader
ERROR 2024-04-06 05:35:24,480 log 16124 16640 Internal Server Error: /shop/fake_db/
Traceback (most recent call last):
  File "C:\Users\mva-1\AppData\Local\Packages\PythonSoftwareFoundation.Python.3.12_qbz5n2kfra8p0\LocalCache\local-packages\Python312\site-packages\django\db\models\fields\__init__.py", line 1805, in to_python
    decimal_value = decimal.Decimal(value)
                    ^^^^^^^^^^^^^^^^^^^^^^
decimal.InvalidOperation: [<class 'decimal.ConversionSyntax'>]

During handling of the above exception, another exception occurred:

Traceback (most recent call last):
  File "C:\Users\mva-1\AppData\Local\Packages\PythonSoftwareFoundation.Python.3.12_qbz5n2kfra8p0\LocalCache\local-packages\Python312\site-packages\django\core\handlers\exception.py", line 55, in inner
    response = get_response(request)
               ^^^^^^^^^^^^^^^^^^^^^
  File "C:\Users\mva-1\AppData\Local\Packages\PythonSoftwareFoundation.Python.3.12_qbz5n2kfra8p0\LocalCache\local-packages\Python312\site-packages\django\core\handlers\base.py", line 197, in _get_response
    response = wrapped_callback(request, *callback_args, **callback_kwargs)
               ^^^^^^^^^^^^^^^^^^^^^^^^^^^^^^^^^^^^^^^^^^^^^^^^^^^^^^^^^^^^
  File "E:\GeekBrains\Учеба GeekBrains\3 quarter. Final\2. Django framework (Seminars)\GB_Django\Seminar2\HomeWork2\shopapp\views.py", line 68, in fake_db
    product.save()
  File "C:\Users\mva-1\AppData\Local\Packages\PythonSoftwareFoundation.Python.3.12_qbz5n2kfra8p0\LocalCache\local-packages\Python312\site-packages\django\db\models\base.py", line 822, in save
    self.save_base(
  File "C:\Users\mva-1\AppData\Local\Packages\PythonSoftwareFoundation.Python.3.12_qbz5n2kfra8p0\LocalCache\local-packages\Python312\site-packages\django\db\models\base.py", line 909, in save_base
    updated = self._save_table(
              ^^^^^^^^^^^^^^^^^
  File "C:\Users\mva-1\AppData\Local\Packages\PythonSoftwareFoundation.Python.3.12_qbz5n2kfra8p0\LocalCache\local-packages\Python312\site-packages\django\db\models\base.py", line 1067, in _save_table
    results = self._do_insert(
              ^^^^^^^^^^^^^^^^
  File "C:\Users\mva-1\AppData\Local\Packages\PythonSoftwareFoundation.Python.3.12_qbz5n2kfra8p0\LocalCache\local-packages\Python312\site-packages\django\db\models\base.py", line 1108, in _do_insert
    return manager._insert(
           ^^^^^^^^^^^^^^^^
  File "C:\Users\mva-1\AppData\Local\Packages\PythonSoftwareFoundation.Python.3.12_qbz5n2kfra8p0\LocalCache\local-packages\Python312\site-packages\django\db\models\manager.py", line 87, in manager_method
    return getattr(self.get_queryset(), name)(*args, **kwargs)
           ^^^^^^^^^^^^^^^^^^^^^^^^^^^^^^^^^^^^^^^^^^^^^^^^^^^
  File "C:\Users\mva-1\AppData\Local\Packages\PythonSoftwareFoundation.Python.3.12_qbz5n2kfra8p0\LocalCache\local-packages\Python312\site-packages\django\db\models\query.py", line 1847, in _insert
    return query.get_compiler(using=using).execute_sql(returning_fields)
           ^^^^^^^^^^^^^^^^^^^^^^^^^^^^^^^^^^^^^^^^^^^^^^^^^^^^^^^^^^^^^
  File "C:\Users\mva-1\AppData\Local\Packages\PythonSoftwareFoundation.Python.3.12_qbz5n2kfra8p0\LocalCache\local-packages\Python312\site-packages\django\db\models\sql\compiler.py", line 1822, in execute_sql
    for sql, params in self.as_sql():
                       ^^^^^^^^^^^^^
  File "C:\Users\mva-1\AppData\Local\Packages\PythonSoftwareFoundation.Python.3.12_qbz5n2kfra8p0\LocalCache\local-packages\Python312\site-packages\django\db\models\sql\compiler.py", line 1747, in as_sql
    self.prepare_value(field, self.pre_save_val(field, obj))
  File "C:\Users\mva-1\AppData\Local\Packages\PythonSoftwareFoundation.Python.3.12_qbz5n2kfra8p0\LocalCache\local-packages\Python312\site-packages\django\db\models\sql\compiler.py", line 1686, in prepare_value
    return field.get_db_prep_save(value, connection=self.connection)
           ^^^^^^^^^^^^^^^^^^^^^^^^^^^^^^^^^^^^^^^^^^^^^^^^^^^^^^^^^
  File "C:\Users\mva-1\AppData\Local\Packages\PythonSoftwareFoundation.Python.3.12_qbz5n2kfra8p0\LocalCache\local-packages\Python312\site-packages\django\db\models\fields\__init__.py", line 1824, in get_db_prep_save
    self.to_python(value), self.max_digits, self.decimal_places
    ^^^^^^^^^^^^^^^^^^^^^
  File "C:\Users\mva-1\AppData\Local\Packages\PythonSoftwareFoundation.Python.3.12_qbz5n2kfra8p0\LocalCache\local-packages\Python312\site-packages\django\db\models\fields\__init__.py", line 1807, in to_python
    raise exceptions.ValidationError(
django.core.exceptions.ValidationError: ['“Цена_0000” value must be a decimal number.']
ERROR 2024-04-06 05:35:24,486 basehttp 16124 16640 "GET /shop/fake_db/ HTTP/1.1" 500 128373
INFO 2024-04-06 05:35:50,211 autoreload 16124 14836 E:\GeekBrains\Учеба GeekBrains\3 quarter. Final\2. Django framework (Seminars)\GB_Django\Seminar2\HomeWork2\shopapp\views.py changed, reloading.
INFO 2024-04-06 05:35:50,771 autoreload 10356 17228 Watching for file changes with StatReloader
ERROR 2024-04-06 05:35:54,717 log 10356 16604 Internal Server Error: /shop/fake_db/
Traceback (most recent call last):
  File "C:\Users\mva-1\AppData\Local\Packages\PythonSoftwareFoundation.Python.3.12_qbz5n2kfra8p0\LocalCache\local-packages\Python312\site-packages\django\db\models\fields\__init__.py", line 1805, in to_python
    decimal_value = decimal.Decimal(value)
                    ^^^^^^^^^^^^^^^^^^^^^^
decimal.InvalidOperation: [<class 'decimal.ConversionSyntax'>]

During handling of the above exception, another exception occurred:

Traceback (most recent call last):
  File "C:\Users\mva-1\AppData\Local\Packages\PythonSoftwareFoundation.Python.3.12_qbz5n2kfra8p0\LocalCache\local-packages\Python312\site-packages\django\core\handlers\exception.py", line 55, in inner
    response = get_response(request)
               ^^^^^^^^^^^^^^^^^^^^^
  File "C:\Users\mva-1\AppData\Local\Packages\PythonSoftwareFoundation.Python.3.12_qbz5n2kfra8p0\LocalCache\local-packages\Python312\site-packages\django\core\handlers\base.py", line 197, in _get_response
    response = wrapped_callback(request, *callback_args, **callback_kwargs)
               ^^^^^^^^^^^^^^^^^^^^^^^^^^^^^^^^^^^^^^^^^^^^^^^^^^^^^^^^^^^^
  File "E:\GeekBrains\Учеба GeekBrains\3 quarter. Final\2. Django framework (Seminars)\GB_Django\Seminar2\HomeWork2\shopapp\views.py", line 68, in fake_db
    product.save()
  File "C:\Users\mva-1\AppData\Local\Packages\PythonSoftwareFoundation.Python.3.12_qbz5n2kfra8p0\LocalCache\local-packages\Python312\site-packages\django\db\models\base.py", line 822, in save
    self.save_base(
  File "C:\Users\mva-1\AppData\Local\Packages\PythonSoftwareFoundation.Python.3.12_qbz5n2kfra8p0\LocalCache\local-packages\Python312\site-packages\django\db\models\base.py", line 909, in save_base
    updated = self._save_table(
              ^^^^^^^^^^^^^^^^^
  File "C:\Users\mva-1\AppData\Local\Packages\PythonSoftwareFoundation.Python.3.12_qbz5n2kfra8p0\LocalCache\local-packages\Python312\site-packages\django\db\models\base.py", line 1067, in _save_table
    results = self._do_insert(
              ^^^^^^^^^^^^^^^^
  File "C:\Users\mva-1\AppData\Local\Packages\PythonSoftwareFoundation.Python.3.12_qbz5n2kfra8p0\LocalCache\local-packages\Python312\site-packages\django\db\models\base.py", line 1108, in _do_insert
    return manager._insert(
           ^^^^^^^^^^^^^^^^
  File "C:\Users\mva-1\AppData\Local\Packages\PythonSoftwareFoundation.Python.3.12_qbz5n2kfra8p0\LocalCache\local-packages\Python312\site-packages\django\db\models\manager.py", line 87, in manager_method
    return getattr(self.get_queryset(), name)(*args, **kwargs)
           ^^^^^^^^^^^^^^^^^^^^^^^^^^^^^^^^^^^^^^^^^^^^^^^^^^^
  File "C:\Users\mva-1\AppData\Local\Packages\PythonSoftwareFoundation.Python.3.12_qbz5n2kfra8p0\LocalCache\local-packages\Python312\site-packages\django\db\models\query.py", line 1847, in _insert
    return query.get_compiler(using=using).execute_sql(returning_fields)
           ^^^^^^^^^^^^^^^^^^^^^^^^^^^^^^^^^^^^^^^^^^^^^^^^^^^^^^^^^^^^^
  File "C:\Users\mva-1\AppData\Local\Packages\PythonSoftwareFoundation.Python.3.12_qbz5n2kfra8p0\LocalCache\local-packages\Python312\site-packages\django\db\models\sql\compiler.py", line 1822, in execute_sql
    for sql, params in self.as_sql():
                       ^^^^^^^^^^^^^
  File "C:\Users\mva-1\AppData\Local\Packages\PythonSoftwareFoundation.Python.3.12_qbz5n2kfra8p0\LocalCache\local-packages\Python312\site-packages\django\db\models\sql\compiler.py", line 1747, in as_sql
    self.prepare_value(field, self.pre_save_val(field, obj))
  File "C:\Users\mva-1\AppData\Local\Packages\PythonSoftwareFoundation.Python.3.12_qbz5n2kfra8p0\LocalCache\local-packages\Python312\site-packages\django\db\models\sql\compiler.py", line 1686, in prepare_value
    return field.get_db_prep_save(value, connection=self.connection)
           ^^^^^^^^^^^^^^^^^^^^^^^^^^^^^^^^^^^^^^^^^^^^^^^^^^^^^^^^^
  File "C:\Users\mva-1\AppData\Local\Packages\PythonSoftwareFoundation.Python.3.12_qbz5n2kfra8p0\LocalCache\local-packages\Python312\site-packages\django\db\models\fields\__init__.py", line 1824, in get_db_prep_save
    self.to_python(value), self.max_digits, self.decimal_places
    ^^^^^^^^^^^^^^^^^^^^^
  File "C:\Users\mva-1\AppData\Local\Packages\PythonSoftwareFoundation.Python.3.12_qbz5n2kfra8p0\LocalCache\local-packages\Python312\site-packages\django\db\models\fields\__init__.py", line 1807, in to_python
    raise exceptions.ValidationError(
django.core.exceptions.ValidationError: ['“Цена_00” value must be a decimal number.']
ERROR 2024-04-06 05:35:54,724 basehttp 10356 16604 "GET /shop/fake_db/ HTTP/1.1" 500 128346
INFO 2024-04-06 05:36:15,483 autoreload 10356 17228 E:\GeekBrains\Учеба GeekBrains\3 quarter. Final\2. Django framework (Seminars)\GB_Django\Seminar2\HomeWork2\shopapp\views.py changed, reloading.
INFO 2024-04-06 05:36:16,103 autoreload 16592 6260 Watching for file changes with StatReloader
INFO 2024-04-06 05:37:33,973 autoreload 16592 6260 E:\GeekBrains\Учеба GeekBrains\3 quarter. Final\2. Django framework (Seminars)\GB_Django\Seminar2\HomeWork2\shopapp\views.py changed, reloading.
INFO 2024-04-06 05:37:34,600 autoreload 16660 12368 Watching for file changes with StatReloader
ERROR 2024-04-06 05:37:36,777 log 16660 15632 Internal Server Error: /shop/fake_db/
Traceback (most recent call last):
  File "C:\Users\mva-1\AppData\Local\Packages\PythonSoftwareFoundation.Python.3.12_qbz5n2kfra8p0\LocalCache\local-packages\Python312\site-packages\django\db\models\fields\__init__.py", line 1805, in to_python
    decimal_value = decimal.Decimal(value)
                    ^^^^^^^^^^^^^^^^^^^^^^
decimal.InvalidOperation: [<class 'decimal.ConversionSyntax'>]

During handling of the above exception, another exception occurred:

Traceback (most recent call last):
  File "C:\Users\mva-1\AppData\Local\Packages\PythonSoftwareFoundation.Python.3.12_qbz5n2kfra8p0\LocalCache\local-packages\Python312\site-packages\django\core\handlers\exception.py", line 55, in inner
    response = get_response(request)
               ^^^^^^^^^^^^^^^^^^^^^
  File "C:\Users\mva-1\AppData\Local\Packages\PythonSoftwareFoundation.Python.3.12_qbz5n2kfra8p0\LocalCache\local-packages\Python312\site-packages\django\core\handlers\base.py", line 197, in _get_response
    response = wrapped_callback(request, *callback_args, **callback_kwargs)
               ^^^^^^^^^^^^^^^^^^^^^^^^^^^^^^^^^^^^^^^^^^^^^^^^^^^^^^^^^^^^
  File "E:\GeekBrains\Учеба GeekBrains\3 quarter. Final\2. Django framework (Seminars)\GB_Django\Seminar2\HomeWork2\shopapp\views.py", line 68, in fake_db
    product.save()
  File "C:\Users\mva-1\AppData\Local\Packages\PythonSoftwareFoundation.Python.3.12_qbz5n2kfra8p0\LocalCache\local-packages\Python312\site-packages\django\db\models\base.py", line 822, in save
    self.save_base(
  File "C:\Users\mva-1\AppData\Local\Packages\PythonSoftwareFoundation.Python.3.12_qbz5n2kfra8p0\LocalCache\local-packages\Python312\site-packages\django\db\models\base.py", line 909, in save_base
    updated = self._save_table(
              ^^^^^^^^^^^^^^^^^
  File "C:\Users\mva-1\AppData\Local\Packages\PythonSoftwareFoundation.Python.3.12_qbz5n2kfra8p0\LocalCache\local-packages\Python312\site-packages\django\db\models\base.py", line 1067, in _save_table
    results = self._do_insert(
              ^^^^^^^^^^^^^^^^
  File "C:\Users\mva-1\AppData\Local\Packages\PythonSoftwareFoundation.Python.3.12_qbz5n2kfra8p0\LocalCache\local-packages\Python312\site-packages\django\db\models\base.py", line 1108, in _do_insert
    return manager._insert(
           ^^^^^^^^^^^^^^^^
  File "C:\Users\mva-1\AppData\Local\Packages\PythonSoftwareFoundation.Python.3.12_qbz5n2kfra8p0\LocalCache\local-packages\Python312\site-packages\django\db\models\manager.py", line 87, in manager_method
    return getattr(self.get_queryset(), name)(*args, **kwargs)
           ^^^^^^^^^^^^^^^^^^^^^^^^^^^^^^^^^^^^^^^^^^^^^^^^^^^
  File "C:\Users\mva-1\AppData\Local\Packages\PythonSoftwareFoundation.Python.3.12_qbz5n2kfra8p0\LocalCache\local-packages\Python312\site-packages\django\db\models\query.py", line 1847, in _insert
    return query.get_compiler(using=using).execute_sql(returning_fields)
           ^^^^^^^^^^^^^^^^^^^^^^^^^^^^^^^^^^^^^^^^^^^^^^^^^^^^^^^^^^^^^
  File "C:\Users\mva-1\AppData\Local\Packages\PythonSoftwareFoundation.Python.3.12_qbz5n2kfra8p0\LocalCache\local-packages\Python312\site-packages\django\db\models\sql\compiler.py", line 1822, in execute_sql
    for sql, params in self.as_sql():
                       ^^^^^^^^^^^^^
  File "C:\Users\mva-1\AppData\Local\Packages\PythonSoftwareFoundation.Python.3.12_qbz5n2kfra8p0\LocalCache\local-packages\Python312\site-packages\django\db\models\sql\compiler.py", line 1747, in as_sql
    self.prepare_value(field, self.pre_save_val(field, obj))
  File "C:\Users\mva-1\AppData\Local\Packages\PythonSoftwareFoundation.Python.3.12_qbz5n2kfra8p0\LocalCache\local-packages\Python312\site-packages\django\db\models\sql\compiler.py", line 1686, in prepare_value
    return field.get_db_prep_save(value, connection=self.connection)
           ^^^^^^^^^^^^^^^^^^^^^^^^^^^^^^^^^^^^^^^^^^^^^^^^^^^^^^^^^
  File "C:\Users\mva-1\AppData\Local\Packages\PythonSoftwareFoundation.Python.3.12_qbz5n2kfra8p0\LocalCache\local-packages\Python312\site-packages\django\db\models\fields\__init__.py", line 1824, in get_db_prep_save
    self.to_python(value), self.max_digits, self.decimal_places
    ^^^^^^^^^^^^^^^^^^^^^
  File "C:\Users\mva-1\AppData\Local\Packages\PythonSoftwareFoundation.Python.3.12_qbz5n2kfra8p0\LocalCache\local-packages\Python312\site-packages\django\db\models\fields\__init__.py", line 1807, in to_python
    raise exceptions.ValidationError(
django.core.exceptions.ValidationError: ['“Цена_0.0” value must be a decimal number.']
ERROR 2024-04-06 05:37:36,784 basehttp 16660 15632 "GET /shop/fake_db/ HTTP/1.1" 500 128355
INFO 2024-04-06 05:37:55,286 autoreload 16660 12368 E:\GeekBrains\Учеба GeekBrains\3 quarter. Final\2. Django framework (Seminars)\GB_Django\Seminar2\HomeWork2\shopapp\views.py changed, reloading.
INFO 2024-04-06 05:37:55,892 autoreload 6468 4708 Watching for file changes with StatReloader
ERROR 2024-04-06 05:37:59,071 log 6468 1944 Internal Server Error: /shop/fake_db/
Traceback (most recent call last):
  File "C:\Users\mva-1\AppData\Local\Packages\PythonSoftwareFoundation.Python.3.12_qbz5n2kfra8p0\LocalCache\local-packages\Python312\site-packages\django\db\models\fields\__init__.py", line 1805, in to_python
    decimal_value = decimal.Decimal(value)
                    ^^^^^^^^^^^^^^^^^^^^^^
decimal.InvalidOperation: [<class 'decimal.ConversionSyntax'>]

During handling of the above exception, another exception occurred:

Traceback (most recent call last):
  File "C:\Users\mva-1\AppData\Local\Packages\PythonSoftwareFoundation.Python.3.12_qbz5n2kfra8p0\LocalCache\local-packages\Python312\site-packages\django\core\handlers\exception.py", line 55, in inner
    response = get_response(request)
               ^^^^^^^^^^^^^^^^^^^^^
  File "C:\Users\mva-1\AppData\Local\Packages\PythonSoftwareFoundation.Python.3.12_qbz5n2kfra8p0\LocalCache\local-packages\Python312\site-packages\django\core\handlers\base.py", line 197, in _get_response
    response = wrapped_callback(request, *callback_args, **callback_kwargs)
               ^^^^^^^^^^^^^^^^^^^^^^^^^^^^^^^^^^^^^^^^^^^^^^^^^^^^^^^^^^^^
  File "E:\GeekBrains\Учеба GeekBrains\3 quarter. Final\2. Django framework (Seminars)\GB_Django\Seminar2\HomeWork2\shopapp\views.py", line 68, in fake_db
    product.save()
  File "C:\Users\mva-1\AppData\Local\Packages\PythonSoftwareFoundation.Python.3.12_qbz5n2kfra8p0\LocalCache\local-packages\Python312\site-packages\django\db\models\base.py", line 822, in save
    self.save_base(
  File "C:\Users\mva-1\AppData\Local\Packages\PythonSoftwareFoundation.Python.3.12_qbz5n2kfra8p0\LocalCache\local-packages\Python312\site-packages\django\db\models\base.py", line 909, in save_base
    updated = self._save_table(
              ^^^^^^^^^^^^^^^^^
  File "C:\Users\mva-1\AppData\Local\Packages\PythonSoftwareFoundation.Python.3.12_qbz5n2kfra8p0\LocalCache\local-packages\Python312\site-packages\django\db\models\base.py", line 1067, in _save_table
    results = self._do_insert(
              ^^^^^^^^^^^^^^^^
  File "C:\Users\mva-1\AppData\Local\Packages\PythonSoftwareFoundation.Python.3.12_qbz5n2kfra8p0\LocalCache\local-packages\Python312\site-packages\django\db\models\base.py", line 1108, in _do_insert
    return manager._insert(
           ^^^^^^^^^^^^^^^^
  File "C:\Users\mva-1\AppData\Local\Packages\PythonSoftwareFoundation.Python.3.12_qbz5n2kfra8p0\LocalCache\local-packages\Python312\site-packages\django\db\models\manager.py", line 87, in manager_method
    return getattr(self.get_queryset(), name)(*args, **kwargs)
           ^^^^^^^^^^^^^^^^^^^^^^^^^^^^^^^^^^^^^^^^^^^^^^^^^^^
  File "C:\Users\mva-1\AppData\Local\Packages\PythonSoftwareFoundation.Python.3.12_qbz5n2kfra8p0\LocalCache\local-packages\Python312\site-packages\django\db\models\query.py", line 1847, in _insert
    return query.get_compiler(using=using).execute_sql(returning_fields)
           ^^^^^^^^^^^^^^^^^^^^^^^^^^^^^^^^^^^^^^^^^^^^^^^^^^^^^^^^^^^^^
  File "C:\Users\mva-1\AppData\Local\Packages\PythonSoftwareFoundation.Python.3.12_qbz5n2kfra8p0\LocalCache\local-packages\Python312\site-packages\django\db\models\sql\compiler.py", line 1822, in execute_sql
    for sql, params in self.as_sql():
                       ^^^^^^^^^^^^^
  File "C:\Users\mva-1\AppData\Local\Packages\PythonSoftwareFoundation.Python.3.12_qbz5n2kfra8p0\LocalCache\local-packages\Python312\site-packages\django\db\models\sql\compiler.py", line 1747, in as_sql
    self.prepare_value(field, self.pre_save_val(field, obj))
  File "C:\Users\mva-1\AppData\Local\Packages\PythonSoftwareFoundation.Python.3.12_qbz5n2kfra8p0\LocalCache\local-packages\Python312\site-packages\django\db\models\sql\compiler.py", line 1686, in prepare_value
    return field.get_db_prep_save(value, connection=self.connection)
           ^^^^^^^^^^^^^^^^^^^^^^^^^^^^^^^^^^^^^^^^^^^^^^^^^^^^^^^^^
  File "C:\Users\mva-1\AppData\Local\Packages\PythonSoftwareFoundation.Python.3.12_qbz5n2kfra8p0\LocalCache\local-packages\Python312\site-packages\django\db\models\fields\__init__.py", line 1824, in get_db_prep_save
    self.to_python(value), self.max_digits, self.decimal_places
    ^^^^^^^^^^^^^^^^^^^^^
  File "C:\Users\mva-1\AppData\Local\Packages\PythonSoftwareFoundation.Python.3.12_qbz5n2kfra8p0\LocalCache\local-packages\Python312\site-packages\django\db\models\fields\__init__.py", line 1807, in to_python
    raise exceptions.ValidationError(
django.core.exceptions.ValidationError: ['“Цена_0.0” value must be a decimal number.']
ERROR 2024-04-06 05:37:59,077 basehttp 6468 1944 "GET /shop/fake_db/ HTTP/1.1" 500 128364
INFO 2024-04-06 05:38:13,366 autoreload 6468 4708 E:\GeekBrains\Учеба GeekBrains\3 quarter. Final\2. Django framework (Seminars)\GB_Django\Seminar2\HomeWork2\shopapp\views.py changed, reloading.
INFO 2024-04-06 05:38:13,981 autoreload 15136 1984 Watching for file changes with StatReloader
INFO 2024-04-06 05:43:53,544 autoreload 15136 1984 E:\GeekBrains\Учеба GeekBrains\3 quarter. Final\2. Django framework (Seminars)\GB_Django\Seminar2\HomeWork2\shopapp\views.py changed, reloading.
INFO 2024-04-06 05:43:54,141 autoreload 10800 16924 Watching for file changes with StatReloader
ERROR 2024-04-06 05:43:55,163 log 10800 6248 Internal Server Error: /shop/fake_db/
Traceback (most recent call last):
  File "C:\Users\mva-1\AppData\Local\Packages\PythonSoftwareFoundation.Python.3.12_qbz5n2kfra8p0\LocalCache\local-packages\Python312\site-packages\django\db\models\fields\__init__.py", line 2117, in get_prep_value
    return int(value)
           ^^^^^^^^^^
ValueError: invalid literal for int() with base 10: 'Количество_5'

The above exception was the direct cause of the following exception:

Traceback (most recent call last):
  File "C:\Users\mva-1\AppData\Local\Packages\PythonSoftwareFoundation.Python.3.12_qbz5n2kfra8p0\LocalCache\local-packages\Python312\site-packages\django\core\handlers\exception.py", line 55, in inner
    response = get_response(request)
               ^^^^^^^^^^^^^^^^^^^^^
  File "C:\Users\mva-1\AppData\Local\Packages\PythonSoftwareFoundation.Python.3.12_qbz5n2kfra8p0\LocalCache\local-packages\Python312\site-packages\django\core\handlers\base.py", line 197, in _get_response
    response = wrapped_callback(request, *callback_args, **callback_kwargs)
               ^^^^^^^^^^^^^^^^^^^^^^^^^^^^^^^^^^^^^^^^^^^^^^^^^^^^^^^^^^^^
  File "E:\GeekBrains\Учеба GeekBrains\3 quarter. Final\2. Django framework (Seminars)\GB_Django\Seminar2\HomeWork2\shopapp\views.py", line 68, in fake_db
    product.save()
  File "C:\Users\mva-1\AppData\Local\Packages\PythonSoftwareFoundation.Python.3.12_qbz5n2kfra8p0\LocalCache\local-packages\Python312\site-packages\django\db\models\base.py", line 822, in save
    self.save_base(
  File "C:\Users\mva-1\AppData\Local\Packages\PythonSoftwareFoundation.Python.3.12_qbz5n2kfra8p0\LocalCache\local-packages\Python312\site-packages\django\db\models\base.py", line 909, in save_base
    updated = self._save_table(
              ^^^^^^^^^^^^^^^^^
  File "C:\Users\mva-1\AppData\Local\Packages\PythonSoftwareFoundation.Python.3.12_qbz5n2kfra8p0\LocalCache\local-packages\Python312\site-packages\django\db\models\base.py", line 1067, in _save_table
    results = self._do_insert(
              ^^^^^^^^^^^^^^^^
  File "C:\Users\mva-1\AppData\Local\Packages\PythonSoftwareFoundation.Python.3.12_qbz5n2kfra8p0\LocalCache\local-packages\Python312\site-packages\django\db\models\base.py", line 1108, in _do_insert
    return manager._insert(
           ^^^^^^^^^^^^^^^^
  File "C:\Users\mva-1\AppData\Local\Packages\PythonSoftwareFoundation.Python.3.12_qbz5n2kfra8p0\LocalCache\local-packages\Python312\site-packages\django\db\models\manager.py", line 87, in manager_method
    return getattr(self.get_queryset(), name)(*args, **kwargs)
           ^^^^^^^^^^^^^^^^^^^^^^^^^^^^^^^^^^^^^^^^^^^^^^^^^^^
  File "C:\Users\mva-1\AppData\Local\Packages\PythonSoftwareFoundation.Python.3.12_qbz5n2kfra8p0\LocalCache\local-packages\Python312\site-packages\django\db\models\query.py", line 1847, in _insert
    return query.get_compiler(using=using).execute_sql(returning_fields)
           ^^^^^^^^^^^^^^^^^^^^^^^^^^^^^^^^^^^^^^^^^^^^^^^^^^^^^^^^^^^^^
  File "C:\Users\mva-1\AppData\Local\Packages\PythonSoftwareFoundation.Python.3.12_qbz5n2kfra8p0\LocalCache\local-packages\Python312\site-packages\django\db\models\sql\compiler.py", line 1822, in execute_sql
    for sql, params in self.as_sql():
                       ^^^^^^^^^^^^^
  File "C:\Users\mva-1\AppData\Local\Packages\PythonSoftwareFoundation.Python.3.12_qbz5n2kfra8p0\LocalCache\local-packages\Python312\site-packages\django\db\models\sql\compiler.py", line 1747, in as_sql
    self.prepare_value(field, self.pre_save_val(field, obj))
  File "C:\Users\mva-1\AppData\Local\Packages\PythonSoftwareFoundation.Python.3.12_qbz5n2kfra8p0\LocalCache\local-packages\Python312\site-packages\django\db\models\sql\compiler.py", line 1686, in prepare_value
    return field.get_db_prep_save(value, connection=self.connection)
           ^^^^^^^^^^^^^^^^^^^^^^^^^^^^^^^^^^^^^^^^^^^^^^^^^^^^^^^^^
  File "C:\Users\mva-1\AppData\Local\Packages\PythonSoftwareFoundation.Python.3.12_qbz5n2kfra8p0\LocalCache\local-packages\Python312\site-packages\django\db\models\fields\__init__.py", line 1013, in get_db_prep_save
    return self.get_db_prep_value(value, connection=connection, prepared=False)
           ^^^^^^^^^^^^^^^^^^^^^^^^^^^^^^^^^^^^^^^^^^^^^^^^^^^^^^^^^^^^^^^^^^^^
  File "C:\Users\mva-1\AppData\Local\Packages\PythonSoftwareFoundation.Python.3.12_qbz5n2kfra8p0\LocalCache\local-packages\Python312\site-packages\django\db\models\fields\__init__.py", line 2124, in get_db_prep_value
    value = super().get_db_prep_value(value, connection, prepared)
            ^^^^^^^^^^^^^^^^^^^^^^^^^^^^^^^^^^^^^^^^^^^^^^^^^^^^^^
  File "C:\Users\mva-1\AppData\Local\Packages\PythonSoftwareFoundation.Python.3.12_qbz5n2kfra8p0\LocalCache\local-packages\Python312\site-packages\django\db\models\fields\__init__.py", line 1006, in get_db_prep_value
    value = self.get_prep_value(value)
            ^^^^^^^^^^^^^^^^^^^^^^^^^^
  File "C:\Users\mva-1\AppData\Local\Packages\PythonSoftwareFoundation.Python.3.12_qbz5n2kfra8p0\LocalCache\local-packages\Python312\site-packages\django\db\models\fields\__init__.py", line 2119, in get_prep_value
    raise e.__class__(
ValueError: Field 'quantity' expected a number but got 'Количество_5'.
ERROR 2024-04-06 05:43:55,169 basehttp 10800 6248 "GET /shop/fake_db/ HTTP/1.1" 500 138450
INFO 2024-04-06 05:45:39,189 autoreload 10800 16924 E:\GeekBrains\Учеба GeekBrains\3 quarter. Final\2. Django framework (Seminars)\GB_Django\Seminar2\HomeWork2\shopapp\views.py changed, reloading.
INFO 2024-04-06 05:45:39,747 autoreload 14716 11132 Watching for file changes with StatReloader
ERROR 2024-04-06 05:45:42,776 log 14716 2216 Internal Server Error: /shop/fake_db/
Traceback (most recent call last):
  File "C:\Users\mva-1\AppData\Local\Packages\PythonSoftwareFoundation.Python.3.12_qbz5n2kfra8p0\LocalCache\local-packages\Python312\site-packages\django\core\handlers\exception.py", line 55, in inner
    response = get_response(request)
               ^^^^^^^^^^^^^^^^^^^^^
  File "C:\Users\mva-1\AppData\Local\Packages\PythonSoftwareFoundation.Python.3.12_qbz5n2kfra8p0\LocalCache\local-packages\Python312\site-packages\django\core\handlers\base.py", line 197, in _get_response
    response = wrapped_callback(request, *callback_args, **callback_kwargs)
               ^^^^^^^^^^^^^^^^^^^^^^^^^^^^^^^^^^^^^^^^^^^^^^^^^^^^^^^^^^^^
  File "E:\GeekBrains\Учеба GeekBrains\3 quarter. Final\2. Django framework (Seminars)\GB_Django\Seminar2\HomeWork2\shopapp\views.py", line 68, in fake_db
    product.save()
  File "C:\Users\mva-1\AppData\Local\Packages\PythonSoftwareFoundation.Python.3.12_qbz5n2kfra8p0\LocalCache\local-packages\Python312\site-packages\django\db\models\base.py", line 822, in save
    self.save_base(
  File "C:\Users\mva-1\AppData\Local\Packages\PythonSoftwareFoundation.Python.3.12_qbz5n2kfra8p0\LocalCache\local-packages\Python312\site-packages\django\db\models\base.py", line 909, in save_base
    updated = self._save_table(
              ^^^^^^^^^^^^^^^^^
  File "C:\Users\mva-1\AppData\Local\Packages\PythonSoftwareFoundation.Python.3.12_qbz5n2kfra8p0\LocalCache\local-packages\Python312\site-packages\django\db\models\base.py", line 1067, in _save_table
    results = self._do_insert(
              ^^^^^^^^^^^^^^^^
  File "C:\Users\mva-1\AppData\Local\Packages\PythonSoftwareFoundation.Python.3.12_qbz5n2kfra8p0\LocalCache\local-packages\Python312\site-packages\django\db\models\base.py", line 1108, in _do_insert
    return manager._insert(
           ^^^^^^^^^^^^^^^^
  File "C:\Users\mva-1\AppData\Local\Packages\PythonSoftwareFoundation.Python.3.12_qbz5n2kfra8p0\LocalCache\local-packages\Python312\site-packages\django\db\models\manager.py", line 87, in manager_method
    return getattr(self.get_queryset(), name)(*args, **kwargs)
           ^^^^^^^^^^^^^^^^^^^^^^^^^^^^^^^^^^^^^^^^^^^^^^^^^^^
  File "C:\Users\mva-1\AppData\Local\Packages\PythonSoftwareFoundation.Python.3.12_qbz5n2kfra8p0\LocalCache\local-packages\Python312\site-packages\django\db\models\query.py", line 1847, in _insert
    return query.get_compiler(using=using).execute_sql(returning_fields)
           ^^^^^^^^^^^^^^^^^^^^^^^^^^^^^^^^^^^^^^^^^^^^^^^^^^^^^^^^^^^^^
  File "C:\Users\mva-1\AppData\Local\Packages\PythonSoftwareFoundation.Python.3.12_qbz5n2kfra8p0\LocalCache\local-packages\Python312\site-packages\django\db\models\sql\compiler.py", line 1822, in execute_sql
    for sql, params in self.as_sql():
                       ^^^^^^^^^^^^^
  File "C:\Users\mva-1\AppData\Local\Packages\PythonSoftwareFoundation.Python.3.12_qbz5n2kfra8p0\LocalCache\local-packages\Python312\site-packages\django\db\models\sql\compiler.py", line 1747, in as_sql
    self.prepare_value(field, self.pre_save_val(field, obj))
  File "C:\Users\mva-1\AppData\Local\Packages\PythonSoftwareFoundation.Python.3.12_qbz5n2kfra8p0\LocalCache\local-packages\Python312\site-packages\django\db\models\sql\compiler.py", line 1686, in prepare_value
    return field.get_db_prep_save(value, connection=self.connection)
           ^^^^^^^^^^^^^^^^^^^^^^^^^^^^^^^^^^^^^^^^^^^^^^^^^^^^^^^^^
  File "C:\Users\mva-1\AppData\Local\Packages\PythonSoftwareFoundation.Python.3.12_qbz5n2kfra8p0\LocalCache\local-packages\Python312\site-packages\django\db\models\fields\__init__.py", line 1013, in get_db_prep_save
    return self.get_db_prep_value(value, connection=connection, prepared=False)
           ^^^^^^^^^^^^^^^^^^^^^^^^^^^^^^^^^^^^^^^^^^^^^^^^^^^^^^^^^^^^^^^^^^^^
  File "C:\Users\mva-1\AppData\Local\Packages\PythonSoftwareFoundation.Python.3.12_qbz5n2kfra8p0\LocalCache\local-packages\Python312\site-packages\django\db\models\fields\__init__.py", line 1671, in get_db_prep_value
    value = self.get_prep_value(value)
            ^^^^^^^^^^^^^^^^^^^^^^^^^^
  File "C:\Users\mva-1\AppData\Local\Packages\PythonSoftwareFoundation.Python.3.12_qbz5n2kfra8p0\LocalCache\local-packages\Python312\site-packages\django\db\models\fields\__init__.py", line 1649, in get_prep_value
    value = super().get_prep_value(value)
            ^^^^^^^^^^^^^^^^^^^^^^^^^^^^^
  File "C:\Users\mva-1\AppData\Local\Packages\PythonSoftwareFoundation.Python.3.12_qbz5n2kfra8p0\LocalCache\local-packages\Python312\site-packages\django\db\models\fields\__init__.py", line 1525, in get_prep_value
    return self.to_python(value)
           ^^^^^^^^^^^^^^^^^^^^^
  File "C:\Users\mva-1\AppData\Local\Packages\PythonSoftwareFoundation.Python.3.12_qbz5n2kfra8p0\LocalCache\local-packages\Python312\site-packages\django\db\models\fields\__init__.py", line 1631, in to_python
    raise exceptions.ValidationError(
django.core.exceptions.ValidationError: ['“Дата добавления_2024-04-06 05:45:42.703509” value has an invalid format. It must be in YYYY-MM-DD HH:MM[:ss[.uuuuuu]][TZ] format.']
ERROR 2024-04-06 05:45:42,782 basehttp 14716 2216 "GET /shop/fake_db/ HTTP/1.1" 500 138012
INFO 2024-04-06 05:46:06,577 autoreload 14716 11132 E:\GeekBrains\Учеба GeekBrains\3 quarter. Final\2. Django framework (Seminars)\GB_Django\Seminar2\HomeWork2\shopapp\views.py changed, reloading.
INFO 2024-04-06 05:46:07,202 autoreload 17308 16928 Watching for file changes with StatReloader
ERROR 2024-04-06 05:46:10,335 log 17308 16584 Internal Server Error: /shop/fake_db/
Traceback (most recent call last):
  File "C:\Users\mva-1\AppData\Local\Packages\PythonSoftwareFoundation.Python.3.12_qbz5n2kfra8p0\LocalCache\local-packages\Python312\site-packages\django\core\handlers\exception.py", line 55, in inner
    response = get_response(request)
               ^^^^^^^^^^^^^^^^^^^^^
  File "C:\Users\mva-1\AppData\Local\Packages\PythonSoftwareFoundation.Python.3.12_qbz5n2kfra8p0\LocalCache\local-packages\Python312\site-packages\django\core\handlers\base.py", line 197, in _get_response
    response = wrapped_callback(request, *callback_args, **callback_kwargs)
               ^^^^^^^^^^^^^^^^^^^^^^^^^^^^^^^^^^^^^^^^^^^^^^^^^^^^^^^^^^^^
  File "E:\GeekBrains\Учеба GeekBrains\3 quarter. Final\2. Django framework (Seminars)\GB_Django\Seminar2\HomeWork2\shopapp\views.py", line 73, in fake_db
    order.save()
  File "C:\Users\mva-1\AppData\Local\Packages\PythonSoftwareFoundation.Python.3.12_qbz5n2kfra8p0\LocalCache\local-packages\Python312\site-packages\django\db\models\base.py", line 822, in save
    self.save_base(
  File "C:\Users\mva-1\AppData\Local\Packages\PythonSoftwareFoundation.Python.3.12_qbz5n2kfra8p0\LocalCache\local-packages\Python312\site-packages\django\db\models\base.py", line 909, in save_base
    updated = self._save_table(
              ^^^^^^^^^^^^^^^^^
  File "C:\Users\mva-1\AppData\Local\Packages\PythonSoftwareFoundation.Python.3.12_qbz5n2kfra8p0\LocalCache\local-packages\Python312\site-packages\django\db\models\base.py", line 1067, in _save_table
    results = self._do_insert(
              ^^^^^^^^^^^^^^^^
  File "C:\Users\mva-1\AppData\Local\Packages\PythonSoftwareFoundation.Python.3.12_qbz5n2kfra8p0\LocalCache\local-packages\Python312\site-packages\django\db\models\base.py", line 1108, in _do_insert
    return manager._insert(
           ^^^^^^^^^^^^^^^^
  File "C:\Users\mva-1\AppData\Local\Packages\PythonSoftwareFoundation.Python.3.12_qbz5n2kfra8p0\LocalCache\local-packages\Python312\site-packages\django\db\models\manager.py", line 87, in manager_method
    return getattr(self.get_queryset(), name)(*args, **kwargs)
           ^^^^^^^^^^^^^^^^^^^^^^^^^^^^^^^^^^^^^^^^^^^^^^^^^^^
  File "C:\Users\mva-1\AppData\Local\Packages\PythonSoftwareFoundation.Python.3.12_qbz5n2kfra8p0\LocalCache\local-packages\Python312\site-packages\django\db\models\query.py", line 1847, in _insert
    return query.get_compiler(using=using).execute_sql(returning_fields)
           ^^^^^^^^^^^^^^^^^^^^^^^^^^^^^^^^^^^^^^^^^^^^^^^^^^^^^^^^^^^^^
  File "C:\Users\mva-1\AppData\Local\Packages\PythonSoftwareFoundation.Python.3.12_qbz5n2kfra8p0\LocalCache\local-packages\Python312\site-packages\django\db\models\sql\compiler.py", line 1822, in execute_sql
    for sql, params in self.as_sql():
                       ^^^^^^^^^^^^^
  File "C:\Users\mva-1\AppData\Local\Packages\PythonSoftwareFoundation.Python.3.12_qbz5n2kfra8p0\LocalCache\local-packages\Python312\site-packages\django\db\models\sql\compiler.py", line 1747, in as_sql
    self.prepare_value(field, self.pre_save_val(field, obj))
  File "C:\Users\mva-1\AppData\Local\Packages\PythonSoftwareFoundation.Python.3.12_qbz5n2kfra8p0\LocalCache\local-packages\Python312\site-packages\django\db\models\sql\compiler.py", line 1686, in prepare_value
    return field.get_db_prep_save(value, connection=self.connection)
           ^^^^^^^^^^^^^^^^^^^^^^^^^^^^^^^^^^^^^^^^^^^^^^^^^^^^^^^^^
  File "C:\Users\mva-1\AppData\Local\Packages\PythonSoftwareFoundation.Python.3.12_qbz5n2kfra8p0\LocalCache\local-packages\Python312\site-packages\django\db\models\fields\__init__.py", line 1013, in get_db_prep_save
    return self.get_db_prep_value(value, connection=connection, prepared=False)
           ^^^^^^^^^^^^^^^^^^^^^^^^^^^^^^^^^^^^^^^^^^^^^^^^^^^^^^^^^^^^^^^^^^^^
  File "C:\Users\mva-1\AppData\Local\Packages\PythonSoftwareFoundation.Python.3.12_qbz5n2kfra8p0\LocalCache\local-packages\Python312\site-packages\django\db\models\fields\__init__.py", line 1671, in get_db_prep_value
    value = self.get_prep_value(value)
            ^^^^^^^^^^^^^^^^^^^^^^^^^^
  File "C:\Users\mva-1\AppData\Local\Packages\PythonSoftwareFoundation.Python.3.12_qbz5n2kfra8p0\LocalCache\local-packages\Python312\site-packages\django\db\models\fields\__init__.py", line 1649, in get_prep_value
    value = super().get_prep_value(value)
            ^^^^^^^^^^^^^^^^^^^^^^^^^^^^^
  File "C:\Users\mva-1\AppData\Local\Packages\PythonSoftwareFoundation.Python.3.12_qbz5n2kfra8p0\LocalCache\local-packages\Python312\site-packages\django\db\models\fields\__init__.py", line 1525, in get_prep_value
    return self.to_python(value)
           ^^^^^^^^^^^^^^^^^^^^^
  File "C:\Users\mva-1\AppData\Local\Packages\PythonSoftwareFoundation.Python.3.12_qbz5n2kfra8p0\LocalCache\local-packages\Python312\site-packages\django\db\models\fields\__init__.py", line 1631, in to_python
    raise exceptions.ValidationError(
django.core.exceptions.ValidationError: ['“2024-04-010” value has an invalid format. It must be in YYYY-MM-DD HH:MM[:ss[.uuuuuu]][TZ] format.']
ERROR 2024-04-06 05:46:10,341 basehttp 17308 16584 "GET /shop/fake_db/ HTTP/1.1" 500 137155
INFO 2024-04-06 05:47:32,804 autoreload 17308 16928 E:\GeekBrains\Учеба GeekBrains\3 quarter. Final\2. Django framework (Seminars)\GB_Django\Seminar2\HomeWork2\shopapp\views.py changed, reloading.
INFO 2024-04-06 05:47:33,488 autoreload 16532 17368 Watching for file changes with StatReloader
INFO 2024-04-06 05:47:36,259 basehttp 16532 16172 "GET /shop/fake_db/ HTTP/1.1" 200 63
